Workbook

Sheet Master
A1: SL | H1: Answerd | O1: OCC | V1: Login | AC1: Total Login | AJ1: Lock | AQ1: Status | AX1: =TODAY() -> 45965
A2: Interval | B2: 247 | C2: R.EU | D2: Cash | E2: ASP | F2: ICC | G2: CM | H2: Interval | I2: 247 | J2: R.EU | K2: Cash | L2: ASP | M2: ICC | N2: CM | O2: Interval | P2: 247 | Q2: R.EU | R2: Cash | S2: ASP | T2: ICC | U2: CM | V2: Interval | W2: 247 | X2: R.EU | Y2: Cash | Z2: ASP | AA2: ICC | AB2: CM | AC2: Interval | AD2: 247 | AE2: R.EU | AF2: Cash | AG2: ASP | AH2: ICC | AI2: CM | AJ2: Interval | AK2: 247 | AL2: R.EU | AM2: RED | AN2: ASP | AO2: ICC | AP2: CM | AQ2: Interval | AR2: 247 | AS2: CASH | AT2: RED | AU2: ASP | AV2: ICC | AW2: CM
A3: 0 | B3: 0.79 | C3: 1 | D3: 1 | E3: 0.47 | F3: 0.15 | G3: - | H3: 0 | I3: 40 | J3: 8 | K3: 23 | L3: 54 | M3: 59 | N3: - | O3: 0 | P3: 91 | Q3: 49 | R3: 99 | S3: 95 | T3: 72 | U3: - | V3: 0 | W3: 15 | X3: 7 | Y3: 8 | Z3: 12 | AA3: 14 | AB3: - | AC3: 0 | AD3: 0.30347222 | AE3: 0.13472222 | AF3: 0.16111111 | AG3: 0.22777778 | AH3: 0.29166667 | AI3: - | AJ3: 0 | AK3: =HLOOKUP($AX$1,[1]EU!$B$2:$AF$51,XFD3,0) -> 36 | AL3: =HLOOKUP($AX$1,'[1]Enterprise Aspiring'!$B$2:$AF$51,XFD3,0) -> 11 | AM3: =HLOOKUP($AX$1,'[1]Red Cash'!$B$2:$AF$51,XFD3,0) -> 36 | AN3: =HLOOKUP($AX$1,[1]Aspiring!$B$2:$AF$51,XFD3,0) -> 36 | AO3: =HLOOKUP($AX$1,[1]ICC!$B$2:$AF$51,XFD3,0) -> 49 | AP3: =HLOOKUP($AX$1,[1]CM!$B$2:$AF$51,XFD3,0) -> 0 | AQ3: 0 | AR3: =EU!N2 -> Achived | AS3: ='R.EU'!N2 -> Wait | AT3: ='Red Cash'!N2 -> Wait | AU3: =Aspiring!N2 -> Achived | AV3: =ICC!N2 -> Achived | AW3: ='SME-CM'!N2 | XFD3: 3
A4: 0.020833333 | B4: 1 | C4: 1 | D4: 1 | E4: 1 | F4: 0.34 | G4: - | H4: 0.020833333 | I4: 24 | J4: 11 | K4: 17 | L4: 38 | M4: 54 | N4: - | O4: 0.020833333 | P4: 89 | Q4: 65 | R4: 60 | S4: 73 | T4: 98 | U4: - | V4: 0.020833333 | W4: 16 | X4: 6 | Y4: 9 | Z4: 13 | AA4: 13 | AB4: - | AC4: 0.020833333 | AD4: 0.30069444 | AE4: 0.13819444 | AF4: 0.18541667 | AG4: 0.275 | AH4: 0.33263889 | AI4: - | AJ4: 0.020833333 | AK4: =HLOOKUP($AX$1,[1]EU!$B$2:$AF$51,XFD4,0) -> 33 | AL4: =HLOOKUP($AX$1,'[1]Enterprise Aspiring'!$B$2:$AF$51,XFD4,0) -> 10 | AM4: =HLOOKUP($AX$1,'[1]Red Cash'!$B$2:$AF$51,XFD4,0) -> 30 | AN4: =HLOOKUP($AX$1,[1]Aspiring!$B$2:$AF$51,XFD4,0) -> 32 | AO4: =HLOOKUP($AX$1,[1]ICC!$B$2:$AF$51,XFD4,0) -> 49 | AP4: =HLOOKUP($AX$1,[1]CM!$B$2:$AF$51,XFD4,0) -> 0 | AQ4: 0.020833333 | AR4: =EU!N3 -> Wait | AS4: ='R.EU'!N3 -> Achived | AT4: ='Red Cash'!N3 -> Wait | AU4: =Aspiring!N3 -> Achived | AV4: =ICC!N3 -> Achived | AW4: ='SME-CM'!N3 | XFD4: =XFD3+1 -> 4
A5: 0.041666667 | B5: 1 | C5: 1 | D5: 1 | E5: 0.78 | F5: 0.67 | G5: - | H5: 0.041666667 | I5: 21 | J5: 4 | K5: 1 | L5: 23 | M5: 47 | N5: - | O5: 0.041666667 | P5: 90 | Q5: 53 | R5: 52 | S5: 80 | T5: 95 | U5: - | V5: 0.041666667 | W5: 11 | X5: 6 | Y5: 8 | Z5: 10 | AA5: 10 | AB5: - | AC5: 0.041666667 | AD5: 0.23541667 | AE5: 0.12222222 | AF5: 0.15069444 | AG5: 0.19236111 | AH5: 0.21180556 | AI5: - | AJ5: 0.041666667 | AK5: =HLOOKUP($AX$1,[1]EU!$B$2:$AF$51,XFD5,0) -> 19 | AL5: =HLOOKUP($AX$1,'[1]Enterprise Aspiring'!$B$2:$AF$51,XFD5,0) -> 8 | AM5: =HLOOKUP($AX$1,'[1]Red Cash'!$B$2:$AF$51,XFD5,0) -> 25 | AN5: =HLOOKUP($AX$1,[1]Aspiring!$B$2:$AF$51,XFD5,0) -> 16 | AO5: =HLOOKUP($AX$1,[1]ICC!$B$2:$AF$51,XFD5,0) -> 40 | AP5: =HLOOKUP($AX$1,[1]CM!$B$2:$AF$51,XFD5,0) -> 0 | AQ5: 0.041666667 | AR5: =EU!N4 -> Achived | AS5: ='R.EU'!N4 -> Wait | AT5: ='Red Cash'!N4 -> Wait | AU5: =Aspiring!N4 -> Achived | AV5: =ICC!N4 -> Achived | AW5: ='SME-CM'!N4 | XFD5: =XFD4+1 -> 5
A6: 0.0625 | B6: 1 | C6: 0.9 | D6: 1 | E6: 1 | F6: 0.98 | G6: - | H6: 0.0625 | I6: 13 | J6: 9 | K6: 12 | L6: 10 | M6: 34 | N6: - | O6: 0.0625 | P6: 81 | Q6: 44 | R6: 46 | S6: 77 | T6: 84 | U6: - | V6: 0.0625 | W6: 12 | X6: 4 | Y6: 7 | Z6: 9 | AA6: 11 | AB6: - | AC6: 0.0625 | AD6: 0.25625 | AE6: 0.1 | AF6: 0.15 | AG6: 0.17847222 | AH6: 0.22291667 | AI6: - | AJ6: 0.0625 | AK6: =HLOOKUP($AX$1,[1]EU!$B$2:$AF$51,XFD6,0) -> 16 | AL6: =HLOOKUP($AX$1,'[1]Enterprise Aspiring'!$B$2:$AF$51,XFD6,0) -> 9 | AM6: =HLOOKUP($AX$1,'[1]Red Cash'!$B$2:$AF$51,XFD6,0) -> 19 | AN6: =HLOOKUP($AX$1,[1]Aspiring!$B$2:$AF$51,XFD6,0) -> 18 | AO6: =HLOOKUP($AX$1,[1]ICC!$B$2:$AF$51,XFD6,0) -> 30 | AP6: =HLOOKUP($AX$1,[1]CM!$B$2:$AF$51,XFD6,0) -> 0 | AQ6: 0.0625 | AR6: =EU!N5 -> Wait | AS6: ='R.EU'!N5 -> Achived | AT6: ='Red Cash'!N5 -> Wait | AU6: =Aspiring!N5 -> Wait | AV6: =ICC!N5 -> Achived | AW6: ='SME-CM'!N5 | XFD6: =XFD5+1 -> 6
A7: 0.083333333 | B7: 1 | C7: 1 | D7: 1 | E7: 1 | F7: 0.94 | G7: - | H7: 0.083333333 | I7: 9 | J7: 5 | K7: 9 | L7: 11 | M7: 43 | N7: - | O7: 0.083333333 | P7: 87 | Q7: 34 | R7: 52 | S7: 66 | T7: 80 | U7: - | V7: 0.083333333 | W7: 8 | X7: 4 | Y7: 6 | Z7: 10 | AA7: 10 | AB7: - | AC7: 0.083333333 | AD7: 0.19930556 | AE7: 0.082638889 | AF7: 0.12291667 | AG7: 0.20208333 | AH7: 0.30763889 | AI7: - | AJ7: 0.083333333 | AK7: =HLOOKUP($AX$1,[1]EU!$B$2:$AF$51,XFD7,0) -> 13 | AL7: =HLOOKUP($AX$1,'[1]Enterprise Aspiring'!$B$2:$AF$51,XFD7,0) -> 5 | AM7: =HLOOKUP($AX$1,'[1]Red Cash'!$B$2:$AF$51,XFD7,0) -> 15 | AN7: =HLOOKUP($AX$1,[1]Aspiring!$B$2:$AF$51,XFD7,0) -> 19 | AO7: =HLOOKUP($AX$1,[1]ICC!$B$2:$AF$51,XFD7,0) -> 24 | AP7: =HLOOKUP($AX$1,[1]CM!$B$2:$AF$51,XFD7,0) -> 0 | AQ7: 0.083333333 | AR7: =EU!N6 -> Wait | AS7: ='R.EU'!N6 -> Achived | AT7: ='Red Cash'!N6 -> Wait | AU7: =Aspiring!N6 -> Wait | AV7: =ICC!N6 -> Achived | AW7: ='SME-CM'!N6 | XFD7: =XFD6+1 -> 7
A8: 0.10416667 | B8: 0.8 | C8: 1 | D8: 1 | E8: 1 | F8: 1 | G8: - | H8: 0.10416667 | I8: 6 | J8: 1 | K8: 3 | L8: 5 | M8: 28 | N8: - | O8: 0.10416667 | P8: 79 | Q8: 16 | R8: 44 | S8: 52 | T8: 71 | U8: - | V8: 0.10416667 | W8: 7 | X8: 3 | Y8: 6 | Z8: 9 | AA8: 8 | AB8: - | AC8: 0.10416667 | AD8: 0.18263889 | AE8: 0.082638889 | AF8: 0.12291667 | AG8: 0.18958333 | AH8: 0.26388889 | AI8: - | AJ8: 0.10416667 | AK8: =HLOOKUP($AX$1,[1]EU!$B$2:$AF$51,XFD8,0) -> 11 | AL8: =HLOOKUP($AX$1,'[1]Enterprise Aspiring'!$B$2:$AF$51,XFD8,0) -> 2 | AM8: =HLOOKUP($AX$1,'[1]Red Cash'!$B$2:$AF$51,XFD8,0) -> 11 | AN8: =HLOOKUP($AX$1,[1]Aspiring!$B$2:$AF$51,XFD8,0) -> 13 | AO8: =HLOOKUP($AX$1,[1]ICC!$B$2:$AF$51,XFD8,0) -> 19 | AP8: =HLOOKUP($AX$1,[1]CM!$B$2:$AF$51,XFD8,0) -> 0 | AQ8: 0.10416667 | AR8: =EU!N7 -> Wait | AS8: ='R.EU'!N7 -> Wait | AT8: ='Red Cash'!N7 -> Wait | AU8: =Aspiring!N7 -> Wait | AV8: =ICC!N7 -> Achived | AW8: ='SME-CM'!N7 | XFD8: =XFD7+1 -> 8
A9: 0.125 | B9: 1 | C9: 0 | D9: - | E9: 0.8 | F9: - | G9: - | H9: 0.125 | I9: 4 | J9: 0 | K9: - | L9: 6 | M9: - | N9: - | O9: 0.125 | P9: 76 | Q9: 25 | R9: - | S9: 60 | T9: - | U9: - | V9: 0.125 | W9: 7 | X9: 3 | Y9: - | Z9: 5 | AA9: - | AB9: - | AC9: 0.125 | AD9: 0.10972222 | AE9: 0.040277778 | AF9: - | AG9: 0.088194444 | AH9: - | AI9: - | AJ9: 0.125 | AK9: =HLOOKUP($AX$1,[1]EU!$B$2:$AF$51,XFD9,0) -> 5 | AL9: =HLOOKUP($AX$1,'[1]Enterprise Aspiring'!$B$2:$AF$51,XFD9,0) -> 4 | AM9: =HLOOKUP($AX$1,'[1]Red Cash'!$B$2:$AF$51,XFD9,0) -> 0 | AN9: =HLOOKUP($AX$1,[1]Aspiring!$B$2:$AF$51,XFD9,0) -> 11 | AO9: =HLOOKUP($AX$1,[1]ICC!$B$2:$AF$51,XFD9,0) -> 0 | AP9: =HLOOKUP($AX$1,[1]CM!$B$2:$AF$51,XFD9,0) -> 0 | AQ9: 0.125 | AR9: =EU!N8 -> Wait | AS9: ='R.EU'!N8 -> Wait | AT9: ='Red Cash'!N8 | AU9: =Aspiring!N8 -> Wait | AV9: =ICC!N8 | AW9: ='SME-CM'!N8 | XFD9: =XFD8+1 -> 9
A10: 0.14583333 | B10: 1 | C10: 0 | D10: - | E10: 0.84 | F10: - | G10: - | H10: 0.14583333 | I10: 7 | J10: 0 | K10: - | L10: 8 | M10: - | N10: - | O10: 0.14583333 | P10: 74 | Q10: 27 | R10: - | S10: 63 | T10: - | U10: - | V10: 0.14583333 | W10: 7 | X10: 3 | Y10: - | Z10: 5 | AA10: - | AB10: - | AC10: 0.14583333 | AD10: 0.14513889 | AE10: 0.055555556 | AF10: - | AG10: 0.11319444 | AH10: - | AI10: - | AJ10: 0.14583333 | AK10: =HLOOKUP($AX$1,[1]EU!$B$2:$AF$51,XFD10,0) -> 5 | AL10: =HLOOKUP($AX$1,'[1]Enterprise Aspiring'!$B$2:$AF$51,XFD10,0) -> 2 | AM10: =HLOOKUP($AX$1,'[1]Red Cash'!$B$2:$AF$51,XFD10,0) -> 0 | AN10: =HLOOKUP($AX$1,[1]Aspiring!$B$2:$AF$51,XFD10,0) -> 7 | AO10: =HLOOKUP($AX$1,[1]ICC!$B$2:$AF$51,XFD10,0) -> 0 | AP10: =HLOOKUP($AX$1,[1]CM!$B$2:$AF$51,XFD10,0) -> 0 | AQ10: 0.14583333 | AR10: =EU!N9 -> Achived | AS10: ='R.EU'!N9 -> Wait | AT10: ='Red Cash'!N9 | AU10: =Aspiring!N9 -> Achived | AV10: =ICC!N9 | AW10: ='SME-CM'!N9 | XFD10: =XFD9+1 -> 10
A11: 0.16666667 | B11: 1 | C11: 0 | D11: - | E11: 1 | F11: - | G11: - | H11: 0.16666667 | I11: 2 | J11: 0 | K11: - | L11: 7 | M11: - | N11: - | O11: 0.16666667 | P11: 93 | Q11: 35 | R11: - | S11: 53 | T11: - | U11: - | V11: 0.16666667 | W11: 6 | X11: 3 | Y11: - | Z11: 5 | AA11: - | AB11: - | AC11: 0.16666667 | AD11: 0.11527778 | AE11: 0.061805556 | AF11: - | AG11: 0.10347222 | AH11: - | AI11: - | AJ11: 0.16666667 | AK11: =HLOOKUP($AX$1,[1]EU!$B$2:$AF$51,XFD11,0) -> 6 | AL11: =HLOOKUP($AX$1,'[1]Enterprise Aspiring'!$B$2:$AF$51,XFD11,0) -> 3 | AM11: =HLOOKUP($AX$1,'[1]Red Cash'!$B$2:$AF$51,XFD11,0) -> 0 | AN11: =HLOOKUP($AX$1,[1]Aspiring!$B$2:$AF$51,XFD11,0) -> 9 | AO11: =HLOOKUP($AX$1,[1]ICC!$B$2:$AF$51,XFD11,0) -> 0 | AP11: =HLOOKUP($AX$1,[1]CM!$B$2:$AF$51,XFD11,0) -> 0 | AQ11: 0.16666667 | AR11: =EU!N10 -> Wait | AS11: ='R.EU'!N10 | AT11: ='Red Cash'!N10 | AU11: =Aspiring!N10 -> Wait | AV11: =ICC!N10 | AW11: ='SME-CM'!N10 | XFD11: =XFD10+1 -> 11
A12: 0.1875 | B12: 1 | C12: 1 | D12: - | E12: 1 | F12: - | G12: - | H12: 0.1875 | I12: 2 | J12: 2 | K12: - | L12: 3 | M12: - | N12: - | O12: 0.1875 | P12: 89 | Q12: 7 | R12: - | S12: 89 | T12: - | U12: - | V12: 0.1875 | W12: 6 | X12: 3 | Y12: - | Z12: 4 | AA12: - | AB12: - | AC12: 0.1875 | AD12: 0.12083333 | AE12: 0.061111111 | AF12: - | AG12: 0.069444444 | AH12: - | AI12: - | AJ12: 0.1875 | AK12: =HLOOKUP($AX$1,[1]EU!$B$2:$AF$51,XFD12,0) -> 4 | AL12: =HLOOKUP($AX$1,'[1]Enterprise Aspiring'!$B$2:$AF$51,XFD12,0) -> 3 | AM12: =HLOOKUP($AX$1,'[1]Red Cash'!$B$2:$AF$51,XFD12,0) -> 0 | AN12: =HLOOKUP($AX$1,[1]Aspiring!$B$2:$AF$51,XFD12,0) -> 2 | AO12: =HLOOKUP($AX$1,[1]ICC!$B$2:$AF$51,XFD12,0) -> 0 | AP12: =HLOOKUP($AX$1,[1]CM!$B$2:$AF$51,XFD12,0) -> 0 | AQ12: 0.1875 | AR12: =EU!N11 -> Wait | AS12: ='R.EU'!N11 -> Wait | AT12: ='Red Cash'!N11 | AU12: =Aspiring!N11 -> Achived | AV12: =ICC!N11 | AW12: ='SME-CM'!N11 | XFD12: =XFD11+1 -> 12
A13: 0.20833333 | B13: 1 | C13: 1 | D13: - | E13: 1 | F13: - | G13: - | H13: 0.20833333 | I13: 3 | J13: 1 | K13: - | L13: 6 | M13: - | N13: - | O13: 0.20833333 | P13: 87 | Q13: 1 | R13: - | S13: 49 | T13: - | U13: - | V13: 0.20833333 | W13: 5 | X13: 3 | Y13: - | Z13: 5 | AA13: - | AB13: - | AC13: 0.20833333 | AD13: 0.10347222 | AE13: 0.061805556 | AF13: - | AG13: 0.095833333 | AH13: - | AI13: - | AJ13: 0.20833333 | AK13: =HLOOKUP($AX$1,[1]EU!$B$2:$AF$51,XFD13,0) -> 4 | AL13: =HLOOKUP($AX$1,'[1]Enterprise Aspiring'!$B$2:$AF$51,XFD13,0) -> 2 | AM13: =HLOOKUP($AX$1,'[1]Red Cash'!$B$2:$AF$51,XFD13,0) -> 0 | AN13: =HLOOKUP($AX$1,[1]Aspiring!$B$2:$AF$51,XFD13,0) -> 3 | AO13: =HLOOKUP($AX$1,[1]ICC!$B$2:$AF$51,XFD13,0) -> 0 | AP13: =HLOOKUP($AX$1,[1]CM!$B$2:$AF$51,XFD13,0) -> 0 | AQ13: 0.20833333 | AR13: =EU!N12 -> Wait | AS13: ='R.EU'!N12 -> Wait | AT13: ='Red Cash'!N12 | AU13: =Aspiring!N12 -> Achived | AV13: =ICC!N12 | AW13: ='SME-CM'!N12 | XFD13: =XFD12+1 -> 13
A14: 0.22916667 | B14: 1 | C14: 1 | D14: - | E14: 1 | F14: - | G14: - | H14: 0.22916667 | I14: 2 | J14: 3 | K14: - | L14: 5 | M14: - | N14: - | O14: 0.22916667 | P14: 83 | Q14: 26 | R14: - | S14: 43 | T14: - | U14: - | V14: 0.22916667 | W14: 4 | X14: 3 | Y14: - | Z14: 5 | AA14: - | AB14: - | AC14: 0.22916667 | AD14: 0.098611111 | AE14: 0.047916667 | AF14: - | AG14: 0.10347222 | AH14: - | AI14: - | AJ14: 0.22916667 | AK14: =HLOOKUP($AX$1,[1]EU!$B$2:$AF$51,XFD14,0) -> 8 | AL14: =HLOOKUP($AX$1,'[1]Enterprise Aspiring'!$B$2:$AF$51,XFD14,0) -> 3 | AM14: =HLOOKUP($AX$1,'[1]Red Cash'!$B$2:$AF$51,XFD14,0) -> 0 | AN14: =HLOOKUP($AX$1,[1]Aspiring!$B$2:$AF$51,XFD14,0) -> 6 | AO14: =HLOOKUP($AX$1,[1]ICC!$B$2:$AF$51,XFD14,0) -> 0 | AP14: =HLOOKUP($AX$1,[1]CM!$B$2:$AF$51,XFD14,0) -> 0 | AQ14: 0.22916667 | AR14: =EU!N13 -> Wait | AS14: ='R.EU'!N13 -> Achived | AT14: ='Red Cash'!N13 | AU14: =Aspiring!N13 -> Wait | AV14: =ICC!N13 | AW14: ='SME-CM'!N13 | XFD14: =XFD13+1 -> 14
A15: 0.25 | B15: 1 | C15: 1 | D15: - | E15: 1 | F15: - | G15: - | H15: 0.25 | I15: 8 | J15: 3 | K15: - | L15: 3 | M15: - | N15: - | O15: 0.25 | P15: 92 | Q15: 16 | R15: - | S15: 48 | T15: - | U15: - | V15: 0.25 | W15: 4 | X15: 3 | Y15: - | Z15: 4 | AA15: - | AB15: - | AC15: 0.25 | AD15: 0.082638889 | AE15: 0.059722222 | AF15: - | AG15: 0.086805556 | AH15: - | AI15: - | AJ15: 0.25 | AK15: =HLOOKUP($AX$1,[1]EU!$B$2:$AF$51,XFD15,0) -> 7 | AL15: =HLOOKUP($AX$1,'[1]Enterprise Aspiring'!$B$2:$AF$51,XFD15,0) -> 4 | AM15: =HLOOKUP($AX$1,'[1]Red Cash'!$B$2:$AF$51,XFD15,0) -> 0 | AN15: =HLOOKUP($AX$1,[1]Aspiring!$B$2:$AF$51,XFD15,0) -> 10 | AO15: =HLOOKUP($AX$1,[1]ICC!$B$2:$AF$51,XFD15,0) -> 0 | AP15: =HLOOKUP($AX$1,[1]CM!$B$2:$AF$51,XFD15,0) -> 0 | AQ15: 0.25 | AR15: =EU!N14 -> Achived | AS15: ='R.EU'!N14 -> Wait | AT15: ='Red Cash'!N14 | AU15: =Aspiring!N14 -> Wait | AV15: =ICC!N14 | AW15: ='SME-CM'!N14 | XFD15: =XFD14+1 -> 15
A16: 0.27083333 | B16: 1 | C16: 1 | D16: - | E16: 0.66 | F16: - | G16: - | H16: 0.27083333 | I16: 7 | J16: 1 | K16: - | L16: 12 | M16: - | N16: - | O16: 0.27083333 | P16: 82 | Q16: 7 | R16: - | S16: 61 | T16: - | U16: - | V16: 0.27083333 | W16: 4 | X16: 3 | Y16: - | Z16: 4 | AA16: - | AB16: - | AC16: 0.27083333 | AD16: 0.082638889 | AE16: 0.061805556 | AF16: - | AG16: 0.082638889 | AH16: - | AI16: - | AJ16: 0.27083333 | AK16: =HLOOKUP($AX$1,[1]EU!$B$2:$AF$51,XFD16,0) -> 10 | AL16: =HLOOKUP($AX$1,'[1]Enterprise Aspiring'!$B$2:$AF$51,XFD16,0) -> 5 | AM16: =HLOOKUP($AX$1,'[1]Red Cash'!$B$2:$AF$51,XFD16,0) -> 0 | AN16: =HLOOKUP($AX$1,[1]Aspiring!$B$2:$AF$51,XFD16,0) -> 6 | AO16: =HLOOKUP($AX$1,[1]ICC!$B$2:$AF$51,XFD16,0) -> 0 | AP16: =HLOOKUP($AX$1,[1]CM!$B$2:$AF$51,XFD16,0) -> 0 | AQ16: 0.27083333 | AR16: =EU!N15 -> Wait | AS16: ='R.EU'!N15 -> Wait | AT16: ='Red Cash'!N15 | AU16: =Aspiring!N15 -> Achived | AV16: =ICC!N15 | AW16: ='SME-CM'!N15 | XFD16: =XFD15+1 -> 16
A17: 0.29166667 | B17: 0.79 | C17: 1 | D17: - | E17: 0.89 | F17: 0.66 | G17: - | H17: 0.29166667 | I17: 14 | J17: 5 | K17: - | L17: 17 | M17: 17 | N17: - | O17: 0.29166667 | P17: 88 | Q17: 26 | R17: - | S17: 75 | T17: 70 | U17: - | V17: 0.29166667 | W17: 7 | X17: 3 | Y17: - | Z17: 7 | AA17: 5 | AB17: - | AC17: 0.29166667 | AD17: 0.12569444 | AE17: 0.061805556 | AF17: - | AG17: 0.12708333 | AH17: 0.059722222 | AI17: - | AJ17: 0.29166667 | AK17: =HLOOKUP($AX$1,[1]EU!$B$2:$AF$51,XFD17,0) -> 14 | AL17: =HLOOKUP($AX$1,'[1]Enterprise Aspiring'!$B$2:$AF$51,XFD17,0) -> 8 | AM17: =HLOOKUP($AX$1,'[1]Red Cash'!$B$2:$AF$51,XFD17,0) -> 0 | AN17: =HLOOKUP($AX$1,[1]Aspiring!$B$2:$AF$51,XFD17,0) -> 15 | AO17: =HLOOKUP($AX$1,[1]ICC!$B$2:$AF$51,XFD17,0) -> 11 | AP17: =HLOOKUP($AX$1,[1]CM!$B$2:$AF$51,XFD17,0) -> 0 | AQ17: 0.29166667 | AR17: =EU!N16 -> Achived | AS17: ='R.EU'!N16 -> Wait | AT17: ='Red Cash'!N16 | AU17: =Aspiring!N16 -> Achived | AV17: =ICC!N16 -> Achived | AW17: ='SME-CM'!N16 | XFD17: =XFD16+1 -> 17
A18: 0.3125 | B18: 0.9 | C18: 1 | D18: - | E18: 0.94 | F18: 0.81 | G18: - | H18: 0.3125 | I18: 21 | J18: 3 | K18: - | L18: 19 | M18: 18 | N18: - | O18: 0.3125 | P18: 85 | Q18: 40 | R18: - | S18: 72 | T18: 89 | U18: - | V18: 0.3125 | W18: 7 | X18: 3 | Y18: - | Z18: 10 | AA18: 5 | AB18: - | AC18: 0.3125 | AD18: 0.18125 | AE18: 0.061111111 | AF18: - | AG18: 3;37 | AH18: 0.10277778 | AI18: - | AJ18: 0.3125 | AK18: =HLOOKUP($AX$1,[1]EU!$B$2:$AF$51,XFD18,0) -> 21 | AL18: =HLOOKUP($AX$1,'[1]Enterprise Aspiring'!$B$2:$AF$51,XFD18,0) -> 9 | AM18: =HLOOKUP($AX$1,'[1]Red Cash'!$B$2:$AF$51,XFD18,0) -> 0 | AN18: =HLOOKUP($AX$1,[1]Aspiring!$B$2:$AF$51,XFD18,0) -> 19 | AO18: =HLOOKUP($AX$1,[1]ICC!$B$2:$AF$51,XFD18,0) -> 13 | AP18: =HLOOKUP($AX$1,[1]CM!$B$2:$AF$51,XFD18,0) -> 0 | AQ18: 0.3125 | AR18: =EU!N17 -> Achived | AS18: ='R.EU'!N17 -> Wait | AT18: ='Red Cash'!N17 | AU18: =Aspiring!N17 -> Achived | AV18: =ICC!N17 -> Achived | AW18: ='SME-CM'!N17 | XFD18: =XFD17+1 -> 18
A19: 0.33333333 | B19: 0.93 | C19: 1 | D19: 1 | E19: 0.95 | F19: 1 | G19: 0.75 | H19: 0.33333333 | I19: 17 | J19: 6 | K19: 10 | L19: 21 | M19: 15 | N19: 14 | O19: 0.33333333 | P19: 86 | Q19: 33 | R19: 28 | S19: 66 | T19: 69 | U19: 74 | V19: 0.33333333 | W19: 7 | X19: 3 | Y19: 5 | Z19: 11 | AA19: 6 | AB19: 4 | AC19: 0.33333333 | AD19: 0.14236111 | AE19: 0.061111111 | AF19: 0.13611111 | AG19: 0.21041667 | AH19: 0.12777778 | AI19: 0.08125 | AJ19: 0.33333333 | AK19: =HLOOKUP($AX$1,[1]EU!$B$2:$AF$51,XFD19,0) -> 28 | AL19: =HLOOKUP($AX$1,'[1]Enterprise Aspiring'!$B$2:$AF$51,XFD19,0) -> 14 | AM19: =HLOOKUP($AX$1,'[1]Red Cash'!$B$2:$AF$51,XFD19,0) -> 15 | AN19: =HLOOKUP($AX$1,[1]Aspiring!$B$2:$AF$51,XFD19,0) -> 15 | AO19: =HLOOKUP($AX$1,[1]ICC!$B$2:$AF$51,XFD19,0) -> 15 | AP19: =HLOOKUP($AX$1,[1]CM!$B$2:$AF$51,XFD19,0) -> 14 | AQ19: 0.33333333 | AR19: =EU!N18 -> Wait | AS19: ='R.EU'!N18 -> Wait | AT19: ='Red Cash'!N18 -> Wait | AU19: =Aspiring!N18 -> Achived | AV19: =ICC!N18 -> Achived | AW19: ='SME-CM'!N18 -> Achived | XFD19: =XFD18+1 -> 19
A20: 0.35416667 | B20: 0.75 | C20: 0.9 | D20: 1 | E20: 1 | F20: 0.8 | G20: 1 | H20: 0.35416667 | I20: 33 | J20: 10 | K20: 19 | L20: 27 | M20: 29 | N20: 11 | O20: 0.35416667 | P20: 92 | Q20: 54 | R20: 40 | S20: 69 | T20: 89 | U20: 83 | V20: 0.35416667 | W20: 10 | X20: 3 | Y20: 8 | Z20: 13 | AA20: 8 | AB20: 5 | AC20: 0.35416667 | AD20: 0.15902778 | AE20: 0.053472222 | AF20: 0.12083333 | AG20: 0.24583333 | AH20: 0.15555556 | AI20: 0.10625 | AJ20: 0.35416667 | AK20: =HLOOKUP($AX$1,[1]EU!$B$2:$AF$51,XFD20,0) -> 36 | AL20: =HLOOKUP($AX$1,'[1]Enterprise Aspiring'!$B$2:$AF$51,XFD20,0) -> 14 | AM20: =HLOOKUP($AX$1,'[1]Red Cash'!$B$2:$AF$51,XFD20,0) -> 16 | AN20: =HLOOKUP($AX$1,[1]Aspiring!$B$2:$AF$51,XFD20,0) -> 21 | AO20: =HLOOKUP($AX$1,[1]ICC!$B$2:$AF$51,XFD20,0) -> 21 | AP20: =HLOOKUP($AX$1,[1]CM!$B$2:$AF$51,XFD20,0) -> 10 | AQ20: 0.35416667 | AR20: =EU!N19 -> Wait | AS20: ='R.EU'!N19 -> Wait | AT20: ='Red Cash'!N19 -> Achived | AU20: =Aspiring!N19 -> Achived | AV20: =ICC!N19 -> Achived | AW20: ='SME-CM'!N19 -> Achived | XFD20: =XFD19+1 -> 20
A21: 0.375 | B21: 0.75 | C21: 0.76 | D21: 1 | E21: 0.95 | F21: 0.8 | G21: 0.94 | H21: 0.375 | I21: 43 | J21: 12 | K21: 14 | L21: 24 | M21: 14 | N21: 24 | O21: 0.375 | P21: 87 | Q21: 59 | R21: 41 | S21: 65 | T21: 90 | U21: 71 | V21: 0.375 | W21: 12 | X21: 5 | Y21: 5 | Z21: 14 | AA21: 9 | AB21: 4 | AC21: 0.375 | AD21: 0.25694444 | AE21: 0.080555556 | AF21: 0.15069444 | AG21: 0.25069444 | AH21: 0.19027778 | AI21: 0.072222222 | AJ21: 0.375 | AK21: =HLOOKUP($AX$1,[1]EU!$B$2:$AF$51,XFD21,0) -> 54 | AL21: =HLOOKUP($AX$1,'[1]Enterprise Aspiring'!$B$2:$AF$51,XFD21,0) -> 21 | AM21: =HLOOKUP($AX$1,'[1]Red Cash'!$B$2:$AF$51,XFD21,0) -> 23 | AN21: =HLOOKUP($AX$1,[1]Aspiring!$B$2:$AF$51,XFD21,0) -> 21 | AO21: =HLOOKUP($AX$1,[1]ICC!$B$2:$AF$51,XFD21,0) -> 24 | AP21: =HLOOKUP($AX$1,[1]CM!$B$2:$AF$51,XFD21,0) -> 10 | AQ21: 0.375 | AR21: =EU!N20 -> Wait | AS21: ='R.EU'!N20 -> Wait | AT21: ='Red Cash'!N20 -> Wait | AU21: =Aspiring!N20 -> Achived | AV21: =ICC!N20 -> Wait | AW21: ='SME-CM'!N20 -> Achived | XFD21: =XFD20+1 -> 21
A22: 0.39583333 | B22: 0.93 | C22: 1 | D22: 1 | E22: 0.53 | F22: 0.45 | G22: 0.83 | H22: 0.39583333 | I22: 37 | J22: 9 | K22: 25 | L22: 44 | M22: 41 | N22: 13 | O22: 0.39583333 | P22: 87 | Q22: 58 | R22: 40 | S22: 81 | T22: 94 | U22: 96 | V22: 0.39583333 | W22: 14 | X22: 6 | Y22: 9 | Z22: 17 | AA22: 11 | AB22: 6 | AC22: 0.39583333 | AD22: 0.27361111 | AE22: 0.10763889 | AF22: 0.18125 | AG22: 0.34305556 | AH22: 0.1875 | AI22: 0.12152778 | AJ22: 0.39583333 | AK22: =HLOOKUP($AX$1,[1]EU!$B$2:$AF$51,XFD22,0) -> 63 | AL22: =HLOOKUP($AX$1,'[1]Enterprise Aspiring'!$B$2:$AF$51,XFD22,0) -> 19 | AM22: =HLOOKUP($AX$1,'[1]Red Cash'!$B$2:$AF$51,XFD22,0) -> 28 | AN22: =HLOOKUP($AX$1,[1]Aspiring!$B$2:$AF$51,XFD22,0) -> 44 | AO22: =HLOOKUP($AX$1,[1]ICC!$B$2:$AF$51,XFD22,0) -> 29 | AP22: =HLOOKUP($AX$1,[1]CM!$B$2:$AF$51,XFD22,0) -> 15 | AQ22: 0.39583333 | AR22: =EU!N21 -> Wait | AS22: ='R.EU'!N21 -> Wait | AT22: ='Red Cash'!N21 -> Wait | AU22: =Aspiring!N21 -> Achived | AV22: =ICC!N21 -> Achived | AW22: ='SME-CM'!N21 -> Wait | XFD22: =XFD21+1 -> 22
A23: 0.41666667 | B23: 0.97 | C23: 0.86 | D23: 1 | E23: 0.97 | F23: 0.66 | G23: 0.92 | H23: 0.41666667 | I23: 36 | J23: 15 | K23: 24 | L23: 38 | M23: 38 | N23: 21 | O23: 0.41666667 | P23: 88 | Q23: 68 | R23: 24 | S23: 69 | T23: 98 | U23: 93 | V23: 0.41666667 | W23: 15 | X23: 6 | Y23: 9 | Z23: 17 | AA23: 13 | AB23: 8 | AC23: 0.41666667 | AD23: 0.29652778 | AE23: 0.15347222 | AF23: 0.18541667 | AG23: 0.34375 | AH23: 0.27222222 | AI23: 0.15 | AJ23: 100 | AK23: =HLOOKUP($AX$1,[1]EU!$B$2:$AF$51,XFD23,0) -> 62 | AL23: =HLOOKUP($AX$1,'[1]Enterprise Aspiring'!$B$2:$AF$51,XFD23,0) -> 19 | AM23: =HLOOKUP($AX$1,'[1]Red Cash'!$B$2:$AF$51,XFD23,0) -> 34 | AN23: =HLOOKUP($AX$1,[1]Aspiring!$B$2:$AF$51,XFD23,0) -> 45 | AO23: =HLOOKUP($AX$1,[1]ICC!$B$2:$AF$51,XFD23,0) -> 34 | AP23: =HLOOKUP($AX$1,[1]CM!$B$2:$AF$51,XFD23,0) -> 20 | AQ23: 0.41666667 | AR23: =EU!N22 -> Wait | AS23: ='R.EU'!N22 -> Wait | AT23: ='Red Cash'!N22 -> Wait | AU23: =Aspiring!N22 -> Wait | AV23: =ICC!N22 -> Achived | AW23: ='SME-CM'!N22 -> Achived | XFD23: =XFD22+1 -> 23
A24: 0.4375 | B24: 0.78 | C24: 1 | D24: 1 | E24: 0.83 | F24: 0.38 | G24: 0.77 | H24: 0.4375 | I24: 56 | J24: 16 | K24: 33 | L24: 47 | M24: 44 | N24: 23 | O24: 0.4375 | P24: 94 | Q24: 64 | R24: 36 | S24: 84 | T24: 99 | U24: 93 | V24: 0.4375 | W24: 16 | X24: 8 | Y24: 9 | Z24: 18 | AA24: 14 | AB24: 8 | AC24: 0.4375 | AD24: 0.32986111 | AE24: 0.15347222 | AF24: 0.18541667 | AG24: 0.34375 | AH24: 0.27222222 | AI24: 0.15 | AJ24: 0.4375 | AK24: =HLOOKUP($AX$1,[1]EU!$B$2:$AF$51,XFD24,0) -> 65 | AL24: =HLOOKUP($AX$1,'[1]Enterprise Aspiring'!$B$2:$AF$51,XFD24,0) -> 20 | AM24: =HLOOKUP($AX$1,'[1]Red Cash'!$B$2:$AF$51,XFD24,0) -> 36 | AN24: =HLOOKUP($AX$1,[1]Aspiring!$B$2:$AF$51,XFD24,0) -> 43 | AO24: =HLOOKUP($AX$1,[1]ICC!$B$2:$AF$51,XFD24,0) -> 41 | AP24: =HLOOKUP($AX$1,[1]CM!$B$2:$AF$51,XFD24,0) -> 22 | AQ24: 0.4375 | AR24: =EU!N23 -> Wait | AS24: ='R.EU'!N23 -> Wait | AT24: ='Red Cash'!N23 -> Wait | AU24: =Aspiring!N23 -> Achived | AV24: =ICC!N23 -> Achived | AW24: ='SME-CM'!N23 -> Achived | XFD24: =XFD23+1 -> 24
A25: 0.45833333 | B25: 0.65 | C25: 0.81 | D25: 1 | E25: 1 | F25: 0.81 | G25: 0.59 | H25: 0.45833333 | I25: 57 | J25: 22 | K25: 28 | L25: 36 | M25: 50 | N25: 25 | O25: 0.45833333 | P25: 92 | Q25: 83 | R25: 49 | S25: 70 | T25: 93 | U25: 96 | V25: 0.45833333 | W25: 19 | X25: 9 | Y25: 10 | Z25: 19 | AA25: 13 | AB25: 8 | AC25: 0.45833333 | AD25: 0.34722222 | AE25: 0.16875 | AF25: 0.18680556 | AG25: 0.37152778 | AH25: 0.29097222 | AI25: 0.16597222 | AJ25: 0.45833333 | AK25: =HLOOKUP($AX$1,[1]EU!$B$2:$AF$51,XFD25,0) -> 60 | AL25: =HLOOKUP($AX$1,'[1]Enterprise Aspiring'!$B$2:$AF$51,XFD25,0) -> 22 | AM25: =HLOOKUP($AX$1,'[1]Red Cash'!$B$2:$AF$51,XFD25,0) -> 41 | AN25: =HLOOKUP($AX$1,[1]Aspiring!$B$2:$AF$51,XFD25,0) -> 45 | AO25: =HLOOKUP($AX$1,[1]ICC!$B$2:$AF$51,XFD25,0) -> 46 | AP25: =HLOOKUP($AX$1,[1]CM!$B$2:$AF$51,XFD25,0) -> 24 | AQ25: 0.45833333 | AR25: =EU!N24 -> Lost | AS25: ='R.EU'!N24 -> Achived | AT25: ='Red Cash'!N24 -> Wait | AU25: =Aspiring!N24 -> Wait | AV25: =ICC!N24 -> Achived | AW25: ='SME-CM'!N24 -> Achived | XFD25: =XFD24+1 -> 25
A26: 0.47916667 | B26: 0.78 | C26: 0.94 | D26: 1 | E26: 0.85 | F26: 0.89 | G26: 0.78 | H26: 0.47916667 | I26: 51 | J26: 17 | K26: 39 | L26: 36 | M26: 46 | N26: 17 | O26: 0.47916667 | P26: 94 | Q26: 79 | R26: 52 | S26: 81 | T26: 95 | U26: 94 | V26: 0.47916667 | W26: 17 | X26: 8 | Y26: 10 | Z26: 18 | AA26: 13 | AB26: 8 | AC26: 0.47916667 | AD26: 0.3875 | AE26: 0.175 | AF26: 0.17569444 | AG26: 0.33819444 | AH26: 0.26875 | AI26: 0.16597222 | AJ26: 0.47916667 | AK26: =HLOOKUP($AX$1,[1]EU!$B$2:$AF$51,XFD26,0) -> 67 | AL26: =HLOOKUP($AX$1,'[1]Enterprise Aspiring'!$B$2:$AF$51,XFD26,0) -> 22 | AM26: =HLOOKUP($AX$1,'[1]Red Cash'!$B$2:$AF$51,XFD26,0) -> 37 | AN26: =HLOOKUP($AX$1,[1]Aspiring!$B$2:$AF$51,XFD26,0) -> 40 | AO26: =HLOOKUP($AX$1,[1]ICC!$B$2:$AF$51,XFD26,0) -> 49 | AP26: =HLOOKUP($AX$1,[1]CM!$B$2:$AF$51,XFD26,0) -> 24 | AQ26: 0.47916667 | AR26: =EU!N25 -> Wait | AS26: ='R.EU'!N25 -> Wait | AT26: ='Red Cash'!N25 -> Achived | AU26: =Aspiring!N25 -> Wait | AV26: =ICC!N25 -> Wait | AW26: ='SME-CM'!N25 -> Wait | XFD26: =XFD25+1 -> 26
A27: 0.5 | B27: 0.75 | C27: 0.82 | D27: 1 | E27: 1 | F27: 0.94 | G27: 0.84 | H27: 0.5 | I27: 69 | J27: 16 | K27: 28 | L27: 47 | M27: 43 | N27: 26 | O27: 0.5 | P27: 94 | Q27: 83 | R27: 55 | S27: 74 | T27: 92 | U27: 93 | V27: 0.5 | W27: 20 | X27: 7 | Y27: 11 | Z27: 21 | AA27: 14 | AB27: 8 | AC27: 0.5 | AD27: 0.39722222 | AE27: 0.15347222 | AF27: 0.20902778 | AG27: 0.43402778 | AH27: 0.29236111 | AI27: 0.16527778 | AJ27: 0.5 | AK27: =HLOOKUP($AX$1,[1]EU!$B$2:$AF$51,XFD27,0) -> 67 | AL27: =HLOOKUP($AX$1,'[1]Enterprise Aspiring'!$B$2:$AF$51,XFD27,0) -> 22 | AM27: =HLOOKUP($AX$1,'[1]Red Cash'!$B$2:$AF$51,XFD27,0) -> 40 | AN27: =HLOOKUP($AX$1,[1]Aspiring!$B$2:$AF$51,XFD27,0) -> 57 | AO27: =HLOOKUP($AX$1,[1]ICC!$B$2:$AF$51,XFD27,0) -> 57 | AP27: =HLOOKUP($AX$1,[1]CM!$B$2:$AF$51,XFD27,0) -> 26 | AQ27: 0.5 | AR27: =EU!N26 -> Achived | AS27: ='R.EU'!N26 -> Wait | AT27: ='Red Cash'!N26 -> Wait | AU27: =Aspiring!N26 -> Wait | AV27: =ICC!N26 -> Wait | AW27: ='SME-CM'!N26 -> Achived | XFD27: =XFD26+1 -> 27
A28: 0.52083333 | B28: 0.71 | C28: 0.75 | D28: 1 | E28: 0.81 | F28: 0.35 | G28: 0.58 | H28: 0.52083333 | I28: 55 | J28: 18 | K28: 46 | L28: 61 | M28: 58 | N28: 25 | O28: 0.52083333 | P28: 93 | Q28: 76 | R28: 67 | S28: 87 | T28: 98 | U28: 95 | V28: 0.52083333 | W28: 21 | X28: 6 | Y28: 11 | Z28: 23 | AA28: 14 | AB28: 8 | AC28: 0.52083333 | AD28: 0.41944444 | AE28: 0.14166667 | AF28: 0.22986111 | AG28: 0.43125 | AH28: 0.28402778 | AI28: 0.16597222 | AJ28: 0.52083333 | AK28: =HLOOKUP($AX$1,[1]EU!$B$2:$AF$51,XFD28,0) -> 74 | AL28: =HLOOKUP($AX$1,'[1]Enterprise Aspiring'!$B$2:$AF$51,XFD28,0) -> 28 | AM28: =HLOOKUP($AX$1,'[1]Red Cash'!$B$2:$AF$51,XFD28,0) -> 49 | AN28: =HLOOKUP($AX$1,[1]Aspiring!$B$2:$AF$51,XFD28,0) -> 52 | AO28: =HLOOKUP($AX$1,[1]ICC!$B$2:$AF$51,XFD28,0) -> 54 | AP28: =HLOOKUP($AX$1,[1]CM!$B$2:$AF$51,XFD28,0) -> 27 | AQ28: 0.52083333 | AR28: =EU!N27 -> Lost | AS28: ='R.EU'!N27 -> Wait | AT28: ='Red Cash'!N27 -> Wait | AU28: =Aspiring!N27 -> Achived | AV28: =ICC!N27 -> Achived | AW28: ='SME-CM'!N27 -> Lost | XFD28: =XFD27+1 -> 28
A29: 0.54166667 | B29: 0.84 | C29: 0.62 | D29: 0.93 | E29: 0.96 | F29: 0.91 | G29: 0.53 | H29: 0.54166667 | I29: 60 | J29: 15 | K29: 47 | L29: 50 | M29: 52 | N29: 30 | O29: 0.54166667 | P29: 96 | Q29: 60 | R29: 72 | S29: 84 | T29: 94 | U29: 87 | V29: 0.54166667 | W29: 22 | X29: 8 | Y29: 12 | Z29: 20 | AA29: 16 | AB29: 8 | AC29: 0.54166667 | AD29: 0.44236111 | AE29: 0.14722222 | AF29: 0.22708333 | AG29: 0.42638889 | AH29: 0.31180556 | AI29: 0.16597222 | AJ29: 0.54166667 | AK29: =HLOOKUP($AX$1,[1]EU!$B$2:$AF$51,XFD29,0) -> 78 | AL29: =HLOOKUP($AX$1,'[1]Enterprise Aspiring'!$B$2:$AF$51,XFD29,0) -> 21 | AM29: =HLOOKUP($AX$1,'[1]Red Cash'!$B$2:$AF$51,XFD29,0) -> 54 | AN29: =HLOOKUP($AX$1,[1]Aspiring!$B$2:$AF$51,XFD29,0) -> 54 | AO29: =HLOOKUP($AX$1,[1]ICC!$B$2:$AF$51,XFD29,0) -> 68 | AP29: =HLOOKUP($AX$1,[1]CM!$B$2:$AF$51,XFD29,0) -> 30 | AQ29: 0.54166667 | AR29: =EU!N28 -> Wait | AS29: ='R.EU'!N28 -> Lost | AT29: ='Red Cash'!N28 -> Wait | AU29: =Aspiring!N28 -> Wait | AV29: =ICC!N28 -> Wait | AW29: ='SME-CM'!N28 -> Achived | XFD29: =XFD28+1 -> 29
A30: 0.5625 | B30: 0.77 | C30: 0.95 | D30: 1 | E30: 0.82 | F30: 0.81 | G30: 0.57 | H30: 0.5625 | I30: 66 | J30: 21 | K30: 49 | L30: 50 | M30: 69 | N30: 30 | O30: 0.5625 | P30: 94 | Q30: 74 | R30: 66 | S30: 82 | T30: 97 | U30: 96 | V30: 0.5625 | W30: 22 | X30: 8 | Y30: 12 | Z30: 21 | AA30: 19 | AB30: 9 | AC30: 0.5625 | AD30: 0.45277778 | AE30: 0.16597222 | AF30: 0.23888889 | AG30: 0.40763889 | AH30: 0.37777778 | AI30: 0.16944444 | AJ30: 0.5625 | AK30: =HLOOKUP($AX$1,[1]EU!$B$2:$AF$51,XFD30,0) -> 71 | AL30: =HLOOKUP($AX$1,'[1]Enterprise Aspiring'!$B$2:$AF$51,XFD30,0) -> 27 | AM30: =HLOOKUP($AX$1,'[1]Red Cash'!$B$2:$AF$51,XFD30,0) -> 57 | AN30: =HLOOKUP($AX$1,[1]Aspiring!$B$2:$AF$51,XFD30,0) -> 55 | AO30: =HLOOKUP($AX$1,[1]ICC!$B$2:$AF$51,XFD30,0) -> 64 | AP30: =HLOOKUP($AX$1,[1]CM!$B$2:$AF$51,XFD30,0) -> 29 | AQ30: 0.5625 | AR30: =EU!N29 -> Wait | AS30: ='R.EU'!N29 -> Wait | AT30: ='Red Cash'!N29 -> Wait | AU30: =Aspiring!N29 -> Wait | AV30: =ICC!N29 -> Achived | AW30: ='SME-CM'!N29 -> Achived | XFD30: =XFD29+1 -> 30
... A35: 0.66666667 | B35: 0.94 | C35: 0.73 | D35: 0.98 | E35: 0.86 | F35: 0.31 | G35: 1 | H35: 0.66666667 | I35: 57 | J35: 19 | K35: 47 | L35: 55 | M35: 86 | N35: 27 | O35: 0.66666667 | P35: 95 | Q35: 79 | R35: 65 | S35: 94 | T35: 98 | U35: 88 | V35: 0.66666667 | W35: 26 | X35: 9 | Y35: 10 | Z35: 22 | AA35: 23 | AB35: 15 | AC35: 0.66666667 | AD35: 0.55833333 | AE35: 0.16666667 | AF35: 0.20763889 | AG35: 0.44722222 | AH35: 0.45625 | AI35: 0.29791667 | AJ35: 0.66666667 | AK35: =HLOOKUP($AX$1,[1]EU!$B$2:$AF$51,XFD35,0) -> 64 | AL35: =HLOOKUP($AX$1,'[1]Enterprise Aspiring'!$B$2:$AF$51,XFD35,0) -> 26 | AM35: =HLOOKUP($AX$1,'[1]Red Cash'!$B$2:$AF$51,XFD35,0) -> 58 | AN35: =HLOOKUP($AX$1,[1]Aspiring!$B$2:$AF$51,XFD35,0) -> 58 | AO35: =HLOOKUP($AX$1,[1]ICC!$B$2:$AF$51,XFD35,0) -> 80 | AP35: =HLOOKUP($AX$1,[1]CM!$B$2:$AF$51,XFD35,0) -> 25 | AQ35: 0.66666667 | AR35: =EU!N34 -> Wait | AS35: ='R.EU'!N34 -> Lost | AT35: ='Red Cash'!N34 -> Wait | AU35: =Aspiring!N34 -> Wait | AV35: =ICC!N34 -> Achived | AW35: ='SME-CM'!N34 -> Achived | XFD35: =XFD34+1 -> 35
A36: 0.6875 | H36: 0.6875 | O36: 0.6875 | V36: 0.6875 | AC36: 0.6875 | AJ36: 0.6875 | AK36: =HLOOKUP($AX$1,[1]EU!$B$2:$AF$51,XFD36,0) -> 62 | AL36: =HLOOKUP($AX$1,'[1]Enterprise Aspiring'!$B$2:$AF$51,XFD36,0) -> 22 | AM36: =HLOOKUP($AX$1,'[1]Red Cash'!$B$2:$AF$51,XFD36,0) -> 58 | AN36: =HLOOKUP($AX$1,[1]Aspiring!$B$2:$AF$51,XFD36,0) -> 56 | AO36: =HLOOKUP($AX$1,[1]ICC!$B$2:$AF$51,XFD36,0) -> 86 | AP36: =HLOOKUP($AX$1,[1]CM!$B$2:$AF$51,XFD36,0) -> 27 | AQ36: 0.6875 | AR36: =EU!N35 | AS36: ='R.EU'!N35 | AT36: ='Red Cash'!N35 | AU36: =Aspiring!N35 | AV36: =ICC!N35 | AW36: ='SME-CM'!N35 | XFD36: =XFD35+1 -> 36
A37: 0.70833333 | H37: 0.70833333 | O37: 0.70833333 | V37: 0.70833333 | AC37: 0.70833333 | AJ37: 0.70833333 | AK37: =HLOOKUP($AX$1,[1]EU!$B$2:$AF$51,XFD37,0) -> 61 | AL37: =HLOOKUP($AX$1,'[1]Enterprise Aspiring'!$B$2:$AF$51,XFD37,0) -> 21 | AM37: =HLOOKUP($AX$1,'[1]Red Cash'!$B$2:$AF$51,XFD37,0) -> 51 | AN37: =HLOOKUP($AX$1,[1]Aspiring!$B$2:$AF$51,XFD37,0) -> 59 | AO37: =HLOOKUP($AX$1,[1]ICC!$B$2:$AF$51,XFD37,0) -> 89 | AP37: =HLOOKUP($AX$1,[1]CM!$B$2:$AF$51,XFD37,0) -> 23 | AQ37: 0.70833333 | AR37: =EU!N36 | AS37: ='R.EU'!N36 | AT37: ='Red Cash'!N36 | AU37: =Aspiring!N36 | AV37: =ICC!N36 | AW37: ='SME-CM'!N36 | XFD37: =XFD36+1 -> 37
A38: 0.72916667 | H38: 0.72916667 | O38: 0.72916667 | V38: 0.72916667 | AC38: 0.72916667 | AJ38: 0.72916667 | AK38: =HLOOKUP($AX$1,[1]EU!$B$2:$AF$51,XFD38,0) -> 72 | AL38: =HLOOKUP($AX$1,'[1]Enterprise Aspiring'!$B$2:$AF$51,XFD38,0) -> 24 | AM38: =HLOOKUP($AX$1,'[1]Red Cash'!$B$2:$AF$51,XFD38,0) -> 56 | AN38: =HLOOKUP($AX$1,[1]Aspiring!$B$2:$AF$51,XFD38,0) -> 74 | AO38: =HLOOKUP($AX$1,[1]ICC!$B$2:$AF$51,XFD38,0) -> 97 | AP38: =HLOOKUP($AX$1,[1]CM!$B$2:$AF$51,XFD38,0) -> 30 | AQ38: 0.72916667 | AR38: =EU!N37 | AS38: ='R.EU'!N37 | AT38: ='Red Cash'!N37 | AU38: =Aspiring!N37 | AV38: =ICC!N37 | AW38: ='SME-CM'!N37 | XFD38: =XFD37+1 -> 38
A39: 0.75 | H39: 0.75 | O39: 0.75 | V39: 0.75 | AC39: 0.75 | AJ39: 0.75 | AK39: =HLOOKUP($AX$1,[1]EU!$B$2:$AF$51,XFD39,0) -> 72 | AL39: =HLOOKUP($AX$1,'[1]Enterprise Aspiring'!$B$2:$AF$51,XFD39,0) -> 23 | AM39: =HLOOKUP($AX$1,'[1]Red Cash'!$B$2:$AF$51,XFD39,0) -> 57 | AN39: =HLOOKUP($AX$1,[1]Aspiring!$B$2:$AF$51,XFD39,0) -> 66 | AO39: =HLOOKUP($AX$1,[1]ICC!$B$2:$AF$51,XFD39,0) -> 99 | AP39: =HLOOKUP($AX$1,[1]CM!$B$2:$AF$51,XFD39,0) -> 30 | AQ39: 0.75 | AR39: =EU!N38 | AS39: ='R.EU'!N38 | AT39: ='Red Cash'!N38 | AU39: =Aspiring!N38 | AV39: =ICC!N38 | AW39: ='SME-CM'!N38 | XFD39: =XFD38+1 -> 39
A40: 0.77083333 | H40: 0.77083333 | O40: 0.77083333 | V40: 0.77083333 | AC40: 0.77083333 | AJ40: 0.77083333 | AK40: =HLOOKUP($AX$1,[1]EU!$B$2:$AF$51,XFD40,0) -> 69 | AL40: =HLOOKUP($AX$1,'[1]Enterprise Aspiring'!$B$2:$AF$51,XFD40,0) -> 27 | AM40: =HLOOKUP($AX$1,'[1]Red Cash'!$B$2:$AF$51,XFD40,0) -> 52 | AN40: =HLOOKUP($AX$1,[1]Aspiring!$B$2:$AF$51,XFD40,0) -> 64 | AO40: =HLOOKUP($AX$1,[1]ICC!$B$2:$AF$51,XFD40,0) -> 100 | AP40: =HLOOKUP($AX$1,[1]CM!$B$2:$AF$51,XFD40,0) -> 23 | AQ40: 0.77083333 | AR40: =EU!N39 | AS40: ='R.EU'!N39 | AT40: ='Red Cash'!N39 | AU40: =Aspiring!N39 | AV40: =ICC!N39 | AW40: ='SME-CM'!N39 | XFD40: =XFD39+1 -> 40
A41: 0.79166667 | H41: 0.79166667 | O41: 0.79166667 | V41: 0.79166667 | AC41: 0.79166667 | AJ41: 0.79166667 | AK41: =HLOOKUP($AX$1,[1]EU!$B$2:$AF$51,XFD41,0) -> 90 | AL41: =HLOOKUP($AX$1,'[1]Enterprise Aspiring'!$B$2:$AF$51,XFD41,0) -> 23 | AM41: =HLOOKUP($AX$1,'[1]Red Cash'!$B$2:$AF$51,XFD41,0) -> 58 | AN41: =HLOOKUP($AX$1,[1]Aspiring!$B$2:$AF$51,XFD41,0) -> 68 | AO41: =HLOOKUP($AX$1,[1]ICC!$B$2:$AF$51,XFD41,0) -> 100 | AP41: =HLOOKUP($AX$1,[1]CM!$B$2:$AF$51,XFD41,0) -> 24 | AQ41: 0.79166667 | AR41: =EU!N40 | AS41: ='R.EU'!N40 | AT41: ='Red Cash'!N40 | AU41: =Aspiring!N40 | AV41: =ICC!N40 | AW41: ='SME-CM'!N40 | XFD41: =XFD40+1 -> 41
A42: 0.8125 | H42: 0.8125 | O42: 0.8125 | V42: 0.8125 | AC42: 0.8125 | AJ42: 0.8125 | AK42: =HLOOKUP($AX$1,[1]EU!$B$2:$AF$51,XFD42,0) -> 77 | AL42: =HLOOKUP($AX$1,'[1]Enterprise Aspiring'!$B$2:$AF$51,XFD42,0) -> 27 | AM42: =HLOOKUP($AX$1,'[1]Red Cash'!$B$2:$AF$51,XFD42,0) -> 61 | AN42: =HLOOKUP($AX$1,[1]Aspiring!$B$2:$AF$51,XFD42,0) -> 69 | AO42: =HLOOKUP($AX$1,[1]ICC!$B$2:$AF$51,XFD42,0) -> 110 | AP42: =HLOOKUP($AX$1,[1]CM!$B$2:$AF$51,XFD42,0) -> 24 | AQ42: 0.8125 | AR42: =EU!N41 | AS42: ='R.EU'!N41 | AT42: ='Red Cash'!N41 | AU42: =Aspiring!N41 | AV42: =ICC!N41 | AW42: ='SME-CM'!N41 | XFD42: =XFD41+1 -> 42
A43: 0.83333333 | H43: 0.83333333 | O43: 0.83333333 | V43: 0.83333333 | AC43: 0.83333333 | AJ43: 0.83333333 | AK43: =HLOOKUP($AX$1,[1]EU!$B$2:$AF$51,XFD43,0) -> 83 | AL43: =HLOOKUP($AX$1,'[1]Enterprise Aspiring'!$B$2:$AF$51,XFD43,0) -> 24 | AM43: =HLOOKUP($AX$1,'[1]Red Cash'!$B$2:$AF$51,XFD43,0) -> 64 | AN43: =HLOOKUP($AX$1,[1]Aspiring!$B$2:$AF$51,XFD43,0) -> 79 | AO43: =HLOOKUP($AX$1,[1]ICC!$B$2:$AF$51,XFD43,0) -> 110 | AP43: =HLOOKUP($AX$1,[1]CM!$B$2:$AF$51,XFD43,0) -> 52 | AQ43: 0.83333333 | AR43: =EU!N42 | AS43: ='R.EU'!N42 | AT43: ='Red Cash'!N42 | AU43: =Aspiring!N42 | AV43: =ICC!N42 | AW43: ='SME-CM'!N42 | XFD43: =XFD42+1 -> 43
A44: 0.85416667 | H44: 0.85416667 | O44: 0.85416667 | V44: 0.85416667 | AC44: 0.85416667 | AJ44: 0.85416667 | AK44: =HLOOKUP($AX$1,[1]EU!$B$2:$AF$51,XFD44,0) -> 73 | AL44: =HLOOKUP($AX$1,'[1]Enterprise Aspiring'!$B$2:$AF$51,XFD44,0) -> 22 | AM44: =HLOOKUP($AX$1,'[1]Red Cash'!$B$2:$AF$51,XFD44,0) -> 63 | AN44: =HLOOKUP($AX$1,[1]Aspiring!$B$2:$AF$51,XFD44,0) -> 67 | AO44: =HLOOKUP($AX$1,[1]ICC!$B$2:$AF$51,XFD44,0) -> 105 | AP44: =HLOOKUP($AX$1,[1]CM!$B$2:$AF$51,XFD44,0) -> 52 | AQ44: 0.85416667 | AR44: =EU!N43 | AS44: ='R.EU'!N43 | AT44: ='Red Cash'!N43 | AU44: =Aspiring!N43 | AV44: =ICC!N43 | AW44: ='SME-CM'!N43 | XFD44: =XFD43+1 -> 44
...

Sheet EU
A1: Acc | B1: Day | C1: Interval | D1: =SUM(D2:D49) -> 2271 | E1: Answerd | F1: Delivery | G1: SL | H1: THT | I1: AHT | J1: OCC | K1: Req Stuff | L1: Login Stuff | M1: OV | N1: Status | O1: Paid Calls | P1: CAP LEFT | Q1: Total Login
A2: =R3 -> Enterprise | B2: =Master!$AX$1 -> 45965 | C2: 0 | D2: =IF(E2="","",Master!AK3) -> 36 | E2: =Master!I3 -> 40 | F2: =IFERROR(IF(OR(E2="-",E2=0),"",E2/D2),0) -> 1.1111111 | G2: =Master!B3 -> 0.79 | H2: =IFERROR(E2*I2,0) -> 23860.2 | I2: =IFERROR(((Master!AD3*3600*24)*((Master!P3/100)/Master!I3)),0) -> 596.505 | J2: =Master!P3 -> 91 | K2: =(D2*Validation!$M$4/1800)/IF(Validation!$N$4="",(IF(OR(NOT(ISNUMBER(J2)),J2=0),1,J2%)),Validation!$N$4) -> 8.8235294 | L2: =Master!W3 -> 15 | M2: =IF(AND(ISNUMBER(L2),L2>0),L2-K2,"-") -> 6.1764706 | N2: =IF(OR(E2=0,E2="-"),"",IF(F2>=98%,"Achived",IF(G2>=75%,"Wait","Lost"))) -> Achived | O2: =IF(E2=0,0,IF(N2="Wait",D2*0.9,IF($T$3="Y",E2,IF(AND(N2="achived",F2<=1.1),E2,IF(F2>=1.1,D2*1.1,IF(N2="Lost",E2,"ER")))))) -> 39.6 | P2: =T3 -> N | Q2: =IFERROR((I2*E2)/((J2/100)*86400),0) -> 0.30347222 | R2: Acc | T2: CAP LEFT
A3: =R3 -> Enterprise | B3: =Master!$AX$1 -> 45965 | C3: 0.020833333 | D3: =Master!AK4 -> 33 | E3: =Master!I4 -> 24 | F3: =IFERROR(IF(OR(E3="-",E3=0),"",E3/D3),0) -> 0.72727273 | G3: =Master!B4 -> 1 | H3: =IFERROR(E3*I3,0) -> 23122.2 | I3: =IFERROR(((Master!AD4*3600*24)*((Master!P4/100)/Master!I4)),0) -> 963.425 | J3: =Master!P4 -> 89 | K3: =(D3*Validation!$M$4/1800)/IF(Validation!$N$4="",(IF(OR(NOT(ISNUMBER(J3)),J3=0),1,J3%)),Validation!$N$4) -> 8.0882353 | L3: =Master!W4 -> 16 | M3: =IF(AND(ISNUMBER(L3),L3>0),L3-K3,"-") -> 7.9117647 | N3: =IF(OR(E3=0,E3="-"),"",IF(F3>=98%,"Achived",IF(G3>=75%,"Wait","Lost"))) -> Wait | O3: =IF(E3=0,0,IF(N3="Wait",D3*0.9,IF($T$3="Y",E3,IF(AND(N3="achived",F3<=1.1),E3,IF(F3>=1.1,D3*1.1,IF(N3="Lost",E3,"ER")))))) -> 29.7 | P3: =T3 -> N | Q3: =IFERROR((I3*E3)/((J3/100)*86400),0) -> 0.30069444 | R3: Enterprise | T3: N
A4: =R3 -> Enterprise | B4: =Master!$AX$1 -> 45965 | C4: 0.041666667 | D4: =Master!AK5 -> 19 | E4: =Master!I5 -> 21 | F4: =IFERROR(IF(OR(E4="-",E4=0),"",E4/D4),0) -> 1.1052632 | G4: =Master!B5 -> 1 | H4: =IFERROR(E4*I4,0) -> 18306 | I4: =IFERROR(((Master!AD5*3600*24)*((Master!P5/100)/Master!I5)),0) -> 871.71429 | J4: =Master!P5 -> 90 | K4: =(D4*Validation!$M$4/1800)/IF(Validation!$N$4="",(IF(OR(NOT(ISNUMBER(J4)),J4=0),1,J4%)),Validation!$N$4) -> 4.6568627 | L4: =Master!W5 -> 11 | M4: =IF(AND(ISNUMBER(L4),L4>0),L4-K4,"-") -> 6.3431373 | N4: =IF(OR(E4=0,E4="-"),"",IF(F4>=98%,"Achived",IF(G4>=75%,"Wait","Lost"))) -> Achived | O4: =IF(E4=0,0,IF(N4="Wait",D4*0.9,IF($T$3="Y",E4,IF(AND(N4="achived",F4<=1.1),E4,IF(F4>=1.1,D4*1.1,IF(N4="Lost",E4,"ER")))))) -> 20.9 | P4: =T3 -> N | Q4: =IFERROR((I4*E4)/((J4/100)*86400),0) -> 0.23541667
A5: =R3 -> Enterprise | B5: =Master!$AX$1 -> 45965 | C5: 0.0625 | D5: =Master!AK6 -> 16 | E5: =Master!I6 -> 13 | F5: =IFERROR(IF(OR(E5="-",E5=0),"",E5/D5),0) -> 0.8125 | G5: =Master!B6 -> 1 | H5: =IFERROR(E5*I5,0) -> 17933.4 | I5: =IFERROR(((Master!AD6*3600*24)*((Master!P6/100)/Master!I6)),0) -> 1379.4923 | J5: =Master!P6 -> 81 | K5: =(D5*Validation!$M$4/1800)/IF(Validation!$N$4="",(IF(OR(NOT(ISNUMBER(J5)),J5=0),1,J5%)),Validation!$N$4) -> 3.9215686 | L5: =Master!W6 -> 12 | M5: =IF(AND(ISNUMBER(L5),L5>0),L5-K5,"-") -> 8.0784314 | N5: =IF(OR(E5=0,E5="-"),"",IF(F5>=98%,"Achived",IF(G5>=75%,"Wait","Lost"))) -> Wait | O5: =IF(E5=0,0,IF(N5="Wait",D5*0.9,IF($T$3="Y",E5,IF(AND(N5="achived",F5<=1.1),E5,IF(F5>=1.1,D5*1.1,IF(N5="Lost",E5,"ER")))))) -> 14.4 | P5: =T3 -> N | Q5: =IFERROR((I5*E5)/((J5/100)*86400),0) -> 0.25625
A6: =R3 -> Enterprise | B6: =Master!$AX$1 -> 45965 | C6: 0.083333333 | D6: =Master!AK7 -> 13 | E6: =Master!I7 -> 9 | F6: =IFERROR(IF(OR(E6="-",E6=0),"",E6/D6),0) -> 0.69230769 | G6: =Master!B7 -> 1 | H6: =IFERROR(E6*I6,0) -> 14981.4 | I6: =IFERROR(((Master!AD7*3600*24)*((Master!P7/100)/Master!I7)),0) -> 1664.6 | J6: =Master!P7 -> 87 | K6: =(D6*Validation!$M$4/1800)/IF(Validation!$N$4="",(IF(OR(NOT(ISNUMBER(J6)),J6=0),1,J6%)),Validation!$N$4) -> 3.1862745 | L6: =Master!W7 -> 8 | M6: =IF(AND(ISNUMBER(L6),L6>0),L6-K6,"-") -> 4.8137255 | N6: =IF(OR(E6=0,E6="-"),"",IF(F6>=98%,"Achived",IF(G6>=75%,"Wait","Lost"))) -> Wait | O6: =IF(E6=0,0,IF(N6="Wait",D6*0.9,IF($T$3="Y",E6,IF(AND(N6="achived",F6<=1.1),E6,IF(F6>=1.1,D6*1.1,IF(N6="Lost",E6,"ER")))))) -> 11.7 | P6: =T3 -> N | Q6: =IFERROR((I6*E6)/((J6/100)*86400),0) -> 0.19930556
A7: =R3 -> Enterprise | B7: =Master!$AX$1 -> 45965 | C7: 0.10416667 | D7: =Master!AK8 -> 11 | E7: =Master!I8 -> 6 | F7: =IFERROR(IF(OR(E7="-",E7=0),"",E7/D7),0) -> 0.54545455 | G7: =Master!B8 -> 0.8 | H7: =IFERROR(E7*I7,0) -> 12466.2 | I7: =IFERROR(((Master!AD8*3600*24)*((Master!P8/100)/Master!I8)),0) -> 2077.7 | J7: =Master!P8 -> 79 | K7: =(D7*Validation!$M$4/1800)/IF(Validation!$N$4="",(IF(OR(NOT(ISNUMBER(J7)),J7=0),1,J7%)),Validation!$N$4) -> 2.6960784 | L7: =Master!W8 -> 7 | M7: =IF(AND(ISNUMBER(L7),L7>0),L7-K7,"-") -> 4.3039216 | N7: =IF(OR(E7=0,E7="-"),"",IF(F7>=98%,"Achived",IF(G7>=75%,"Wait","Lost"))) -> Wait | O7: =IF(E7=0,0,IF(N7="Wait",D7*0.9,IF($T$3="Y",E7,IF(AND(N7="achived",F7<=1.1),E7,IF(F7>=1.1,D7*1.1,IF(N7="Lost",E7,"ER")))))) -> 9.9 | P7: =T3 -> N | Q7: =IFERROR((I7*E7)/((J7/100)*86400),0) -> 0.18263889
A8: =R3 -> Enterprise | B8: =Master!$AX$1 -> 45965 | C8: 0.125 | D8: =Master!AK9 -> 5 | E8: =Master!I9 -> 4 | F8: =IFERROR(IF(OR(E8="-",E8=0),"",E8/D8),0) -> 0.8 | G8: =Master!B9 -> 1 | H8: =IFERROR(E8*I8,0) -> 7204.8 | I8: =IFERROR(((Master!AD9*3600*24)*((Master!P9/100)/Master!I9)),0) -> 1801.2 | J8: =Master!P9 -> 76 | K8: =(D8*Validation!$M$4/1800)/IF(Validation!$N$4="",(IF(OR(NOT(ISNUMBER(J8)),J8=0),1,J8%)),Validation!$N$4) -> 1.2254902 | L8: =Master!W9 -> 7 | M8: =IF(AND(ISNUMBER(L8),L8>0),L8-K8,"-") -> 5.7745098 | N8: =IF(OR(E8=0,E8="-"),"",IF(F8>=98%,"Achived",IF(G8>=75%,"Wait","Lost"))) -> Wait | O8: =IF(E8=0,0,IF(N8="Wait",D8*0.9,IF($T$3="Y",E8,IF(AND(N8="achived",F8<=1.1),E8,IF(F8>=1.1,D8*1.1,IF(N8="Lost",E8,"ER")))))) -> 4.5 | P8: =T3 -> N | Q8: =IFERROR((I8*E8)/((J8/100)*86400),0) -> 0.10972222
A9: =R3 -> Enterprise | B9: =Master!$AX$1 -> 45965 | C9: 0.14583333 | D9: =Master!AK10 -> 5 | E9: =Master!I10 -> 7 | F9: =IFERROR(IF(OR(E9="-",E9=0),"",E9/D9),0) -> 1.4 | G9: =Master!B10 -> 1 | H9: =IFERROR(E9*I9,0) -> 9279.6 | I9: =IFERROR(((Master!AD10*3600*24)*((Master!P10/100)/Master!I10)),0) -> 1325.6571 | J9: =Master!P10 -> 74 | K9: =(D9*Validation!$M$4/1800)/IF(Validation!$N$4="",(IF(OR(NOT(ISNUMBER(J9)),J9=0),1,J9%)),Validation!$N$4) -> 1.2254902 | L9: =Master!W10 -> 7 | M9: =IF(AND(ISNUMBER(L9),L9>0),L9-K9,"-") -> 5.7745098 | N9: =IF(OR(E9=0,E9="-"),"",IF(F9>=98%,"Achived",IF(G9>=75%,"Wait","Lost"))) -> Achived | O9: =IF(E9=0,0,IF(N9="Wait",D9*0.9,IF($T$3="Y",E9,IF(AND(N9="achived",F9<=1.1),E9,IF(F9>=1.1,D9*1.1,IF(N9="Lost",E9,"ER")))))) -> 5.5 | P9: =T3 -> N | Q9: =IFERROR((I9*E9)/((J9/100)*86400),0) -> 0.14513889
A10: =R3 -> Enterprise | B10: =Master!$AX$1 -> 45965 | C10: 0.16666667 | D10: =Master!AK11 -> 6 | E10: =Master!I11 -> 2 | F10: =IFERROR(IF(OR(E10="-",E10=0),"",E10/D10),0) -> 0.33333333 | G10: =Master!B11 -> 1 | H10: =IFERROR(E10*I10,0) -> 9262.8 | I10: =IFERROR(((Master!AD11*3600*24)*((Master!P11/100)/Master!I11)),0) -> 4631.4 | J10: =Master!P11 -> 93 | K10: =(D10*Validation!$M$4/1800)/IF(Validation!$N$4="",(IF(OR(NOT(ISNUMBER(J10)),J10=0),1,J10%)),Validation!$N$4) -> 1.4705882 | L10: =Master!W11 -> 6 | M10: =IF(AND(ISNUMBER(L10),L10>0),L10-K10,"-") -> 4.5294118 | N10: =IF(OR(E10=0,E10="-"),"",IF(F10>=98%,"Achived",IF(G10>=75%,"Wait","Lost"))) -> Wait | O10: =IF(E10=0,0,IF(N10="Wait",D10*0.9,IF($T$3="Y",E10,IF(AND(N10="achived",F10<=1.1),E10,IF(F10>=1.1,D10*1.1,IF(N10="Lost",E10,"ER")))))) -> 5.4 | P10: =T3 -> N | Q10: =IFERROR((I10*E10)/((J10/100)*86400),0) -> 0.11527778
A11: =R3 -> Enterprise | B11: =Master!$AX$1 -> 45965 | C11: 0.1875 | D11: =Master!AK12 -> 4 | E11: =Master!I12 -> 2 | F11: =IFERROR(IF(OR(E11="-",E11=0),"",E11/D11),0) -> 0.5 | G11: =Master!B12 -> 1 | H11: =IFERROR(E11*I11,0) -> 9291.6 | I11: =IFERROR(((Master!AD12*3600*24)*((Master!P12/100)/Master!I12)),0) -> 4645.8 | J11: =Master!P12 -> 89 | K11: =(D11*Validation!$M$4/1800)/IF(Validation!$N$4="",(IF(OR(NOT(ISNUMBER(J11)),J11=0),1,J11%)),Validation!$N$4) -> 0.98039216 | L11: =Master!W12 -> 6 | M11: =IF(AND(ISNUMBER(L11),L11>0),L11-K11,"-") -> 5.0196078 | N11: =IF(OR(E11=0,E11="-"),"",IF(F11>=98%,"Achived",IF(G11>=75%,"Wait","Lost"))) -> Wait | O11: =IF(E11=0,0,IF(N11="Wait",D11*0.9,IF($T$3="Y",E11,IF(AND(N11="achived",F11<=1.1),E11,IF(F11>=1.1,D11*1.1,IF(N11="Lost",E11,"ER")))))) -> 3.6 | P11: =T3 -> N | Q11: =IFERROR((I11*E11)/((J11/100)*86400),0) -> 0.12083333
A12: =R3 -> Enterprise | B12: =Master!$AX$1 -> 45965 | C12: 0.20833333 | D12: =Master!AK13 -> 4 | E12: =Master!I13 -> 3 | F12: =IFERROR(IF(OR(E12="-",E12=0),"",E12/D12),0) -> 0.75 | G12: =Master!B13 -> 1 | H12: =IFERROR(E12*I12,0) -> 7777.8 | I12: =IFERROR(((Master!AD13*3600*24)*((Master!P13/100)/Master!I13)),0) -> 2592.6 | J12: =Master!P13 -> 87 | K12: =(D12*Validation!$M$4/1800)/IF(Validation!$N$4="",(IF(OR(NOT(ISNUMBER(J12)),J12=0),1,J12%)),Validation!$N$4) -> 0.98039216 | L12: =Master!W13 -> 5 | M12: =IF(AND(ISNUMBER(L12),L12>0),L12-K12,"-") -> 4.0196078 | N12: =IF(OR(E12=0,E12="-"),"",IF(F12>=98%,"Achived",IF(G12>=75%,"Wait","Lost"))) -> Wait | O12: =IF(E12=0,0,IF(N12="Wait",D12*0.9,IF($T$3="Y",E12,IF(AND(N12="achived",F12<=1.1),E12,IF(F12>=1.1,D12*1.1,IF(N12="Lost",E12,"ER")))))) -> 3.6 | P12: =T3 -> N | Q12: =IFERROR((I12*E12)/((J12/100)*86400),0) -> 0.10347222
A13: =R3 -> Enterprise | B13: =Master!$AX$1 -> 45965 | C13: 0.22916667 | D13: =Master!AK14 -> 8 | E13: =Master!I14 -> 2 | F13: =IFERROR(IF(OR(E13="-",E13=0),"",E13/D13),0) -> 0.25 | G13: =Master!B14 -> 1 | H13: =IFERROR(E13*I13,0) -> 7071.6 | I13: =IFERROR(((Master!AD14*3600*24)*((Master!P14/100)/Master!I14)),0) -> 3535.8 | J13: =Master!P14 -> 83 | K13: =(D13*Validation!$M$4/1800)/IF(Validation!$N$4="",(IF(OR(NOT(ISNUMBER(J13)),J13=0),1,J13%)),Validation!$N$4) -> 1.9607843 | L13: =Master!W14 -> 4 | M13: =IF(AND(ISNUMBER(L13),L13>0),L13-K13,"-") -> 2.0392157 | N13: =IF(OR(E13=0,E13="-"),"",IF(F13>=98%,"Achived",IF(G13>=75%,"Wait","Lost"))) -> Wait | O13: =IF(E13=0,0,IF(N13="Wait",D13*0.9,IF($T$3="Y",E13,IF(AND(N13="achived",F13<=1.1),E13,IF(F13>=1.1,D13*1.1,IF(N13="Lost",E13,"ER")))))) -> 7.2 | P13: =T3 -> N | Q13: =IFERROR((I13*E13)/((J13/100)*86400),0) -> 0.098611111
A14: =R3 -> Enterprise | B14: =Master!$AX$1 -> 45965 | C14: 0.25 | D14: =Master!AK15 -> 7 | E14: =Master!I15 -> 8 | F14: =IFERROR(IF(OR(E14="-",E14=0),"",E14/D14),0) -> 1.1428571 | G14: =Master!B15 -> 1 | H14: =IFERROR(E14*I14,0) -> 6568.8 | I14: =IFERROR(((Master!AD15*3600*24)*((Master!P15/100)/Master!I15)),0) -> 821.1 | J14: =Master!P15 -> 92 | K14: =(D14*Validation!$M$4/1800)/IF(Validation!$N$4="",(IF(OR(NOT(ISNUMBER(J14)),J14=0),1,J14%)),Validation!$N$4) -> 1.7156863 | L14: =Master!W15 -> 4 | M14: =IF(AND(ISNUMBER(L14),L14>0),L14-K14,"-") -> 2.2843137 | N14: =IF(OR(E14=0,E14="-"),"",IF(F14>=98%,"Achived",IF(G14>=75%,"Wait","Lost"))) -> Achived | O14: =IF(E14=0,0,IF(N14="Wait",D14*0.9,IF($T$3="Y",E14,IF(AND(N14="achived",F14<=1.1),E14,IF(F14>=1.1,D14*1.1,IF(N14="Lost",E14,"ER")))))) -> 7.7 | P14: =T3 -> N | Q14: =IFERROR((I14*E14)/((J14/100)*86400),0) -> 0.082638889
A15: =R3 -> Enterprise | B15: =Master!$AX$1 -> 45965 | C15: 0.27083333 | D15: =Master!AK16 -> 10 | E15: =Master!I16 -> 7 | F15: =IFERROR(IF(OR(E15="-",E15=0),"",E15/D15),0) -> 0.7 | G15: =Master!B16 -> 1 | H15: =IFERROR(E15*I15,0) -> 5854.8 | I15: =IFERROR(((Master!AD16*3600*24)*((Master!P16/100)/Master!I16)),0) -> 836.4 | J15: =Master!P16 -> 82 | K15: =(D15*Validation!$M$4/1800)/IF(Validation!$N$4="",(IF(OR(NOT(ISNUMBER(J15)),J15=0),1,J15%)),Validation!$N$4) -> 2.4509804 | L15: =Master!W16 -> 4 | M15: =IF(AND(ISNUMBER(L15),L15>0),L15-K15,"-") -> 1.5490196 | N15: =IF(OR(E15=0,E15="-"),"",IF(F15>=98%,"Achived",IF(G15>=75%,"Wait","Lost"))) -> Wait | O15: =IF(E15=0,0,IF(N15="Wait",D15*0.9,IF($T$3="Y",E15,IF(AND(N15="achived",F15<=1.1),E15,IF(F15>=1.1,D15*1.1,IF(N15="Lost",E15,"ER")))))) -> 9 | P15: =T3 -> N | Q15: =IFERROR((I15*E15)/((J15/100)*86400),0) -> 0.082638889
A16: =R3 -> Enterprise | B16: =Master!$AX$1 -> 45965 | C16: 0.29166667 | D16: =Master!AK17 -> 14 | E16: =Master!I17 -> 14 | F16: =IFERROR(IF(OR(E16="-",E16=0),"",E16/D16),0) -> 1 | G16: =Master!B17 -> 0.79 | H16: =IFERROR(E16*I16,0) -> 9556.8 | I16: =IFERROR(((Master!AD17*3600*24)*((Master!P17/100)/Master!I17)),0) -> 682.62857 | J16: =Master!P17 -> 88 | K16: =(D16*Validation!$M$4/1800)/IF(Validation!$N$4="",(IF(OR(NOT(ISNUMBER(J16)),J16=0),1,J16%)),Validation!$N$4) -> 3.4313725 | L16: =Master!W17 -> 7 | M16: =IF(AND(ISNUMBER(L16),L16>0),L16-K16,"-") -> 3.5686275 | N16: =IF(OR(E16=0,E16="-"),"",IF(F16>=98%,"Achived",IF(G16>=75%,"Wait","Lost"))) -> Achived | O16: =IF(E16=0,0,IF(N16="Wait",D16*0.9,IF($T$3="Y",E16,IF(AND(N16="achived",F16<=1.1),E16,IF(F16>=1.1,D16*1.1,IF(N16="Lost",E16,"ER")))))) -> 14 | P16: =T3 -> N | Q16: =IFERROR((I16*E16)/((J16/100)*86400),0) -> 0.12569444
A17: =R3 -> Enterprise | B17: =Master!$AX$1 -> 45965 | C17: 0.3125 | D17: =Master!AK18 -> 21 | E17: =Master!I18 -> 21 | F17: =IFERROR(IF(OR(E17="-",E17=0),"",E17/D17),0) -> 1 | G17: =Master!B18 -> 0.9 | H17: =IFERROR(E17*I17,0) -> 13311 | I17: =IFERROR(((Master!AD18*3600*24)*((Master!P18/100)/Master!I18)),0) -> 633.85714 | J17: =Master!P18 -> 85 | K17: =(D17*Validation!$M$4/1800)/IF(Validation!$N$4="",(IF(OR(NOT(ISNUMBER(J17)),J17=0),1,J17%)),Validation!$N$4) -> 5.1470588 | L17: =Master!W18 -> 7 | M17: =IF(AND(ISNUMBER(L17),L17>0),L17-K17,"-") -> 1.8529412 | N17: =IF(OR(E17=0,E17="-"),"",IF(F17>=98%,"Achived",IF(G17>=75%,"Wait","Lost"))) -> Achived | O17: =IF(E17=0,0,IF(N17="Wait",D17*0.9,IF($T$3="Y",E17,IF(AND(N17="achived",F17<=1.1),E17,IF(F17>=1.1,D17*1.1,IF(N17="Lost",E17,"ER")))))) -> 21 | P17: =T3 -> N | Q17: =IFERROR((I17*E17)/((J17/100)*86400),0) -> 0.18125
A18: =R3 -> Enterprise | B18: =Master!$AX$1 -> 45965 | C18: 0.33333333 | D18: =Master!AK19 -> 28 | E18: =Master!I19 -> 17 | F18: =IFERROR(IF(OR(E18="-",E18=0),"",E18/D18),0) -> 0.60714286 | G18: =Master!B19 -> 0.93 | H18: =IFERROR(E18*I18,0) -> 10578 | I18: =IFERROR(((Master!AD19*3600*24)*((Master!P19/100)/Master!I19)),0) -> 622.23529 | J18: =Master!P19 -> 86 | K18: =(D18*Validation!$M$4/1800)/IF(Validation!$N$4="",(IF(OR(NOT(ISNUMBER(J18)),J18=0),1,J18%)),Validation!$N$4) -> 6.8627451 | L18: =Master!W19 -> 7 | M18: =IF(AND(ISNUMBER(L18),L18>0),L18-K18,"-") -> 0.1372549 | N18: =IF(OR(E18=0,E18="-"),"",IF(F18>=98%,"Achived",IF(G18>=75%,"Wait","Lost"))) -> Wait | O18: =IF(E18=0,0,IF(N18="Wait",D18*0.9,IF($T$3="Y",E18,IF(AND(N18="achived",F18<=1.1),E18,IF(F18>=1.1,D18*1.1,IF(N18="Lost",E18,"ER")))))) -> 25.2 | P18: =T3 -> N | Q18: =IFERROR((I18*E18)/((J18/100)*86400),0) -> 0.14236111
A19: =R3 -> Enterprise | B19: =Master!$AX$1 -> 45965 | C19: 0.35416667 | D19: =Master!AK20 -> 36 | E19: =Master!I20 -> 33 | F19: =IFERROR(IF(OR(E19="-",E19=0),"",E19/D19),0) -> 0.91666667 | G19: =Master!B20 -> 0.75 | H19: =IFERROR(E19*I19,0) -> 12640.8 | I19: =IFERROR(((Master!AD20*3600*24)*((Master!P20/100)/Master!I20)),0) -> 383.05455 | J19: =Master!P20 -> 92 | K19: =(D19*Validation!$M$4/1800)/IF(Validation!$N$4="",(IF(OR(NOT(ISNUMBER(J19)),J19=0),1,J19%)),Validation!$N$4) -> 8.8235294 | L19: =Master!W20 -> 10 | M19: =IF(AND(ISNUMBER(L19),L19>0),L19-K19,"-") -> 1.1764706 | N19: =IF(OR(E19=0,E19="-"),"",IF(F19>=98%,"Achived",IF(G19>=75%,"Wait","Lost"))) -> Wait | O19: =IF(E19=0,0,IF(N19="Wait",D19*0.9,IF($T$3="Y",E19,IF(AND(N19="achived",F19<=1.1),E19,IF(F19>=1.1,D19*1.1,IF(N19="Lost",E19,"ER")))))) -> 32.4 | P19: =T3 -> N | Q19: =IFERROR((I19*E19)/((J19/100)*86400),0) -> 0.15902778
A20: =R3 -> Enterprise | B20: =Master!$AX$1 -> 45965 | C20: 0.375 | D20: =Master!AK21 -> 54 | E20: =Master!I21 -> 43 | F20: =IFERROR(IF(OR(E20="-",E20=0),"",E20/D20),0) -> 0.7962963 | G20: =Master!B21 -> 0.75 | H20: =IFERROR(E20*I20,0) -> 19314 | I20: =IFERROR(((Master!AD21*3600*24)*((Master!P21/100)/Master!I21)),0) -> 449.16279 | J20: =Master!P21 -> 87 | K20: =(D20*Validation!$M$4/1800)/IF(Validation!$N$4="",(IF(OR(NOT(ISNUMBER(J20)),J20=0),1,J20%)),Validation!$N$4) -> 13.235294 | L20: =Master!W21 -> 12 | M20: =IF(AND(ISNUMBER(L20),L20>0),L20-K20,"-") -> -1.2352941 | N20: =IF(OR(E20=0,E20="-"),"",IF(F20>=98%,"Achived",IF(G20>=75%,"Wait","Lost"))) -> Wait | O20: =IF(E20=0,0,IF(N20="Wait",D20*0.9,IF($T$3="Y",E20,IF(AND(N20="achived",F20<=1.1),E20,IF(F20>=1.1,D20*1.1,IF(N20="Lost",E20,"ER")))))) -> 48.6 | P20: =T3 -> N | Q20: =IFERROR((I20*E20)/((J20/100)*86400),0) -> 0.25694444
A21: =R3 -> Enterprise | B21: =Master!$AX$1 -> 45965 | C21: 0.39583333 | D21: =Master!AK22 -> 63 | E21: =Master!I22 -> 37 | F21: =IFERROR(IF(OR(E21="-",E21=0),"",E21/D21),0) -> 0.58730159 | G21: =Master!B22 -> 0.93 | H21: =IFERROR(E21*I21,0) -> 21138.1 | I21: =IFERROR(((Master!AD22*3600*24)*((Master!P22/100)/Master!I23)),0) -> 571.3 | J21: =Master!P22 -> 87 | K21: =(D21*Validation!$M$4/1800)/IF(Validation!$N$4="",(IF(OR(NOT(ISNUMBER(J21)),J21=0),1,J21%)),Validation!$N$4) -> 15.441176 | L21: =Master!W22 -> 14 | M21: =IF(AND(ISNUMBER(L21),L21>0),L21-K21,"-") -> -1.4411765 | N21: =IF(OR(E21=0,E21="-"),"",IF(F21>=98%,"Achived",IF(G21>=75%,"Wait","Lost"))) -> Wait | O21: =IF(E21=0,0,IF(N21="Wait",D21*0.9,IF($T$3="Y",E21,IF(AND(N21="achived",F21<=1.1),E21,IF(F21>=1.1,D21*1.1,IF(N21="Lost",E21,"ER")))))) -> 56.7 | P21: =T3 -> N | Q21: =IFERROR((I21*E21)/((J21/100)*86400),0) -> 0.28121142
A22: =R3 -> Enterprise | B22: =Master!$AX$1 -> 45965 | C22: 0.41666667 | D22: =Master!AK23 -> 62 | E22: =Master!I23 -> 36 | F22: =IFERROR(IF(OR(E22="-",E22=0),"",E22/D22),0) -> 0.58064516 | G22: =Master!B23 -> 0.97 | H22: =IFERROR(E22*I22,0) -> 0 | I22: =IFERROR(((Master!AD23*3600*24)*((Master!P23/100)/Master!#REF!)),0) -> 0 | J22: =Master!P23 -> 88 | K22: =(D22*Validation!$M$4/1800)/IF(Validation!$N$4="",(IF(OR(NOT(ISNUMBER(J22)),J22=0),1,J22%)),Validation!$N$4) -> 15.196078 | L22: =Master!W23 -> 15 | M22: =IF(AND(ISNUMBER(L22),L22>0),L22-K22,"-") -> -0.19607843 | N22: =IF(OR(E22=0,E22="-"),"",IF(F22>=98%,"Achived",IF(G22>=75%,"Wait","Lost"))) -> Wait | O22: =IF(E22=0,0,IF(N22="Wait",D22*0.9,IF($T$3="Y",E22,IF(AND(N22="achived",F22<=1.1),E22,IF(F22>=1.1,D22*1.1,IF(N22="Lost",E22,"ER")))))) -> 55.8 | P22: =T3 -> N | Q22: =IFERROR((I22*E22)/((J22/100)*86400),0) -> 0
A23: =R3 -> Enterprise | B23: =Master!$AX$1 -> 45965 | C23: 0.4375 | D23: =Master!AK24 -> 65 | E23: =Master!I24 -> 56 | F23: =IFERROR(IF(OR(E23="-",E23=0),"",E23/D23),0) -> 0.86153846 | G23: =Master!B24 -> 0.78 | H23: =IFERROR(E23*I23,0) -> 26790 | I23: =IFERROR(((Master!AD24*3600*24)*((Master!P24/100)/Master!I24)),0) -> 478.39286 | J23: =Master!P24 -> 94 | K23: =(D23*Validation!$M$4/1800)/IF(Validation!$N$4="",(IF(OR(NOT(ISNUMBER(J23)),J23=0),1,J23%)),Validation!$N$4) -> 15.931373 | L23: =Master!W24 -> 16 | M23: =IF(AND(ISNUMBER(L23),L23>0),L23-K23,"-") -> 0.068627451 | N23: =IF(OR(E23=0,E23="-"),"",IF(F23>=98%,"Achived",IF(G23>=75%,"Wait","Lost"))) -> Wait | O23: =IF(E23=0,0,IF(N23="Wait",D23*0.9,IF($T$3="Y",E23,IF(AND(N23="achived",F23<=1.1),E23,IF(F23>=1.1,D23*1.1,IF(N23="Lost",E23,"ER")))))) -> 58.5 | P23: =T3 -> N | Q23: =IFERROR((I23*E23)/((J23/100)*86400),0) -> 0.32986111
A24: =R3 -> Enterprise | B24: =Master!$AX$1 -> 45965 | C24: 0.45833333 | D24: =Master!AK25 -> 60 | E24: =Master!I25 -> 57 | F24: =IFERROR(IF(OR(E24="-",E24=0),"",E24/D24),0) -> 0.95 | G24: =Master!B25 -> 0.65 | H24: =IFERROR(E24*I24,0) -> 27600 | I24: =IFERROR(((Master!AD25*3600*24)*((Master!P25/100)/Master!I25)),0) -> 484.21053 | J24: =Master!P25 -> 92 | K24: =(D24*Validation!$M$4/1800)/IF(Validation!$N$4="",(IF(OR(NOT(ISNUMBER(J24)),J24=0),1,J24%)),Validation!$N$4) -> 14.705882 | L24: =Master!W25 -> 19 | M24: =IF(AND(ISNUMBER(L24),L24>0),L24-K24,"-") -> 4.2941176 | N24: =IF(OR(E24=0,E24="-"),"",IF(F24>=98%,"Achived",IF(G24>=75%,"Wait","Lost"))) -> Lost | O24: =IF(E24=0,0,IF(N24="Wait",D24*0.9,IF($T$3="Y",E24,IF(AND(N24="achived",F24<=1.1),E24,IF(F24>=1.1,D24*1.1,IF(N24="Lost",E24,"ER")))))) -> 57 | P24: =T3 -> N | Q24: =IFERROR((I24*E24)/((J24/100)*86400),0) -> 0.34722222
A25: =R3 -> Enterprise | B25: =Master!$AX$1 -> 45965 | C25: 0.47916667 | D25: =Master!AK26 -> 67 | E25: =Master!I26 -> 51 | F25: =IFERROR(IF(OR(E25="-",E25=0),"",E25/D25),0) -> 0.76119403 | G25: =Master!B26 -> 0.78 | H25: =IFERROR(E25*I25,0) -> 31471.2 | I25: =IFERROR(((Master!AD26*3600*24)*((Master!P26/100)/Master!I26)),0) -> 617.08235 | J25: =Master!P26 -> 94 | K25: =(D25*Validation!$M$4/1800)/IF(Validation!$N$4="",(IF(OR(NOT(ISNUMBER(J25)),J25=0),1,J25%)),Validation!$N$4) -> 16.421569 | L25: =Master!W26 -> 17 | M25: =IF(AND(ISNUMBER(L25),L25>0),L25-K25,"-") -> 0.57843137 | N25: =IF(OR(E25=0,E25="-"),"",IF(F25>=98%,"Achived",IF(G25>=75%,"Wait","Lost"))) -> Wait | O25: =IF(E25=0,0,IF(N25="Wait",D25*0.9,IF($T$3="Y",E25,IF(AND(N25="achived",F25<=1.1),E25,IF(F25>=1.1,D25*1.1,IF(N25="Lost",E25,"ER")))))) -> 60.3 | P25: =T3 -> N | Q25: =IFERROR((I25*E25)/((J25/100)*86400),0) -> 0.3875
A26: =R3 -> Enterprise | B26: =Master!$AX$1 -> 45965 | C26: 0.5 | D26: =Master!AK27 -> 67 | E26: =Master!I27 -> 69 | F26: =IFERROR(IF(OR(E26="-",E26=0),"",E26/D26),0) -> 1.0298507 | G26: =Master!B27 -> 0.75 | H26: =IFERROR(E26*I26,0) -> 32260.8 | I26: =IFERROR(((Master!AD27*3600*24)*((Master!P27/100)/Master!I27)),0) -> 467.54783 | J26: =Master!P27 -> 94 | K26: =(D26*Validation!$M$4/1800)/IF(Validation!$N$4="",(IF(OR(NOT(ISNUMBER(J26)),J26=0),1,J26%)),Validation!$N$4) -> 16.421569 | L26: =Master!W27 -> 20 | M26: =IF(AND(ISNUMBER(L26),L26>0),L26-K26,"-") -> 3.5784314 | N26: =IF(OR(E26=0,E26="-"),"",IF(F26>=98%,"Achived",IF(G26>=75%,"Wait","Lost"))) -> Achived | O26: =IF(E26=0,0,IF(N26="Wait",D26*0.9,IF($T$3="Y",E26,IF(AND(N26="achived",F26<=1.1),E26,IF(F26>=1.1,D26*1.1,IF(N26="Lost",E26,"ER")))))) -> 69 | P26: =T3 -> N | Q26: =IFERROR((I26*E26)/((J26/100)*86400),0) -> 0.39722222
A27: =R3 -> Enterprise | B27: =Master!$AX$1 -> 45965 | C27: 0.52083333 | D27: =Master!AK28 -> 74 | E27: =Master!I28 -> 55 | F27: =IFERROR(IF(OR(E27="-",E27=0),"",E27/D27),0) -> 0.74324324 | G27: =Master!B28 -> 0.71 | H27: =IFERROR(E27*I27,0) -> 33703.2 | I27: =IFERROR(((Master!AD28*3600*24)*((Master!P28/100)/Master!I28)),0) -> 612.78545 | J27: =Master!P28 -> 93 | K27: =(D27*Validation!$M$4/1800)/IF(Validation!$N$4="",(IF(OR(NOT(ISNUMBER(J27)),J27=0),1,J27%)),Validation!$N$4) -> 18.137255 | L27: =Master!W28 -> 21 | M27: =IF(AND(ISNUMBER(L27),L27>0),L27-K27,"-") -> 2.8627451 | N27: =IF(OR(E27=0,E27="-"),"",IF(F27>=98%,"Achived",IF(G27>=75%,"Wait","Lost"))) -> Lost | O27: =IF(E27=0,0,IF(N27="Wait",D27*0.9,IF($T$3="Y",E27,IF(AND(N27="achived",F27<=1.1),E27,IF(F27>=1.1,D27*1.1,IF(N27="Lost",E27,"ER")))))) -> 55 | P27: =T3 -> N | Q27: =IFERROR((I27*E27)/((J27/100)*86400),0) -> 0.41944444
A28: =R3 -> Enterprise | B28: =Master!$AX$1 -> 45965 | C28: 0.54166667 | D28: =Master!AK29 -> 78 | E28: =Master!I29 -> 60 | F28: =IFERROR(IF(OR(E28="-",E28=0),"",E28/D28),0) -> 0.76923077 | G28: =Master!B29 -> 0.84 | H28: =IFERROR(E28*I28,0) -> 36691.2 | I28: =IFERROR(((Master!AD29*3600*24)*((Master!P29/100)/Master!I29)),0) -> 611.52 | J28: =Master!P29 -> 96 | K28: =(D28*Validation!$M$4/1800)/IF(Validation!$N$4="",(IF(OR(NOT(ISNUMBER(J28)),J28=0),1,J28%)),Validation!$N$4) -> 19.117647 | L28: =Master!W29 -> 22 | M28: =IF(AND(ISNUMBER(L28),L28>0),L28-K28,"-") -> 2.8823529 | N28: =IF(OR(E28=0,E28="-"),"",IF(F28>=98%,"Achived",IF(G28>=75%,"Wait","Lost"))) -> Wait | O28: =IF(E28=0,0,IF(N28="Wait",D28*0.9,IF($T$3="Y",E28,IF(AND(N28="achived",F28<=1.1),E28,IF(F28>=1.1,D28*1.1,IF(N28="Lost",E28,"ER")))))) -> 70.2 | P28: =T3 -> N | Q28: =IFERROR((I28*E28)/((J28/100)*86400),0) -> 0.44236111
A29: =R3 -> Enterprise | B29: =Master!$AX$1 -> 45965 | C29: 0.5625 | D29: =Master!AK30 -> 71 | E29: =Master!I30 -> 66 | F29: =IFERROR(IF(OR(E29="-",E29=0),"",E29/D29),0) -> 0.92957746 | G29: =Master!B30 -> 0.77 | H29: =IFERROR(E29*I29,0) -> 36772.8 | I29: =IFERROR(((Master!AD30*3600*24)*((Master!P30/100)/Master!I30)),0) -> 557.16364 | J29: =Master!P30 -> 94 | K29: =(D29*Validation!$M$4/1800)/IF(Validation!$N$4="",(IF(OR(NOT(ISNUMBER(J29)),J29=0),1,J29%)),Validation!$N$4) -> 17.401961 | L29: =Master!W30 -> 22 | M29: =IF(AND(ISNUMBER(L29),L29>0),L29-K29,"-") -> 4.5980392 | N29: =IF(OR(E29=0,E29="-"),"",IF(F29>=98%,"Achived",IF(G29>=75%,"Wait","Lost"))) -> Wait | O29: =IF(E29=0,0,IF(N29="Wait",D29*0.9,IF($T$3="Y",E29,IF(AND(N29="achived",F29<=1.1),E29,IF(F29>=1.1,D29*1.1,IF(N29="Lost",E29,"ER")))))) -> 63.9 | P29: =T3 -> N | Q29: =IFERROR((I29*E29)/((J29/100)*86400),0) -> 0.45277778
