Workbook

Sheet FL
A1: VF-Cash Red | F1: Fri | G1: Sat | H1: Sun | I1: Mon | J1: Tue | K1: Wed | L1: Thu | M1: Fri | N1: Sat | O1: Sun | P1: Mon | Q1: Tue | R1: Wed | S1: Thu | T1: Fri | U1: Sat | V1: Sun | W1: Mon | X1: Tue | Y1: Wed | Z1: Thu | AA1: Fri | AB1: Sat | AC1: Sun | AD1: Mon | AE1: Tue | AF1: Wed | AG1: Thu | AH1: Fri | AI1: Sat | AJ1: Sun | AK1: Summary
A2: Monthly Attendance Tracker
A3: 0 | B3: Username | C3: Displayname | D3: Leader | E3: SPV | F3: 45982 | G3: 45983 | H3: 45984 | I3: 45985 | J3: 45986 | K3: 45987 | L3: 45988 | M3: 45989 | N3: 45990 | O3: 45991 | P3: 45992 | Q3: 45993 | R3: 45994 | S3: 45995 | T3: 45996 | U3: 45997 | V3: 45998 | W3: 45999 | X3: 46000 | Y3: 46001 | Z3: 46002 | AA3: 46003 | AB3: 46004 | AC3: 46005 | AD3: 46006 | AE3: 46007 | AF3: 46008 | AG3: 46009 | AH3: 46010 | AI3: 46011 | AJ3: 46012 | AK3: Attended | AL3: No Show | AM3: Annual | AN3: Bereavement | AO3: Sick | AP3: UPL | AQ3: Compensation | AR3: Resignation | AS3: App Issue | AT3: OFF | AU3: Suspension | AV3: Training
A4: 1 | B4: V22HRassoul | C4: Hend Yousry-AbdElRassoul | D4: Mohamed Ahmed-Nagy | E4: Mohamed Ahmed-Nagy | F4: Task | G4: Task | H4: Task | I4: Task | J4: Task | K4: Task | L4: Task | M4: Task | N4: Task | O4: Task | P4: Task | Q4: Task | R4: Task | S4: Task | T4: Task | U4: Task | V4: Task | W4: Task | X4: Task | Y4: Task | Z4: Task | AA4: Task | AB4: Task | AK4: 23 | AL4: 0 | AM4: 0 | AN4: 0 | AO4: 0 | AP4: 0 | AQ4: 0 | AR4: 0 | AS4: 0 | AT4: 0 | AU4: 0 | AV4: 0
A5: 2 | B5: V23MGelil | C5: Mohamed Ali-AbdElGelil | D5: Omar Emad-Mahmoud | E5: Mohamed Ahmed-Nagy | F5: Attended | G5: OFF | H5: Attended | I5: Attended | J5: Attended | K5: Attended | L5: Attended | M5: Attended | N5: Off | O5: Compensation | P5: Attended | Q5: Attended | R5: Attended | S5: Attended | T5: Off | U5: Off | V5: No Show | W5: No Show | X5: Attended | Y5: Attended | Z5: Attended | AA5: Off | AB5: Attended | AK5: 15 | AL5: 2 | AM5: 0 | AN5: 0 | AO5: 0 | AP5: 0 | AQ5: 1 | AR5: 0 | AS5: 0 | AT5: 5 | AU5: 0 | AV5: 0
A6: 3 | B6: V24OMahmoud | C6: Omar Emad-Mahmoud | D6: Mohamed Ahmed-Nagy | E6: Mohamed Ahmed-Nagy | F6: Task | G6: Off | H6: Task | I6: Attended | J6: Off | K6: Task | L6: Attended | M6: Task | N6: Off | O6: Off | P6: Task | Q6: Task | R6: Attended | S6: Task | T6: Attended | U6: Task | V6: Task | W6: Task | X6: Task | Y6: Task | Z6: Attended | AA6: Task | AB6: Task | AK6: 19 | AL6: 0 | AM6: 0 | AN6: 0 | AO6: 0 | AP6: 0 | AQ6: 0 | AR6: 0 | AS6: 0 | AT6: 4 | AU6: 0 | AV6: 0
A7: 4 | B7: V24AHassan6 | C7: Aya Mohamed-Hassan | D7: Merna Ashraf-Ashrafy | E7: Mohamed Ahmed-Nagy | F7: Off | G7: Off | H7: Attended | I7: Attended | J7: Attended | K7: Attended | L7: Attended | M7: Off | N7: Off | O7: Attended | P7: Attended | Q7: Attended | R7: Attended | S7: Attended | T7: Off | U7: Off | V7: Attended | W7: Attended | X7: Attended | Y7: Attended | Z7: Attended | AA7: Off | AB7: OFF | AK7: 15 | AL7: 0 | AM7: 0 | AN7: 0 | AO7: 0 | AP7: 0 | AQ7: 0 | AR7: 0 | AS7: 0 | AT7: 8 | AU7: 0 | AV7: 0
A8: 5 | B8: V22MAshrafy | C8: Merna Ashraf-Ashrafy | D8: Mohamed Ahmed-Nagy | E8: Mohamed Ahmed-Nagy | F8: Task | G8: Task | H8: Task | I8: Task | J8: Task | K8: Task | L8: Task | M8: Task | N8: Task | O8: Task | P8: Task | Q8: Task | R8: Task | S8: Task | T8: Task | U8: Task | V8: Task | W8: Task | X8: Task | Y8: Task | Z8: Task | AA8: Task | AB8: Task | AK8: 23 | AL8: 0 | AM8: 0 | AN8: 0 | AO8: 0 | AP8: 0 | AQ8: 0 | AR8: 0 | AS8: 0 | AT8: 0 | AU8: 0 | AV8: 0
A9: 6 | B9: V24SAhmed28 | C9: Salma Taha-Ahmed | D9: Merna Ashraf-Ashrafy | E9: Mohamed Ahmed-Nagy | F9: Off | G9: Off | H9: Attended | I9: Attended | J9: Attended | K9: Attended | L9: Attended | M9: Off | N9: Off | O9: Attended | P9: Attended | Q9: No Show | R9: Attended | S9: Attended | T9: Off | U9: Off | V9: No Show | W9: No Show | X9: No Show | Y9: No Show | Z9: No Show | AA9: Off | AB9: No Show | AK9: 9 | AL9: 7 | AM9: 0 | AN9: 0 | AO9: 0 | AP9: 0 | AQ9: 0 | AR9: 0 | AS9: 0 | AT9: 7 | AU9: 0 | AV9: 0
A10: 7 | B10: V24AKelany | C10: AbdElRahman Adel-ElKelany | D10: Mohamed Ahmed-Nagy | E10: Mohamed Ahmed-Nagy | F10: Attended | G10: Attended | H10: Attended | I10: Attended | J10: Attended | K10: Task | L10: Task | M10: Task | N10: Task | O10: Task | P10: Task | Q10: OFF | R10: Off | S10: Task | T10: Task | U10: Attended | V10: Task | W10: Task | X10: Task | Y10: Task | Z10: Task | AA10: Task | AB10: Task | AK10: 21 | AL10: 0 | AM10: 0 | AN10: 0 | AO10: 0 | AP10: 0 | AQ10: 0 | AR10: 0 | AS10: 0 | AT10: 2 | AU10: 0 | AV10: 0
A11: 8 | B11: V24OSamea | C11: Omnia Salah-AbdElSamea | D11: Merna Ashraf-Ashrafy | E11: Mohamed Ahmed-Nagy | F11: No Show | G11: Off | H11: Off | I11: No Show | J11: No Show | K11: Attended | L11: Attended | M11: Attended | N11: Off | O11: Off | P11: Attended | Q11: Attended | R11: Attended | S11: Attended | T11: Attended | U11: Off | V11: Off | W11: Attended | X11: Attended | Y11: Attended | Z11: Attended | AA11: Attended | AB11: OFF | AK11: 13 | AL11: 3 | AM11: 0 | AN11: 0 | AO11: 0 | AP11: 0 | AQ11: 0 | AR11: 0 | AS11: 0 | AT11: 7 | AU11: 0 | AV11: 0
A12: 9 | B12: V24AMohamed142 | C12: Ahmed Hany-Mohamed | D12: Mohamed Ahmed-Nagy | E12: Mohamed Ahmed-Nagy | F12: Suspended | G12: Suspended | H12: Suspended | I12: Suspended | J12: Suspended | K12: Suspended | L12: Suspended | M12: Suspended | N12: Suspended | O12: Suspended | P12: Suspended | Q12: Suspended | R12: Suspended | S12: Suspended | T12: Suspended | U12: Suspended | V12: Suspended | W12: Suspended | X12: Suspended | Y12: Suspended | Z12: Suspended | AA12: Suspended | AB12: Suspended | AK12: 0 | AL12: 0 | AM12: 0 | AN12: 0 | AO12: 0 | AP12: 0 | AQ12: 0 | AR12: 0 | AS12: 0 | AT12: 0 | AU12: 0 | AV12: 0
A13: 10 | B13: V24KKhalek1 | C13: Khaled Waleed-AbdElKhalek | D13: Omar Emad-Mahmoud | E13: Mohamed Ahmed-Nagy | F13: Attended | G13: Attended | H13: Attended | I13: Off | J13: Attended | K13: Attended | L13: Attended | M13: Attended | N13: Attended | O13: Attended | P13: Attended | Q13: Attended | R13: Compensation | S13: Off | T13: Off | U13: Off | V13: Off | W13: Attended | X13: Attended | Y13: Attended | Z13: Attended | AA13: Attended | AB13: Attended | AK13: 17 | AL13: 0 | AM13: 0 | AN13: 0 | AO13: 0 | AP13: 0 | AQ13: 1 | AR13: 0 | AS13: 0 | AT13: 5 | AU13: 0 | AV13: 0
A14: 11 | B14: V25RFarag3 | C14: Rawan Ayman-Farag | D14: Merna Ashraf-Ashrafy | E14: Mohamed Ahmed-Nagy | F14: Attended | G14: Off | H14: Attended | I14: Attended | J14: Off | K14: Attended | L14: Attended | M14: Attended | N14: Attended | O14: Attended | P14: Attended | Q14: Off | R14: Off | S14: Attended | T14: Attended | U14: Off | V14: Attended | W14: Off | X14: Attended | Y14: Attended | Z14: Attended | AA14: Attended | AB14: OFF | AK14: 16 | AL14: 0 | AM14: 0 | AN14: 0 | AO14: 0 | AP14: 0 | AQ14: 0 | AR14: 0 | AS14: 0 | AT14: 7 | AU14: 0 | AV14: 0
A15: 12 | B15: V25ASamir2 | C15: AbdElRahman Mohamed-Samir | D15: AbdElRahman Adel-ElKelany | E15: Mohamed Ahmed-Nagy | F15: Attended | G15: Off | H15: Off | I15: No Show | J15: No Show | K15: Attended | L15: Attended | M15: Attended | N15: Off | O15: Attended | P15: Attended | Q15: Attended | R15: Off | S15: Attended | T15: Attended | U15: Off | V15: Attended | W15: Attended | X15: Attended | Y15: Attended | Z15: Off | AA15: Attended | AB15: Attended | AK15: 15 | AL15: 2 | AM15: 0 | AN15: 0 | AO15: 0 | AP15: 0 | AQ15: 0 | AR15: 0 | AS15: 0 | AT15: 6 | AU15: 0 | AV15: 0
... A52: 49 | B52: V25MMohamed279 | C52: Mohamed Adel-Mohamed | D52: Omar Emad-Mahmoud | E52: Mohamed Ahmed-Nagy | F52: - | G52: - | H52: - | I52: - | J52: - | K52: - | L52: - | M52: - | N52: - | O52: - | P52: - | Q52: Training | R52: App issue | S52: App Issue | T52: App issue | U52: App issue | V52: App issue | W52: Training | X52: Attended | Y52: Attended | Z52: Attended | AA52: Attended | AB52: Off | AK52: 4 | AL52: 0 | AM52: 0 | AN52: 0 | AO52: 0 | AP52: 0 | AQ52: 0 | AR52: 0 | AS52: 5 | AT52: 1 | AU52: 0 | AV52: 2

Sheet Conformance
A1: VF-Cash Red | E1: Fri | F1: Sat | G1: Sun | H1: Mon | I1: Tue | J1: Wed | K1: Thu | L1: Fri | M1: Sat | N1: Sun | O1: Mon | P1: Tue | Q1: Wed | R1: Thu | S1: Fri | T1: Sat | U1: Sun | V1: Mon | W1: Tue | X1: Wed | Y1: Thu | Z1: Fri | AA1: Sat | AB1: Sun | AC1: Mon | AD1: Tue | AE1: Wed | AF1: Thu | AG1: Fri | AH1: Sat | AI1: Sun | AJ1: Summary
A2: Monthly Conformance Tracker
A3: 0 | B3: Username | C3: Displayname | D3: Leader | E3: 45982 | F3: 45983 | G3: 45984 | H3: 45985 | I3: 45986 | J3: 45987 | K3: 45988 | L3: 45989 | M3: 45990 | N3: 45991 | O3: 45992 | P3: 45993 | Q3: 45994 | R3: 45995 | S3: 45996 | T3: 45997 | U3: 45998 | V3: 45999 | W3: 46000 | X3: 46001 | Y3: 46002 | Z3: 46003 | AA3: 46004 | AB3: 46005 | AC3: 46006 | AD3: 46007 | AE3: 46008 | AF3: 46009 | AG3: 46010 | AH3: 46011 | AI3: 46012 | AJ3: Missing
A4: 1 | B4: V22HRassoul | C4: Hend Yousry-AbdElRassoul | D4: Mohamed Ahmed-Nagy | AJ4: 0
A5: 2 | B5: V23MGelil | C5: Mohamed Ali-AbdElGelil | D5: Omar Emad-Mahmoud | E5: 0.0071180556 | H5: 0.020243056 | I5: 0.0014814815 | J5: 0.026805556 | K5: 0.011898148 | L5: 0.016747685 | P5: 0.0093171296 | Q5: 0.079212963 | R5: 0.001412037 | AJ5: 0.17423611
A6: 3 | B6: V24OMahmoud | C6: Omar Emad-Mahmoud | D6: Mohamed Ahmed-Nagy | H6: 0 | K6: 0 | Q6: 4.6296296e-05 | S6: 0.23561343 | AJ6: 0.23565972
A7: 4 | B7: V24AHassan6 | C7: Aya Mohamed-Hassan | D7: Merna Ashraf-Ashrafy | AJ7: 0
A8: 5 | B8: V22MAshrafy | C8: Merna Ashraf-Ashrafy | D8: Mohamed Ahmed-Nagy | AJ8: 0
A9: 6 | B9: V24SAhmed28 | C9: Salma Taha-Ahmed | D9: Merna Ashraf-Ashrafy | G9: 0.0083796296 | AJ9: 0.0083796296
A10: 7 | B10: V24AKelany | C10: AbdElRahman Adel-ElKelany | D10: Mohamed Ahmed-Nagy | E10: 2.3148148e-05 | H10: 0 | AJ10: 2.3148148e-05
A11: 8 | B11: V24OSamea | C11: Omnia Salah-AbdElSamea | D11: Merna Ashraf-Ashrafy | K11: 0.023611111 | O11: 0.014456019 | P11: 0.0010416667 | Q11: 0.0060416667 | AJ11: 0.045150463
A12: 9 | B12: V24AMohamed142 | C12: Ahmed Hany-Mohamed | D12: Mohamed Ahmed-Nagy | AJ12: 0
A13: 10 | B13: V24KKhalek1 | C13: Khaled Waleed-AbdElKhalek | D13: Omar Emad-Mahmoud | M13: 0.0050925926 | AJ13: 0.0050925926
A14: 11 | B14: V25RFarag3 | C14: Rawan Ayman-Farag | D14: Merna Ashraf-Ashrafy | O14: 0.0028703704 | AJ14: 0.0028703704
A15: 12 | B15: V25ASamir2 | C15: AbdElRahman Mohamed-Samir | D15: AbdElRahman Adel-ElKelany | R15: 0.0035069444 | AJ15: 0.0035069444
A16: 13 | B16: V25SZekry | C16: Safaa Safwat-Zekry | D16: Merna Ashraf-Ashrafy | H16: 0.0053703704 | S16: 0.0063657407 | AJ16: 0.011736111
A17: 14 | B17: V24OMohamed10 | C17: Osama Magdy-Mohamed | D17: AbdElRahman Adel-ElKelany | K17: 0.010891204 | L17: 0.062939815 | M17: 0.029027778 | O17: 0.0067939815 | P17: 0.011122685 | AJ17: 0.12077546
A18: 15 | B18: V25TAhmed3 | C18: Tarek Ayman-Ahmed | D18: AbdElRahman Adel-ElKelany | E18: 0.0082638889 | F18: 0.0068055556 | I18: 0.012013889 | K18: 0.021064815 | M18: 0.015960648 | O18: 0.000625 | P18: 0.0043981481 | Q18: 0.017951389 | R18: 0.015949074 | AJ18: 0.10303241
A19: 16 | B19: V25ARizk | C19: Ahmed Sameh-Rizk | D19: Omar Emad-Mahmoud | E19: 0.0064930556 | L19: 0.0059143519 | O19: 0.014409722 | Q19: 0.0041666667 | S19: 0.015 | AJ19: 0.045983796
A20: 17 | B20: V25YMohamed24 | C20: Yasmine Waleed-Mohamed | D20: Merna Ashraf-Ashrafy | AJ20: 0
A21: 18 | B21: V25NSaeed1 | C21: Nouran AbdAllah-Saeed | D21: Merna Ashraf-Ashrafy | O21: 0.00074074074 | R21: 0.0018402778 | AJ21: 0.0025810185
A22: 19 | B22: V25JRazek | C22: Jana HossamElDin-AbdElRazek | D22: Merna Ashraf-Ashrafy | V22: 0.043611111 | AJ22: 0.043611111
A23: 20 | B23: V25OAzab | C23: Omnia Wageeh-ElAzab | D23: AbdElRahman Adel-ElKelany | S23: 0 | AJ23: 0
A24: 21 | B24: V25MHassanien | C24: Mohamed Adel-Hassanien | D24: AbdElRahman Adel-ElKelany | H24: 0.002974537 | AJ24: 0.002974537
A25: 22 | B25: V25OMahmoud1 | C25: Ola Essam-Mahmoud | D25: Merna Ashraf-Ashrafy | AJ25: 0
A26: 23 | B26: V25YMohamed7 | C26: Youssef Hamdy-Mohamed | D26: Omar Emad-Mahmoud | E26: 0.0045833333 | F26: 0.0044791667 | L26: 0.0038194444 | M26: 0.046273148 | Q26: 0.017175926 | S26: 0.0031018519 | AJ26: 0.07943287
A27: 24 | B27: V25AHussein9 | C27: Ahmed Khaled-Hussein | D27: Omar Emad-Mahmoud | I27: 0.00033564815 | K27: 0.0050810185 | M27: 0.0070486111 | R27: 0.01412037 | AJ27: 0.026585648
A28: 25 | B28: V24ASaeed11 | C28: Ali Bahat-Saeed | D28: Omar Emad-Mahmoud | K28: 0.0013888889 | AJ28: 0.0013888889
A29: 26 | B29: V25BHassan3 | C29: Bassant Salah-Hassan | D29: AbdElRahman Adel-ElKelany | AJ29: 0
A30: 27 | B30: V25MHamdy1 | C30: Mohada Mohamed-Hamdy | D30: Merna Ashraf-Ashrafy | AJ30: 0
A31: 28 | B31: V25AMahmoud45 | C31: Aya Ezzat-Mahmoud | D31: AbdElRahman Adel-ElKelany | F31: 0.0053935185 | G31: 0.018229167 | AJ31: 0.023622685
A32: 29 | B32: V25IZakaria | C32: Islam Gamal-Zakaria | D32: Omar Emad-Mahmoud | H32: 0.0017939815 | O32: 0.025127315 | P32: 0.0052083333 | AJ32: 0.03212963
A33: 30 | B33: V25AAziz28 | C33: AbdAllah Shaker-AbdElAziz | D33: Omar Emad-Mahmoud | E33: 0.00074074074 | M33: 0.023136574 | O33: 0.0086111111 | AJ33: 0.032488426
A34: 31 | B34: V25HAhmed43 | C34: Hatem Ibrahim-Ahmed | D34: Omar Emad-Mahmoud | I34: 0.010300926 | J34: 0.005150463 | M34: 0.023958333 | P34: 0.013888889 | Q34: 0.020763889 | AJ34: 0.0740625
A35: 32 | B35: V25AEwis2 | C35: Ahmed Magdy-Ewis | D35: Omar Emad-Mahmoud | G35: 0.00033564815 | K35: 0.051724537 | M35: 0.029143519 | AJ35: 0.081203704
A36: 33 | B36: V25AEldemerdash | C36: Anas Mohamed-Eldemerdash | D36: AbdElRahman Adel-ElKelany | L36: 0.0020949074 | AJ36: 0.0020949074
A37: 34 | B37: V25SSagheer | C37: Samir Hosny-Sagheer | D37: AbdElRahman Adel-ElKelany | H37: 0.0024652778 | I37: 0.0038078704 | K37: 0.0059490741 | O37: 0.051122685 | Q37: 0.014340278 | R37: 0.053217593 | AJ37: 0.13090278
A38: 35 | B38: V25FMagd | C38: Farha Ashraf-AboElMagd | D38: Merna Ashraf-Ashrafy | I38: 0.00043981481 | O38: 0.00017361111 | U38: 0.00010416667 | AJ38: 0.00071759259
A39: 36 | B39: V25NMawla1 | C39: Nesreen Emad-AbdElMawla | D39: Merna Ashraf-Ashrafy | G39: 0.01775463 | O39: 0.20101852 | AJ39: 0.21877315
A40: 37 | B40: V25MAhmed108 | C40: Mohamed Yasser-Ahmed | D40: Omar Emad-Mahmoud | E40: 0.0016550926 | M40: 0.025104167 | O40: 0.017905093 | AJ40: 0.044664352
...

Sheet Tardy tracker
A1: VF-Cash Red | E1: Fri | F1: Sat | G1: Sun | H1: Mon | I1: Tue | J1: Wed | K1: Thu | L1: Fri | M1: Sat | N1: Sun | O1: Mon | P1: Tue | Q1: Wed | R1: Thu | S1: Fri | T1: Sat | U1: Sun | V1: Mon | W1: Tue | X1: Wed | Y1: Thu | Z1: Fri | AA1: Sat | AB1: Sun | AC1: Mon | AD1: Tue | AE1: Wed | AF1: Thu | AG1: Fri | AH1: Sat | AI1: Sun | AJ1: Tardy
A2: Monthly Tardy Tracker
A3: 0 | B3: Username | C3: Displayname | D3: Leader | E3: 45982 | F3: 45983 | G3: 45984 | H3: 45985 | I3: 45986 | J3: 45987 | K3: 45988 | L3: 45989 | M3: 45990 | N3: 45991 | O3: 45992 | P3: 45993 | Q3: 45994 | R3: 45995 | S3: 45996 | T3: 45997 | U3: 45998 | V3: 45999 | W3: 46000 | X3: 46001 | Y3: 46002 | Z3: 46003 | AA3: 46004 | AB3: 46005 | AC3: 46006 | AD3: 46007 | AE3: 46008 | AF3: 46009 | AG3: 46010 | AH3: 46011 | AI3: 46012 | AJ3: Tardy | AK3: NM Tardy
A4: 1 | B4: V22HRassoul | C4: Hend Yousry-AbdElRassoul | D4: Mohamed Ahmed-Nagy | AJ4: 0 | AK4: 0
A5: 2 | B5: V23MGelil | C5: Mohamed Ali-AbdElGelil | D5: Omar Emad-Mahmoud | E5: 45982.009 | H5: 45985.054 | I5: 45986.003 | J5: 45987.028 | Q5: 45994.079 | W5: 46000.061 | Y5: 46002.012 | Z5: 46001.058 | AA5: 46004.048 | AJ5: 0.35234954 | AK5: 8.4563889
A6: 3 | B6: V24OMahmoud | C6: Omar Emad-Mahmoud | D6: Mohamed Ahmed-Nagy | H6: 0 | J6: 0 | Q6: 45994.043 | AJ6: 0.043275463 | AK6: 1.0386111
A7: 4 | B7: V24AHassan6 | C7: Aya Mohamed-Hassan | D7: Merna Ashraf-Ashrafy | K7: 0 | AJ7: 0 | AK7: 0
A8: 5 | B8: V22MAshrafy | C8: Merna Ashraf-Ashrafy | D8: Mohamed Ahmed-Nagy | AJ8: 0 | AK8: 0
A9: 6 | B9: V24SAhmed28 | C9: Salma Taha-Ahmed | D9: Merna Ashraf-Ashrafy | K9: 0 | AJ9: 0 | AK9: 0
A10: 7 | B10: V24AKelany | C10: AbdElRahman Adel-ElKelany | D10: Mohamed Ahmed-Nagy | F10: 0 | H10: 0 | J10: 0 | R10: 45995.233 | AJ10: 0.23251157 | AK10: 5.5802778
A11: 8 | B11: V24OSamea | C11: Omnia Salah-AbdElSamea | D11: Merna Ashraf-Ashrafy | O11: 45992.06 | X11: 46001.003 | Z11: 46001.003 | AJ11: 0.066539352 | AK11: 1.5969444
A12: 9 | B12: V24AMohamed142 | C12: Ahmed Hany-Mohamed | D12: Mohamed Ahmed-Nagy | AJ12: 0 | AK12: 0
A13: 10 | B13: V24KKhalek1 | C13: Khaled Waleed-AbdElKhalek | D13: Omar Emad-Mahmoud | N13: 45991.004 | V13: 45999.037 | W13: 46000.031 | Y13: 46002.002 | Z13: 46001 | AJ13: 0.074490741 | AK13: 1.7877778
A14: 11 | B14: V25RFarag3 | C14: Rawan Ayman-Farag | D14: Merna Ashraf-Ashrafy | K14: 0 | M14: 0 | Y14: 46002.062 | AJ14: 0.061909722 | AK14: 1.4858333
A15: 12 | B15: V25ASamir2 | C15: AbdElRahman Mohamed-Samir | D15: AbdElRahman Adel-ElKelany | H15: 0 | P15: 45993 | R15: 45995.03 | U15: 45998.046 | W15: 46000.018 | X15: 46001.003 | Z15: 46001.003 | AJ15: 0.10052083 | AK15: 2.4125
A16: 13 | B16: V25SZekry | C16: Safaa Safwat-Zekry | D16: Merna Ashraf-Ashrafy | AA16: 46004.005 | AJ16: 0.0049652778 | AK16: 0.11916667
A17: 14 | B17: V24OMohamed10 | C17: Osama Magdy-Mohamed | D17: AbdElRahman Adel-ElKelany | I17: 0 | J17: 0 | U17: 45998.015 | V17: 45999.003 | W17: 46000.078 | Z17: 46001.025 | AJ17: 0.12081019 | AK17: 2.8994444
A18: 15 | B18: V25TAhmed3 | C18: Tarek Ayman-Ahmed | D18: AbdElRahman Adel-ElKelany | E18: 45982.007 | F18: 45983.003 | H18: 45985.019 | I18: 45986.007 | J18: 0 | L18: 45989.008 | P18: 45993.045 | Q18: 45994.013 | R18: 45995.058 | U18: 45998.025 | W18: 46000.101 | Z18: 46001.03 | AA18: 46004.008 | AJ18: 0.32461806 | AK18: 7.7908333
A19: 16 | B19: V25ARizk | C19: Ahmed Sameh-Rizk | D19: Omar Emad-Mahmoud | E19: 45982.007 | H19: 45985.01 | J19: 0 | L19: 0.011805556 | N19: 0 | P19: 0 | Q19: 45994.004 | R19: 45995.03 | U19: 45998.122 | V19: 45999.017 | Y19: 46002.015 | AJ19: 0.21667824 | AK19: 5.2002778
A20: 17 | B20: V25YMohamed24 | C20: Yasmine Waleed-Mohamed | D20: Merna Ashraf-Ashrafy | G20: 0 | AJ20: 0 | AK20: 0
A21: 18 | B21: V25NSaeed1 | C21: Nouran AbdAllah-Saeed | D21: Merna Ashraf-Ashrafy | K21: 45988.004 | O21: 45992.002 | V21: 45999.005 | X21: 46001.009 | Y21: 46002.008 | Z21: 46001.009 | AJ21: 0.037071759 | AK21: 0.88972222
A22: 19 | B22: V25JRazek | C22: Jana HossamElDin-AbdElRazek | D22: Merna Ashraf-Ashrafy | G22: 0 | K22: 0 | AA22: 46004.02 | AJ22: 0.020034722 | AK22: 0.48083333
A23: 20 | B23: V25OAzab | C23: Omnia Wageeh-ElAzab | D23: AbdElRahman Adel-ElKelany | AA23: 46004.018 | AJ23: 0.017928241 | AK23: 0.43027778
A24: 21 | B24: V25MHassanien | C24: Mohamed Adel-Hassanien | D24: AbdElRahman Adel-ElKelany | H24: 0.0027777778 | I24: 45986.027 | V24: 45999.05 | W24: 46000.064 | Z24: 46001.015 | AJ24: 0.15840278 | AK24: 3.8016667
A25: 22 | B25: V25OMahmoud1 | C25: Ola Essam-Mahmoud | D25: Merna Ashraf-Ashrafy | G25: 0.0034722222 | O25: 45992.005 | AJ25: 0.0083217593 | AK25: 0.19972222
A26: 23 | B26: V25YMohamed7 | C26: Youssef Hamdy-Mohamed | D26: Omar Emad-Mahmoud | E26: 45982.005 | I26: 45986.031 | J26: 45987.016 | N26: 45991.027 | P26: 45993.013 | Q26: 45994.016 | AJ26: 0.10840278 | AK26: 2.6016667
A27: 24 | B27: V25AHussein9 | C27: Ahmed Khaled-Hussein | D27: Omar Emad-Mahmoud | F27: 45983.005 | H27: 0.0048611111 | I27: 45986 | T27: 0 | U27: 45998.031 | AA27: 46004.004 | AJ27: 0.045 | AK27: 1.08
A28: 25 | B28: V24ASaeed11 | C28: Ali Bahat-Saeed | D28: Omar Emad-Mahmoud | F28: 0 | I28: 0 | K28: 45988.001 | AJ28: 0.00055555556 | AK28: 0.013333333
A29: 26 | B29: V25BHassan3 | C29: Bassant Salah-Hassan | D29: AbdElRahman Adel-ElKelany | O29: 45992.006 | AA29: 46004.019 | AJ29: 0.024722222 | AK29: 0.59333333
A30: 27 | B30: V25MHamdy1 | C30: Mohada Mohamed-Hamdy | D30: Merna Ashraf-Ashrafy | G30: 0.0041666667 | AJ30: 0.0041666667 | AK30: 0.1
A31: 28 | B31: V25AMahmoud45 | C31: Aya Ezzat-Mahmoud | D31: AbdElRahman Adel-ElKelany | G31: 0.022916667 | V31: 45999.009 | AA31: 46004.018 | AJ31: 0.050127315 | AK31: 1.2030556
A32: 29 | B32: V25IZakaria | C32: Islam Gamal-Zakaria | D32: Omar Emad-Mahmoud | F32: 45983.006 | J32: 45987.005 | U32: 45998.006 | W32: 46000.04 | AA32: 46004.01 | AJ32: 0.067314815 | AK32: 1.6155556
A33: 30 | B33: V25AAziz28 | C33: AbdAllah Shaker-AbdElAziz | D33: Omar Emad-Mahmoud | F33: 45983.002 | K33: 45988.007 | U33: 45998.044 | Y33: 46002.014 | AJ33: 0.066851852 | AK33: 1.6044444
A34: 31 | B34: V25HAhmed43 | C34: Hatem Ibrahim-Ahmed | D34: Omar Emad-Mahmoud | F34: 45983.069 | H34: 45985.048 | I34: 0 | J34: 45987.027 | Q34: 45994.017 | U34: 45998.037 | W34: 46000.055 | AJ34: 0.25148148 | AK34: 6.0355556
A35: 32 | B35: V25AEwis2 | C35: Ahmed Magdy-Ewis | D35: Omar Emad-Mahmoud | H35: 45985.006 | I35: 45986.001 | J35: 45987.002 | K35: 0 | T35: 45997.002 | W35: 46000.052 | Z35: 46001.014 | AJ35: 0.076851852 | AK35: 1.8444444
A36: 33 | B36: V25AEldemerdash | C36: Anas Mohamed-Eldemerdash | D36: AbdElRahman Adel-ElKelany | F36: 45983.001 | J36: 0 | N36: 45991.004 | P36: 45993.002 | Y36: 46002.005 | Z36: 46001.008 | AJ36: 0.020671296 | AK36: 0.49611111
A37: 34 | B37: V25SSagheer | C37: Samir Hosny-Sagheer | D37: AbdElRahman Adel-ElKelany | F37: 0 | H37: 45985.023 | J37: 0 | K37: 45988.003 | Q37: 45994.011 | AJ37: 0.036331019 | AK37: 0.87194444
A38: 35 | B38: V25FMagd | C38: Farha Ashraf-AboElMagd | D38: Merna Ashraf-Ashrafy | G38: 45984.001 | O38: 45992 | AJ38: 0.0018402778 | AK38: 0.044166667
A39: 36 | B39: V25NMawla1 | C39: Nesreen Emad-AbdElMawla | D39: Merna Ashraf-Ashrafy | G39: 45984.049 | AJ39: 0.048541667 | AK39: 1.165
A40: 37 | B40: V25MAhmed108 | C40: Mohamed Yasser-Ahmed | D40: Omar Emad-Mahmoud | I40: 45986.002 | K40: 0 | N40: 0 | AJ40: 0.0020601852 | AK40: 0.049444444
...

Sheet Summary
A1: 1 | B1: 2 | C1: 3 | D1: 4 | E1: 5 | F1: 6 | G1: 7 | H1: 8 | I1: 9 | J1: 10 | K1: 11
A2: Team Leader | B2: Attended | C2: Sick | D2: No Show | E2: Annual | F2: Bereavement | G2: UPL | H2: App Issue | I2: Res | J2: OFF | K2: Compensation | L2: Absenteeism%
A3: =IF(PIV!A22="Grand total",0,PIV!A22) -> Mohamed Ahmed-Nagy | B3: =IFERROR(VLOOKUP($A3,PIV!$A:$J,Summary!B$1,0),"-") -> 86 | C3: =IFERROR(VLOOKUP(A:A,PIV!A:F,6,0),"-") -> 0 | D3: =IFERROR(VLOOKUP(A:A,PIV!A:C,3,0),"-") -> 0 | E3: =IFERROR(VLOOKUP(A:A,PIV!A:D,4,0),"-") -> 0 | F3: =IFERROR(VLOOKUP(A:A,PIV!A:E,5,0),"-") -> 0 | G3: =IFERROR(VLOOKUP(A:A,PIV!A:G,7,0),"*") -> 0 | H3: =IFERROR(VLOOKUP($A3,PIV!A:J,10,0),"-") -> 0 | I3: =IFERROR(VLOOKUP(A:A,PIV!A:I,9,0),"-") -> 0 | J3: =IFERROR(VLOOKUP(A:A,PIV!A:K,11,0),"-") -> 6 | K3: =IFERROR(VLOOKUP(A:A,PIV!A:H,8,0),"-") -> 0 | L3: =SUM(D3,F3,H3,C3)/SUM(D3,F3,H3,B3) -> 0
A4: =IF(PIV!A23="Grand total",0,PIV!A23) -> Omar Emad-Mahmoud | B4: =IFERROR(VLOOKUP($A4,PIV!$A:$J,Summary!B$1,0),"-") -> 199 | C4: =IFERROR(VLOOKUP(A:A,PIV!A:F,6,0),"-") -> 0 | D4: =IFERROR(VLOOKUP(A:A,PIV!A:C,3,0),"-") -> 11 | E4: =IFERROR(VLOOKUP(A:A,PIV!A:D,4,0),"-") -> 1 | F4: =IFERROR(VLOOKUP(A:A,PIV!A:E,5,0),"-") -> 0 | G4: =IFERROR(VLOOKUP(A:A,PIV!A:G,7,0),"*") -> 0 | H4: =IFERROR(VLOOKUP($A4,PIV!A:J,10,0),"-") -> 5 | I4: =IFERROR(VLOOKUP(A:A,PIV!A:I,9,0),"-") -> 0 | J4: =IFERROR(VLOOKUP(A:A,PIV!A:K,11,0),"-") -> 69 | K4: =IFERROR(VLOOKUP(A:A,PIV!A:H,8,0),"-") -> 2 | L4: =SUM(D4,F4,H4,C4)/SUM(D4,F4,H4,B4) -> 0.074418605
A5: =IF(PIV!A24="Grand total",0,PIV!A24) -> Merna Ashraf-Ashrafy | B5: =IFERROR(VLOOKUP($A5,PIV!$A:$J,Summary!B$1,0),"-") -> 198 | C5: =IFERROR(VLOOKUP(A:A,PIV!A:F,6,0),"-") -> 0 | D5: =IFERROR(VLOOKUP(A:A,PIV!A:C,3,0),"-") -> 18 | E5: =IFERROR(VLOOKUP(A:A,PIV!A:D,4,0),"-") -> 0 | F5: =IFERROR(VLOOKUP(A:A,PIV!A:E,5,0),"-") -> 0 | G5: =IFERROR(VLOOKUP(A:A,PIV!A:G,7,0),"*") -> 0 | H5: =IFERROR(VLOOKUP($A5,PIV!A:J,10,0),"-") -> 11 | I5: =IFERROR(VLOOKUP(A:A,PIV!A:I,9,0),"-") -> 0 | J5: =IFERROR(VLOOKUP(A:A,PIV!A:K,11,0),"-") -> 83 | K5: =IFERROR(VLOOKUP(A:A,PIV!A:H,8,0),"-") -> 0 | L5: =SUM(D5,F5,H5,C5)/SUM(D5,F5,H5,B5) -> 0.1277533
A6: =IF(PIV!A25="Grand total",0,PIV!A25) -> AbdElRahman Adel-ElKelany | B6: =IFERROR(VLOOKUP($A6,PIV!$A:$J,Summary!B$1,0),"-") -> 191 | C6: =IFERROR(VLOOKUP(A:A,PIV!A:F,6,0),"-") -> 0 | D6: =IFERROR(VLOOKUP(A:A,PIV!A:C,3,0),"-") -> 8 | E6: =IFERROR(VLOOKUP(A:A,PIV!A:D,4,0),"-") -> 0 | F6: =IFERROR(VLOOKUP(A:A,PIV!A:E,5,0),"-") -> 0 | G6: =IFERROR(VLOOKUP(A:A,PIV!A:G,7,0),"*") -> 0 | H6: =IFERROR(VLOOKUP($A6,PIV!A:J,10,0),"-") -> 0 | I6: =IFERROR(VLOOKUP(A:A,PIV!A:I,9,0),"-") -> 0 | J6: =IFERROR(VLOOKUP(A:A,PIV!A:K,11,0),"-") -> 67 | K6: =IFERROR(VLOOKUP(A:A,PIV!A:H,8,0),"-") -> 0 | L6: =SUM(D6,F6,H6,C6)/SUM(D6,F6,H6,B6) -> 0.040201005
A7: =IF(PIV!A26="Grand total",0,PIV!A26) -> 0 | B7: =IFERROR(VLOOKUP($A7,PIV!$A:$J,Summary!B$1,0),"-") -> - | C7: =IFERROR(VLOOKUP(A:A,PIV!A:F,6,0),"-") -> - | D7: =IFERROR(VLOOKUP(A:A,PIV!A:C,3,0),"-") -> - | E7: =IFERROR(VLOOKUP(A:A,PIV!A:D,4,0),"-") -> - | F7: =IFERROR(VLOOKUP(A:A,PIV!A:E,5,0),"-") -> - | G7: =IFERROR(VLOOKUP(A:A,PIV!A:G,7,0),"*") -> * | H7: =IFERROR(VLOOKUP($A7,PIV!A:J,10,0),"-") -> - | I7: =IFERROR(VLOOKUP(A:A,PIV!A:I,9,0),"-") -> - | J7: =IFERROR(VLOOKUP(A:A,PIV!A:K,11,0),"-") -> - | K7: =IFERROR(VLOOKUP(A:A,PIV!A:H,8,0),"-") -> - | L7: =SUM(D7,F7,H7,C7)/SUM(D7,F7,H7,B7) -> #DIV/0!
A8: =IF(PIV!A27="Grand total",0,PIV!A27) -> 0 | B8: =IFERROR(VLOOKUP($A8,PIV!$A:$J,Summary!B$1,0),"-") -> - | C8: =IFERROR(VLOOKUP(A:A,PIV!A:F,6,0),"-") -> - | D8: =IFERROR(VLOOKUP(A:A,PIV!A:C,3,0),"-") -> - | E8: =IFERROR(VLOOKUP(A:A,PIV!A:D,4,0),"-") -> - | F8: =IFERROR(VLOOKUP(A:A,PIV!A:E,5,0),"-") -> - | G8: =IFERROR(VLOOKUP(A:A,PIV!A:G,7,0),"*") -> * | H8: =IFERROR(VLOOKUP($A8,PIV!A:J,10,0),"-") -> - | I8: =IFERROR(VLOOKUP(A:A,PIV!A:I,9,0),"-") -> - | J8: =IFERROR(VLOOKUP(A:A,PIV!A:K,11,0),"-") -> - | K8: =IFERROR(VLOOKUP(A:A,PIV!A:H,8,0),"-") -> - | L8: =SUM(D8,F8,H8,C8)/SUM(D8,F8,H8,B8) -> #DIV/0!
A9: =IF(PIV!A28="Grand total",0,PIV!A28) -> 0 | B9: =IFERROR(VLOOKUP($A9,PIV!$A:$J,Summary!B$1,0),"-") -> - | C9: =IFERROR(VLOOKUP(A:A,PIV!A:F,6,0),"-") -> - | D9: =IFERROR(VLOOKUP(A:A,PIV!A:C,3,0),"-") -> - | E9: =IFERROR(VLOOKUP(A:A,PIV!A:D,4,0),"-") -> - | F9: =IFERROR(VLOOKUP(A:A,PIV!A:E,5,0),"-") -> - | G9: =IFERROR(VLOOKUP(A:A,PIV!A:G,7,0),"*") -> * | H9: =IFERROR(VLOOKUP($A9,PIV!A:J,10,0),"-") -> - | I9: =IFERROR(VLOOKUP(A:A,PIV!A:I,9,0),"-") -> - | J9: =IFERROR(VLOOKUP(A:A,PIV!A:K,11,0),"-") -> - | K9: =IFERROR(VLOOKUP(A:A,PIV!A:H,8,0),"-") -> - | L9: =SUM(D9,F9,H9,C9)/SUM(D9,F9,H9,B9) -> #DIV/0!
A10: Total | B10: =SUM(B3:B9) -> 674 | C10: =SUM(C3:C9) -> 0 | D10: =SUM(D3:D9) -> 37 | E10: =SUM(E3:E9) -> 1 | F10: =SUM(F3:F9) -> 0 | G10: =SUM(G3:G9) -> 0 | H10: =SUM(H3:H9) -> 16 | I10: =SUM(I3:I9) -> 0 | ... K10: =SUM(K3:K9) -> 2 | L10: =SUM(D10,F10,H10,C10)/SUM(D10,F10,H10,B10) -> 0.072902338
A12: Attended | B12: No Show | C12: Annual | D12: Bereavement | E12: Sick | F12: UPL | G12: Compensation | H12: Resignation | I12: App Issue | J12: OFF | K12: Scheduled | L12: Task | M12: Task | N12: Task
A13: Task | F13: Task | G13: Task | H13: Task | I13: Task | J13: Task | K13: Task | L13: Task | M13: Task | N13: Task
F14: Task | G14: Task | H14: Task | I14: Task | J14: Task | K14: Task | L14: Task | M14: Task | N14: Task
F15: Task | G15: Task | H15: Task | I15: Task | J15: Task | K15: Task | L15: Task | M15: Task | N15: Task
A21: Type | B21: =Conformance!E3 -> 45982 | C21: =Conformance!F3 -> 45983 | D21: =Conformance!G3 -> 45984 | E21: =Conformance!H3 -> 45985 | F21: =Conformance!I3 -> 45986 | G21: =Conformance!J3 -> 45987 | H21: =Conformance!K3 -> 45988 | I21: =Conformance!L3 -> 45989 | ... AF21: =Conformance!AI3 -> 46012 | AG21: Total
A22: Attended | B22: =COUNTIF(FL!F:F,Summary!$A$22)+COUNTIF(FL!F:F,$A$13) -> 23 | C22: =COUNTIF(FL!G:G,Summary!$A$22)+COUNTIF(FL!G:G,$A$13) -> 28 | D22: =COUNTIF(FL!H:H,Summary!$A$22)+COUNTIF(FL!H:H,$A$13) -> 30 | E22: =COUNTIF(FL!I:I,Summary!$A$22)+COUNTIF(FL!I:I,$A$13) -> 28 | F22: =COUNTIF(FL!J:J,Summary!$A$22)+COUNTIF(FL!J:J,$A$13) -> 28 | G22: =COUNTIF(FL!K:K,Summary!$A$22)+COUNTIF(FL!K:K,$A$13) -> 31 | H22: =COUNTIF(FL!L:L,Summary!$A$22)+COUNTIF(FL!L:L,$A$13) -> 30 | I22: =COUNTIF(FL!M:M,Summary!$A$22)+COUNTIF(FL!M:M,$A$13) -> 26 | J22: =COUNTIF(FL!N:N,Summary!$A$22)+COUNTIF(FL!N:N,$A$13) -> 28 | K22: =COUNTIF(FL!O:O,Summary!$A$22)+COUNTIF(FL!O:O,$A$13) -> 28 | L22: =COUNTIF(FL!P:P,Summary!$A$22)+COUNTIF(FL!P:P,$A$13) -> 34 | M22: =COUNTIF(FL!Q:Q,Summary!$A$22)+COUNTIF(FL!Q:Q,$A$13) -> 34 | N22: =COUNTIF(FL!R:R,Summary!$A$22)+COUNTIF(FL!R:R,$A$13) -> 32 | O22: =COUNTIF(FL!S:S,Summary!$A$22)+COUNTIF(FL!S:S,$A$13) -> 34 | P22: =COUNTIF(FL!T:T,Summary!$A$22)+COUNTIF(FL!T:T,$A$13) -> 26 | Q22: =COUNTIF(FL!U:U,Summary!$A$22)+COUNTIF(FL!U:U,$A$13) -> 30 | R22: =COUNTIF(FL!V:V,Summary!$A$22)+COUNTIF(FL!V:V,$A$13) -> 33 | S22: =COUNTIF(FL!W:W,Summary!$A$22)+COUNTIF(FL!W:W,$A$13) -> 30 | T22: =COUNTIF(FL!X:X,Summary!$A$22)+COUNTIF(FL!X:X,$A$13) -> 32 | U22: =COUNTIF(FL!Y:Y,Summary!$A$22)+COUNTIF(FL!Y:Y,$A$13) -> 31 | V22: =COUNTIF(FL!Z:Z,Summary!$A$22)+COUNTIF(FL!Z:Z,$A$13) -> 30 | W22: =COUNTIF(FL!AA:AA,Summary!$A$22)+COUNTIF(FL!AA:AA,$A$13) -> 27 | X22: =COUNTIF(FL!AB:AB,Summary!$A$22)+COUNTIF(FL!AB:AB,$A$13) -> 30 | Y22: =COUNTIF(FL!AC:AC,Summary!$A$22)+COUNTIF(FL!AC:AC,$A$13) -> 0 | Z22: =COUNTIF(FL!AD:AD,Summary!$A$22)+COUNTIF(FL!AD:AD,$A$13) -> 0 | AA22: =COUNTIF(FL!AE:AE,Summary!$A$22)+COUNTIF(FL!AE:AE,$A$13) -> 0 | AB22: =COUNTIF(FL!AF:AF,Summary!$A$22)+COUNTIF(FL!AF:AF,$A$13) -> 0 | AC22: =COUNTIF(FL!AG:AG,Summary!$A$22)+COUNTIF(FL!AG:AG,$A$13) -> 0 | AD22: =COUNTIF(FL!AH:AH,Summary!$A$22)+COUNTIF(FL!AH:AH,$A$13) -> 0 | AE22: =COUNTIF(FL!AI:AI,Summary!$A$22)+COUNTIF(FL!AI:AI,$A$13) -> 0 | AF22: =COUNTIF(FL!AJ:AJ,Summary!$A$22)+COUNTIF(FL!AJ:AJ,$A$13) -> 0 | AG22: =SUM(B22:AF22) -> 683
A23: No Show | B23: =COUNTIF(FL!F:F,Summary!$A23) -> 1 | C23: =COUNTIF(FL!G:G,Summary!$A23) -> 0 | D23: =COUNTIF(FL!H:H,Summary!$A23) -> 0 | E23: =COUNTIF(FL!I:I,Summary!$A23) -> 2 | F23: =COUNTIF(FL!J:J,Summary!$A23) -> 2 | G23: =COUNTIF(FL!K:K,Summary!$A23) -> 0 | H23: =COUNTIF(FL!L:L,Summary!$A23) -> 0 | I23: =COUNTIF(FL!M:M,Summary!$A23) -> 1 | J23: =COUNTIF(FL!N:N,Summary!$A23) -> 2 | K23: =COUNTIF(FL!O:O,Summary!$A23) -> 1 | L23: =COUNTIF(FL!P:P,Summary!$A23) -> 0 | M23: =COUNTIF(FL!Q:Q,Summary!$A23) -> 1 | N23: =COUNTIF(FL!R:R,Summary!$A23) -> 1 | O23: =COUNTIF(FL!S:S,Summary!$A23) -> 0 | P23: =COUNTIF(FL!T:T,Summary!$A23) -> 0 | Q23: =COUNTIF(FL!U:U,Summary!$A23) -> 3 | R23: =COUNTIF(FL!V:V,Summary!$A23) -> 2 | S23: =COUNTIF(FL!W:W,Summary!$A23) -> 5 | T23: =COUNTIF(FL!X:X,Summary!$A23) -> 4 | U23: =COUNTIF(FL!Y:Y,Summary!$A23) -> 6 | V23: =COUNTIF(FL!Z:Z,Summary!$A23) -> 4 | W23: =COUNTIF(FL!AA:AA,Summary!$A23) -> 1 | X23: =COUNTIF(FL!AB:AB,Summary!$A23) -> 2 | Y23: =COUNTIF(FL!AC:AC,Summary!$A23) -> 0 | Z23: =COUNTIF(FL!AD:AD,Summary!$A23) -> 0 | AA23: =COUNTIF(FL!AE:AE,Summary!$A23) -> 0 | AB23: =COUNTIF(FL!AF:AF,Summary!$A23) -> 0 | AC23: =COUNTIF(FL!AG:AG,Summary!$A23) -> 0 | AD23: =COUNTIF(FL!AH:AH,Summary!$A23) -> 0 | AE23: =COUNTIF(FL!AI:AI,Summary!$A23) -> 0 | AF23: =COUNTIF(FL!AJ:AJ,Summary!$A23) -> 0 | AG23: =SUM(B23:AF23) -> 38
A24: Annual | B24: =COUNTIF(FL!F:F,Summary!$A24) -> 0 | C24: =COUNTIF(FL!G:G,Summary!$A24) -> 0 | D24: =COUNTIF(FL!H:H,Summary!$A24) -> 0 | E24: =COUNTIF(FL!I:I,Summary!$A24) -> 0 | F24: =COUNTIF(FL!J:J,Summary!$A24) -> 0 | G24: =COUNTIF(FL!K:K,Summary!$A24) -> 1 | H24: =COUNTIF(FL!L:L,Summary!$A24) -> 0 | I24: =COUNTIF(FL!M:M,Summary!$A24) -> 0 | J24: =COUNTIF(FL!N:N,Summary!$A24) -> 0 | K24: =COUNTIF(FL!O:O,Summary!$A24) -> 0 | L24: =COUNTIF(FL!P:P,Summary!$A24) -> 0 | M24: =COUNTIF(FL!Q:Q,Summary!$A24) -> 0 | N24: =COUNTIF(FL!R:R,Summary!$A24) -> 0 | O24: =COUNTIF(FL!S:S,Summary!$A24) -> 0 | P24: =COUNTIF(FL!T:T,Summary!$A24) -> 0 | Q24: =COUNTIF(FL!U:U,Summary!$A24) -> 0 | R24: =COUNTIF(FL!V:V,Summary!$A24) -> 0 | S24: =COUNTIF(FL!W:W,Summary!$A24) -> 0 | T24: =COUNTIF(FL!X:X,Summary!$A24) -> 0 | U24: =COUNTIF(FL!Y:Y,Summary!$A24) -> 0 | V24: =COUNTIF(FL!Z:Z,Summary!$A24) -> 0 | W24: =COUNTIF(FL!AA:AA,Summary!$A24) -> 0 | X24: =COUNTIF(FL!AB:AB,Summary!$A24) -> 0 | Y24: =COUNTIF(FL!AC:AC,Summary!$A24) -> 0 | Z24: =COUNTIF(FL!AD:AD,Summary!$A24) -> 0 | AA24: =COUNTIF(FL!AE:AE,Summary!$A24) -> 0 | AB24: =COUNTIF(FL!AF:AF,Summary!$A24) -> 0 | AC24: =COUNTIF(FL!AG:AG,Summary!$A24) -> 0 | AD24: =COUNTIF(FL!AH:AH,Summary!$A24) -> 0 | AE24: =COUNTIF(FL!AI:AI,Summary!$A24) -> 0 | AF24: =COUNTIF(FL!AJ:AJ,Summary!$A24) -> 0 | AG24: =SUM(B24:AF24) -> 1
A25: Bereavement | B25: =COUNTIF(FL!F:F,Summary!$A25) -> 0 | C25: =COUNTIF(FL!G:G,Summary!$A25) -> 0 | D25: =COUNTIF(FL!H:H,Summary!$A25) -> 0 | E25: =COUNTIF(FL!I:I,Summary!$A25) -> 0 | F25: =COUNTIF(FL!J:J,Summary!$A25) -> 0 | G25: =COUNTIF(FL!K:K,Summary!$A25) -> 0 | H25: =COUNTIF(FL!L:L,Summary!$A25) -> 0 | I25: =COUNTIF(FL!M:M,Summary!$A25) -> 0 | J25: =COUNTIF(FL!N:N,Summary!$A25) -> 0 | K25: =COUNTIF(FL!O:O,Summary!$A25) -> 0 | L25: =COUNTIF(FL!P:P,Summary!$A25) -> 0 | M25: =COUNTIF(FL!Q:Q,Summary!$A25) -> 0 | N25: =COUNTIF(FL!R:R,Summary!$A25) -> 0 | O25: =COUNTIF(FL!S:S,Summary!$A25) -> 0 | P25: =COUNTIF(FL!T:T,Summary!$A25) -> 0 | Q25: =COUNTIF(FL!U:U,Summary!$A25) -> 0 | R25: =COUNTIF(FL!V:V,Summary!$A25) -> 0 | S25: =COUNTIF(FL!W:W,Summary!$A25) -> 0 | T25: =COUNTIF(FL!X:X,Summary!$A25) -> 0 | U25: =COUNTIF(FL!Y:Y,Summary!$A25) -> 0 | V25: =COUNTIF(FL!Z:Z,Summary!$A25) -> 0 | W25: =COUNTIF(FL!AA:AA,Summary!$A25) -> 0 | X25: =COUNTIF(FL!AB:AB,Summary!$A25) -> 0 | Y25: =COUNTIF(FL!AC:AC,Summary!$A25) -> 0 | Z25: =COUNTIF(FL!AD:AD,Summary!$A25) -> 0 | AA25: =COUNTIF(FL!AE:AE,Summary!$A25) -> 0 | AB25: =COUNTIF(FL!AF:AF,Summary!$A25) -> 0 | AC25: =COUNTIF(FL!AG:AG,Summary!$A25) -> 0 | AD25: =COUNTIF(FL!AH:AH,Summary!$A25) -> 0 | AE25: =COUNTIF(FL!AI:AI,Summary!$A25) -> 0 | AF25: =COUNTIF(FL!AJ:AJ,Summary!$A25) -> 0 | AG25: =SUM(B25:AF25) -> 0
A26: Sick | B26: =COUNTIF(FL!F:F,Summary!$A26) -> 0 | C26: =COUNTIF(FL!G:G,Summary!$A26) -> 0 | D26: =COUNTIF(FL!H:H,Summary!$A26) -> 0 | E26: =COUNTIF(FL!I:I,Summary!$A26) -> 0 | F26: =COUNTIF(FL!J:J,Summary!$A26) -> 0 | G26: =COUNTIF(FL!K:K,Summary!$A26) -> 0 | H26: =COUNTIF(FL!L:L,Summary!$A26) -> 0 | I26: =COUNTIF(FL!M:M,Summary!$A26) -> 0 | J26: =COUNTIF(FL!N:N,Summary!$A26) -> 0 | K26: =COUNTIF(FL!O:O,Summary!$A26) -> 0 | L26: =COUNTIF(FL!P:P,Summary!$A26) -> 0 | M26: =COUNTIF(FL!Q:Q,Summary!$A26) -> 0 | N26: =COUNTIF(FL!R:R,Summary!$A26) -> 0 | O26: =COUNTIF(FL!S:S,Summary!$A26) -> 0 | P26: =COUNTIF(FL!T:T,Summary!$A26) -> 0 | Q26: =COUNTIF(FL!U:U,Summary!$A26) -> 0 | R26: =COUNTIF(FL!V:V,Summary!$A26) -> 0 | S26: =COUNTIF(FL!W:W,Summary!$A26) -> 0 | T26: =COUNTIF(FL!X:X,Summary!$A26) -> 0 | U26: =COUNTIF(FL!Y:Y,Summary!$A26) -> 0 | V26: =COUNTIF(FL!Z:Z,Summary!$A26) -> 0 | W26: =COUNTIF(FL!AA:AA,Summary!$A26) -> 0 | X26: =COUNTIF(FL!AB:AB,Summary!$A26) -> 0 | Y26: =COUNTIF(FL!AC:AC,Summary!$A26) -> 0 | Z26: =COUNTIF(FL!AD:AD,Summary!$A26) -> 0 | AA26: =COUNTIF(FL!AE:AE,Summary!$A26) -> 0 | AB26: =COUNTIF(FL!AF:AF,Summary!$A26) -> 0 | AC26: =COUNTIF(FL!AG:AG,Summary!$A26) -> 0 | AD26: =COUNTIF(FL!AH:AH,Summary!$A26) -> 0 | AE26: =COUNTIF(FL!AI:AI,Summary!$A26) -> 0 | AF26: =COUNTIF(FL!AJ:AJ,Summary!$A26) -> 0 | AG26: =SUM(B26:AF26) -> 0
A27: UPL | B27: =COUNTIF(FL!F:F,Summary!$A27) -> 0 | C27: =COUNTIF(FL!G:G,Summary!$A27) -> 0 | D27: =COUNTIF(FL!H:H,Summary!$A27) -> 0 | E27: =COUNTIF(FL!I:I,Summary!$A27) -> 0 | F27: =COUNTIF(FL!J:J,Summary!$A27) -> 0 | G27: =COUNTIF(FL!K:K,Summary!$A27) -> 0 | H27: =COUNTIF(FL!L:L,Summary!$A27) -> 0 | I27: =COUNTIF(FL!M:M,Summary!$A27) -> 0 | J27: =COUNTIF(FL!N:N,Summary!$A27) -> 0 | K27: =COUNTIF(FL!O:O,Summary!$A27) -> 0 | L27: =COUNTIF(FL!P:P,Summary!$A27) -> 0 | M27: =COUNTIF(FL!Q:Q,Summary!$A27) -> 0 | N27: =COUNTIF(FL!R:R,Summary!$A27) -> 0 | O27: =COUNTIF(FL!S:S,Summary!$A27) -> 0 | P27: =COUNTIF(FL!T:T,Summary!$A27) -> 0 | Q27: =COUNTIF(FL!U:U,Summary!$A27) -> 0 | R27: =COUNTIF(FL!V:V,Summary!$A27) -> 0 | S27: =COUNTIF(FL!W:W,Summary!$A27) -> 0 | T27: =COUNTIF(FL!X:X,Summary!$A27) -> 0 | U27: =COUNTIF(FL!Y:Y,Summary!$A27) -> 0 | V27: =COUNTIF(FL!Z:Z,Summary!$A27) -> 0 | W27: =COUNTIF(FL!AA:AA,Summary!$A27) -> 0 | X27: =COUNTIF(FL!AB:AB,Summary!$A27) -> 0 | Y27: =COUNTIF(FL!AC:AC,Summary!$A27) -> 0 | Z27: =COUNTIF(FL!AD:AD,Summary!$A27) -> 0 | AA27: =COUNTIF(FL!AE:AE,Summary!$A27) -> 0 | AB27: =COUNTIF(FL!AF:AF,Summary!$A27) -> 0 | AC27: =COUNTIF(FL!AG:AG,Summary!$A27) -> 0 | AD27: =COUNTIF(FL!AH:AH,Summary!$A27) -> 0 | AE27: =COUNTIF(FL!AI:AI,Summary!$A27) -> 0 | AF27: =COUNTIF(FL!AJ:AJ,Summary!$A27) -> 0 | AG27: =SUM(B27:AF27) -> 0
A28: Compensation | B28: =COUNTIF(FL!F:F,Summary!$A28) -> 0 | C28: =COUNTIF(FL!G:G,Summary!$A28) -> 0 | D28: =COUNTIF(FL!H:H,Summary!$A28) -> 0 | E28: =COUNTIF(FL!I:I,Summary!$A28) -> 0 | F28: =COUNTIF(FL!J:J,Summary!$A28) -> 0 | G28: =COUNTIF(FL!K:K,Summary!$A28) -> 0 | H28: =COUNTIF(FL!L:L,Summary!$A28) -> 0 | I28: =COUNTIF(FL!M:M,Summary!$A28) -> 0 | J28: =COUNTIF(FL!N:N,Summary!$A28) -> 0 | K28: =COUNTIF(FL!O:O,Summary!$A28) -> 1 | L28: =COUNTIF(FL!P:P,Summary!$A28) -> 0 | M28: =COUNTIF(FL!Q:Q,Summary!$A28) -> 0 | N28: =COUNTIF(FL!R:R,Summary!$A28) -> 1 | O28: =COUNTIF(FL!S:S,Summary!$A28) -> 0 | P28: =COUNTIF(FL!T:T,Summary!$A28) -> 0 | Q28: =COUNTIF(FL!U:U,Summary!$A28) -> 0 | R28: =COUNTIF(FL!V:V,Summary!$A28) -> 0 | S28: =COUNTIF(FL!W:W,Summary!$A28) -> 0 | T28: =COUNTIF(FL!X:X,Summary!$A28) -> 0 | U28: =COUNTIF(FL!Y:Y,Summary!$A28) -> 0 | V28: =COUNTIF(FL!Z:Z,Summary!$A28) -> 0 | W28: =COUNTIF(FL!AA:AA,Summary!$A28) -> 0 | X28: =COUNTIF(FL!AB:AB,Summary!$A28) -> 0 | Y28: =COUNTIF(FL!AC:AC,Summary!$A28) -> 0 | Z28: =COUNTIF(FL!AD:AD,Summary!$A28) -> 0 | AA28: =COUNTIF(FL!AE:AE,Summary!$A28) -> 0 | AB28: =COUNTIF(FL!AF:AF,Summary!$A28) -> 0 | AC28: =COUNTIF(FL!AG:AG,Summary!$A28) -> 0 | AD28: =COUNTIF(FL!AH:AH,Summary!$A28) -> 0 | AE28: =COUNTIF(FL!AI:AI,Summary!$A28) -> 0 | AF28: =COUNTIF(FL!AJ:AJ,Summary!$A28) -> 0 | AG28: =SUM(B28:AF28) -> 2
A29: Resignation | B29: =COUNTIF(FL!F:F,Summary!$A29) -> 0 | C29: =COUNTIF(FL!G:G,Summary!$A29) -> 0 | D29: =COUNTIF(FL!H:H,Summary!$A29) -> 0 | E29: =COUNTIF(FL!I:I,Summary!$A29) -> 0 | F29: =COUNTIF(FL!J:J,Summary!$A29) -> 0 | G29: =COUNTIF(FL!K:K,Summary!$A29) -> 0 | H29: =COUNTIF(FL!L:L,Summary!$A29) -> 0 | I29: =COUNTIF(FL!M:M,Summary!$A29) -> 0 | J29: =COUNTIF(FL!N:N,Summary!$A29) -> 0 | K29: =COUNTIF(FL!O:O,Summary!$A29) -> 0 | L29: =COUNTIF(FL!P:P,Summary!$A29) -> 0 | M29: =COUNTIF(FL!Q:Q,Summary!$A29) -> 1 | N29: =COUNTIF(FL!R:R,Summary!$A29) -> 2 | O29: =COUNTIF(FL!S:S,Summary!$A29) -> 2 | P29: =COUNTIF(FL!T:T,Summary!$A29) -> 2 | Q29: =COUNTIF(FL!U:U,Summary!$A29) -> 2 | R29: =COUNTIF(FL!V:V,Summary!$A29) -> 2 | S29: =COUNTIF(FL!W:W,Summary!$A29) -> 2 | T29: =COUNTIF(FL!X:X,Summary!$A29) -> 2 | U29: =COUNTIF(FL!Y:Y,Summary!$A29) -> 2 | V29: =COUNTIF(FL!Z:Z,Summary!$A29) -> 2 | W29: =COUNTIF(FL!AA:AA,Summary!$A29) -> 2 | X29: =COUNTIF(FL!AB:AB,Summary!$A29) -> 2 | Y29: =COUNTIF(FL!AC:AC,Summary!$A29) -> 0 | Z29: =COUNTIF(FL!AD:AD,Summary!$A29) -> 0 | AA29: =COUNTIF(FL!AE:AE,Summary!$A29) -> 0 | AB29: =COUNTIF(FL!AF:AF,Summary!$A29) -> 0 | AC29: =COUNTIF(FL!AG:AG,Summary!$A29) -> 0 | AD29: =COUNTIF(FL!AH:AH,Summary!$A29) -> 0 | AE29: =COUNTIF(FL!AI:AI,Summary!$A29) -> 0 | AF29: =COUNTIF(FL!AJ:AJ,Summary!$A29) -> 0 | AG29: =SUM(B29:AF29) -> 23
A30: App Issue | B30: =COUNTIF(FL!F:F,Summary!$A30) -> 0 | C30: =COUNTIF(FL!G:G,Summary!$A30) -> 0 | D30: =COUNTIF(FL!H:H,Summary!$A30) -> 0 | E30: =COUNTIF(FL!I:I,Summary!$A30) -> 0 | F30: =COUNTIF(FL!J:J,Summary!$A30) -> 0 | G30: =COUNTIF(FL!K:K,Summary!$A30) -> 0 | H30: =COUNTIF(FL!L:L,Summary!$A30) -> 0 | I30: =COUNTIF(FL!M:M,Summary!$A30) -> 0 | J30: =COUNTIF(FL!N:N,Summary!$A30) -> 0 | K30: =COUNTIF(FL!O:O,Summary!$A30) -> 0 | L30: =COUNTIF(FL!P:P,Summary!$A30) -> 0 | M30: =COUNTIF(FL!Q:Q,Summary!$A30) -> 0 | N30: =COUNTIF(FL!R:R,Summary!$A30) -> 2 | O30: =COUNTIF(FL!S:S,Summary!$A30) -> 2 | P30: =COUNTIF(FL!T:T,Summary!$A30) -> 2 | Q30: =COUNTIF(FL!U:U,Summary!$A30) -> 2 | R30: =COUNTIF(FL!V:V,Summary!$A30) -> 2 | S30: =COUNTIF(FL!W:W,Summary!$A30) -> 1 | T30: =COUNTIF(FL!X:X,Summary!$A30) -> 1 | U30: =COUNTIF(FL!Y:Y,Summary!$A30) -> 1 | V30: =COUNTIF(FL!Z:Z,Summary!$A30) -> 1 | W30: =COUNTIF(FL!AA:AA,Summary!$A30) -> 1 | X30: =COUNTIF(FL!AB:AB,Summary!$A30) -> 1 | Y30: =COUNTIF(FL!AC:AC,Summary!$A30) -> 0 | Z30: =COUNTIF(FL!AD:AD,Summary!$A30) -> 0 | AA30: =COUNTIF(FL!AE:AE,Summary!$A30) -> 0 | AB30: =COUNTIF(FL!AF:AF,Summary!$A30) -> 0 | AC30: =COUNTIF(FL!AG:AG,Summary!$A30) -> 0 | AD30: =COUNTIF(FL!AH:AH,Summary!$A30) -> 0 | AE30: =COUNTIF(FL!AI:AI,Summary!$A30) -> 0 | AF30: =COUNTIF(FL!AJ:AJ,Summary!$A30) -> 0 | AG30: =SUM(B30:AF30) -> 16
A31: OFF | B31: =COUNTIF(FL!F:F,Summary!$A31) -> 14 | C31: =COUNTIF(FL!G:G,Summary!$A31) -> 10 | D31: =COUNTIF(FL!H:H,Summary!$A31) -> 8 | E31: =COUNTIF(FL!I:I,Summary!$A31) -> 8 | F31: =COUNTIF(FL!J:J,Summary!$A31) -> 8 | G31: =COUNTIF(FL!K:K,Summary!$A31) -> 6 | H31: =COUNTIF(FL!L:L,Summary!$A31) -> 8 | I31: =COUNTIF(FL!M:M,Summary!$A31) -> 11 | J31: =COUNTIF(FL!N:N,Summary!$A31) -> 8 | K31: =COUNTIF(FL!O:O,Summary!$A31) -> 8 | L31: =COUNTIF(FL!P:P,Summary!$A31) -> 4 | M31: =COUNTIF(FL!Q:Q,Summary!$A31) -> 9 | N31: =COUNTIF(FL!R:R,Summary!$A31) -> 10 | O31: =COUNTIF(FL!S:S,Summary!$A31) -> 10 | P31: =COUNTIF(FL!T:T,Summary!$A31) -> 18 | Q31: =COUNTIF(FL!U:U,Summary!$A31) -> 11 | R31: =COUNTIF(FL!V:V,Summary!$A31) -> 9 | S31: =COUNTIF(FL!W:W,Summary!$A31) -> 9 | T31: =COUNTIF(FL!X:X,Summary!$A31) -> 9 | U31: =COUNTIF(FL!Y:Y,Summary!$A31) -> 8 | V31: =COUNTIF(FL!Z:Z,Summary!$A31) -> 11 | W31: =COUNTIF(FL!AA:AA,Summary!$A31) -> 17 | X31: =COUNTIF(FL!AB:AB,Summary!$A31) -> 13 | Y31: =COUNTIF(FL!AC:AC,Summary!$A31) -> 0 | Z31: =COUNTIF(FL!AD:AD,Summary!$A31) -> 0 | AA31: =COUNTIF(FL!AE:AE,Summary!$A31) -> 0 | AB31: =COUNTIF(FL!AF:AF,Summary!$A31) -> 0 | AC31: =COUNTIF(FL!AG:AG,Summary!$A31) -> 0 | AD31: =COUNTIF(FL!AH:AH,Summary!$A31) -> 0 | AE31: =COUNTIF(FL!AI:AI,Summary!$A31) -> 0 | AF31: =COUNTIF(FL!AJ:AJ,Summary!$A31) -> 0 | AG31: =SUM(B31:AF31) -> 227
A32: Scheduled | B32: =COUNTIF(FL!F:F,Summary!$A32) -> 0 | C32: =COUNTIF(FL!G:G,Summary!$A32) -> 0 | D32: =COUNTIF(FL!H:H,Summary!$A32) -> 0 | E32: =COUNTIF(FL!I:I,Summary!$A32) -> 0 | F32: =COUNTIF(FL!J:J,Summary!$A32) -> 0 | G32: =COUNTIF(FL!K:K,Summary!$A32) -> 0 | H32: =COUNTIF(FL!L:L,Summary!$A32) -> 0 | I32: =COUNTIF(FL!M:M,Summary!$A32) -> 0 | J32: =COUNTIF(FL!N:N,Summary!$A32) -> 0 | K32: =COUNTIF(FL!O:O,Summary!$A32) -> 0 | L32: =COUNTIF(FL!P:P,Summary!$A32) -> 0 | M32: =COUNTIF(FL!Q:Q,Summary!$A32) -> 0 | N32: =COUNTIF(FL!R:R,Summary!$A32) -> 0 | O32: =COUNTIF(FL!S:S,Summary!$A32) -> 0 | P32: =COUNTIF(FL!T:T,Summary!$A32) -> 0 | Q32: =COUNTIF(FL!U:U,Summary!$A32) -> 0 | R32: =COUNTIF(FL!V:V,Summary!$A32) -> 0 | S32: =COUNTIF(FL!W:W,Summary!$A32) -> 0 | T32: =COUNTIF(FL!X:X,Summary!$A32) -> 0 | U32: =COUNTIF(FL!Y:Y,Summary!$A32) -> 0 | V32: =COUNTIF(FL!Z:Z,Summary!$A32) -> 0 | W32: =COUNTIF(FL!AA:AA,Summary!$A32) -> 0 | X32: =COUNTIF(FL!AB:AB,Summary!$A32) -> 0 | Y32: =COUNTIF(FL!AC:AC,Summary!$A32) -> 0 | Z32: =COUNTIF(FL!AD:AD,Summary!$A32) -> 0 | AA32: =COUNTIF(FL!AE:AE,Summary!$A32) -> 0 | AB32: =COUNTIF(FL!AF:AF,Summary!$A32) -> 0 | AC32: =COUNTIF(FL!AG:AG,Summary!$A32) -> 0 | AD32: =COUNTIF(FL!AH:AH,Summary!$A32) -> 0 | AE32: =COUNTIF(FL!AI:AI,Summary!$A32) -> 0 | AF32: =COUNTIF(FL!AJ:AJ,Summary!$A32) -> 0 | AG32: =SUM(AG22:AG31) -> 990
A33: Absenteeism% | B33: =SUM(B23,B25,B30)/SUM(B23,B25,B30,B22) -> 0.041666667 | C33: =SUM(C23,C25,C30)/SUM(C23,C25,C30,C22) -> 0 | D33: =SUM(D23,D25,D30)/SUM(D23,D25,D30,D22) -> 0 | E33: =SUM(E23,E25,E30)/SUM(E23,E25,E30,E22) -> 0.066666667 | F33: =SUM(F23,F25,F30)/SUM(F23,F25,F30,F22) -> 0.066666667 | G33: =SUM(G23,G25,G30)/SUM(G23,G25,G30,G22) -> 0 | H33: =SUM(H23,H25,H30)/SUM(H23,H25,H30,H22) -> 0 | I33: =SUM(I23,I25,I30)/SUM(I23,I25,I30,I22) -> 0.037037037 | ... AG33: =SUM(AG23,AG25,AG30)/SUM(AG23,AG25,AG30,AG22) -> 0.073270014
A41: SPV | B41: Attended | C41: Sick | D41: No Show | E41: Annual | F41: Bereavement | G41: UPL | H41: App Issue | I41: Res | J41: OFF | K41: Compensation | L41: Absenteeism%
A42: Kareem Mohamed-AbdElMetaal | B42: =VLOOKUP(A42,PIV!A43:B48,2,0) -> #N/A | C42: =VLOOKUP(A42,PIV!A41:F48,6,0) -> #N/A | D42: =VLOOKUP(A42,PIV!A41:C48,3,0) -> #N/A | E42: =VLOOKUP(A42,PIV!A41:D48,4,0) -> #N/A | F42: =VLOOKUP(A42,PIV!A41:E48,5,0) -> #N/A | G42: =VLOOKUP(A42,PIV!A41:G48,7,0) -> #N/A | H42: =VLOOKUP(A42,PIV!A41:J48,10,0) -> #N/A | I42: =VLOOKUP(A42,PIV!A41:I48,9,0) -> #N/A | J42: =VLOOKUP(A42,PIV!A41:K48,11,0) -> #N/A | K42: =VLOOKUP(A:A,PIV!A:L,8,0) -> #N/A | L42: =SUM(D42,F42,H42,C42)/SUM(D42,F42,H42,B42) -> #N/A
A43: Ahmed Hamed-Mohamed | B43: =VLOOKUP(A43,PIV!A44:B49,2,0) -> #N/A | C43: =VLOOKUP(A43,PIV!A42:F49,6,0) -> #N/A | D43: =VLOOKUP(A43,PIV!A42:C49,3,0) -> #N/A | E43: =VLOOKUP(A43,PIV!A42:D49,4,0) -> #N/A | F43: =VLOOKUP(A43,PIV!A42:E49,5,0) -> #N/A | G43: =VLOOKUP(A43,PIV!A42:G49,7,0) -> #N/A | H43: =VLOOKUP(A43,PIV!A42:J49,10,0) -> #N/A | I43: =VLOOKUP(A43,PIV!A42:I49,9,0) -> #N/A | J43: =VLOOKUP(A43,PIV!A42:K49,11,0) -> #N/A | K43: =VLOOKUP(A:A,PIV!A:L,8,0) -> #N/A | L43: =SUM(D43,F43,H43,C43)/SUM(D43,F43,H43,B43) -> #N/A
A44: Desouky Ramadan-Mohamed | B44: =VLOOKUP(A44,PIV!A45:B50,2,0) -> #N/A | C44: =VLOOKUP(A44,PIV!A43:F50,6,0) -> #N/A | D44: =VLOOKUP(A44,PIV!A43:C50,3,0) -> #N/A | E44: =VLOOKUP(A44,PIV!A43:D50,4,0) -> #N/A | F44: =VLOOKUP(A44,PIV!A43:E50,5,0) -> #N/A | G44: =VLOOKUP(A44,PIV!A43:G50,7,0) -> #N/A | H44: =VLOOKUP(A44,PIV!A43:J50,10,0) -> #N/A | I44: =VLOOKUP(A44,PIV!A43:I50,9,0) -> #N/A | J44: =VLOOKUP(A44,PIV!A43:K50,11,0) -> #N/A | K44: =VLOOKUP(A:A,PIV!A:L,8,0) -> #N/A | L44: =SUM(D44,F44,H44,C44)/SUM(D44,F44,H44,B44) -> #N/A
A45: Total | B45: =SUM(B42:B42) -> #N/A | C45: =SUM(C42:C42) -> #N/A | D45: =SUM(D42:D42) -> #N/A | E45: =SUM(E42:E42) -> #N/A | F45: =SUM(F42:F42) -> #N/A | G45: =SUM(G42:G42) -> #N/A | H45: =SUM(H42:H42) -> #N/A | I45: =SUM(I42:I42) -> #N/A | ... K45: =SUM(K42:K42) -> #N/A | L45: =SUM(D45,F45,H45,C45)/SUM(D45,F45,H45,B45) -> #N/A

Sheet Total
A1: Monthly Conformance Tracker | F1: =MATCH(F$2,FL!$B$3:$AV$3,0) -> 36 | G1: =MATCH(G$2,FL!$B$3:$AV$3,0) -> 37 | H1: =MATCH(H$2,FL!$B$3:$AV$3,0) -> 38 | I1: =MATCH(I$2,FL!$B$3:$AV$3,0) -> 39 | J1: =MATCH(J$2,FL!$B$3:$AV$3,0) -> 40 | K1: =MATCH(K$2,FL!$B$3:$AV$3,0) -> 41 | L1: =MATCH(L$2,FL!$B$3:$AV$3,0) -> 42 | M1: =MATCH(M$2,FL!$B$3:$AV$3,0) -> 43 | ... Q1: =MATCH(Q$2,FL!$B$3:$AV$3,0) -> 47 | R1: =MATCH("Missing",Conformance!B3:AJ3,0) -> 35
A2: 0 | B2: Username | C2: Displayname | D2: Leader | E2: SPV | F2: Attended | G2: No Show | H2: Annual | I2: Bereavement | J2: Sick | K2: UPL | L2: Compensation | M2: Resignation | N2: App Issue | O2: OFF | P2: Suspension | Q2: Training | R2: Conformance Per H | S2: Conformance Per D
A3: =A2+1 -> 1 | B3: =IF(FL!B4="","",FL!B4) -> V22HRassoul | C3: =IF(FL!C4="","",FL!C4) -> Hend Yousry-AbdElRassoul | D3: =IF(FL!D4="","",FL!D4) -> Mohamed Ahmed-Nagy | E3: =IF(FL!E4="","",FL!E4) -> Mohamed Ahmed-Nagy | F3: =VLOOKUP($B:$B,FL!$B:$AV,Total!F$1,0) -> 23 | G3: =VLOOKUP($B:$B,FL!$B:$AV,Total!G$1,0) -> 0 | H3: =VLOOKUP($B:$B,FL!$B:$AV,Total!H$1,0) -> 0 | I3: =VLOOKUP($B:$B,FL!$B:$AV,Total!I$1,0) -> 0 | J3: =VLOOKUP($B:$B,FL!$B:$AV,Total!J$1,0) -> 0 | K3: =VLOOKUP($B:$B,FL!$B:$AV,Total!K$1,0) -> 0 | L3: =VLOOKUP($B:$B,FL!$B:$AV,Total!L$1,0) -> 0 | M3: =VLOOKUP($B:$B,FL!$B:$AV,Total!M$1,0) -> 0 | ... Q3: =VLOOKUP($B:$B,FL!$B:$AV,Total!Q$1,0) -> 0 | R3: =VLOOKUP(B:B,Conformance!$B$3:$AJ$37,Total!$R$1,0) -> 0 | S3: =IF((R3*24)>12,3,IF((R3*24)>6,2,IF((R3*24)>2,1,0))) -> 0
A4: =A3+1 -> 2 | B4: =IF(FL!B5="","",FL!B5) -> V23MGelil | C4: =IF(FL!C5="","",FL!C5) -> Mohamed Ali-AbdElGelil | D4: =IF(FL!D5="","",FL!D5) -> Omar Emad-Mahmoud | E4: =IF(FL!E5="","",FL!E5) -> Mohamed Ahmed-Nagy | F4: =VLOOKUP($B:$B,FL!$B:$AV,Total!F$1,0) -> 15 | G4: =VLOOKUP($B:$B,FL!$B:$AV,Total!G$1,0) -> 2 | H4: =VLOOKUP($B:$B,FL!$B:$AV,Total!H$1,0) -> 0 | I4: =VLOOKUP($B:$B,FL!$B:$AV,Total!I$1,0) -> 0 | J4: =VLOOKUP($B:$B,FL!$B:$AV,Total!J$1,0) -> 0 | K4: =VLOOKUP($B:$B,FL!$B:$AV,Total!K$1,0) -> 0 | L4: =VLOOKUP($B:$B,FL!$B:$AV,Total!L$1,0) -> 1 | M4: =VLOOKUP($B:$B,FL!$B:$AV,Total!M$1,0) -> 0 | ... Q4: =VLOOKUP($B:$B,FL!$B:$AV,Total!Q$1,0) -> 0 | R4: =VLOOKUP(B:B,Conformance!$B$3:$AJ$37,Total!$R$1,0) -> 0.17423611 | S4: =IF((R4*24)>12,3,IF((R4*24)>6,2,IF((R4*24)>2,1,0))) -> 1
A5: =A4+1 -> 3 | B5: =IF(FL!B6="","",FL!B6) -> V24OMahmoud | C5: =IF(FL!C6="","",FL!C6) -> Omar Emad-Mahmoud | D5: =IF(FL!D6="","",FL!D6) -> Mohamed Ahmed-Nagy | E5: =IF(FL!E6="","",FL!E6) -> Mohamed Ahmed-Nagy | F5: =VLOOKUP($B:$B,FL!$B:$AV,Total!F$1,0) -> 19 | G5: =VLOOKUP($B:$B,FL!$B:$AV,Total!G$1,0) -> 0 | H5: =VLOOKUP($B:$B,FL!$B:$AV,Total!H$1,0) -> 0 | I5: =VLOOKUP($B:$B,FL!$B:$AV,Total!I$1,0) -> 0 | J5: =VLOOKUP($B:$B,FL!$B:$AV,Total!J$1,0) -> 0 | K5: =VLOOKUP($B:$B,FL!$B:$AV,Total!K$1,0) -> 0 | L5: =VLOOKUP($B:$B,FL!$B:$AV,Total!L$1,0) -> 0 | M5: =VLOOKUP($B:$B,FL!$B:$AV,Total!M$1,0) -> 0 | ... Q5: =VLOOKUP($B:$B,FL!$B:$AV,Total!Q$1,0) -> 0 | R5: =VLOOKUP(B:B,Conformance!$B$3:$AJ$37,Total!$R$1,0) -> 0.23565972 | S5: =IF((R5*24)>12,3,IF((R5*24)>6,2,IF((R5*24)>2,1,0))) -> 1
A6: =A5+1 -> 4 | B6: =IF(FL!B7="","",FL!B7) -> V24AHassan6 | C6: =IF(FL!C7="","",FL!C7) -> Aya Mohamed-Hassan | D6: =IF(FL!D7="","",FL!D7) -> Merna Ashraf-Ashrafy | E6: =IF(FL!E7="","",FL!E7) -> Mohamed Ahmed-Nagy | F6: =VLOOKUP($B:$B,FL!$B:$AV,Total!F$1,0) -> 15 | G6: =VLOOKUP($B:$B,FL!$B:$AV,Total!G$1,0) -> 0 | H6: =VLOOKUP($B:$B,FL!$B:$AV,Total!H$1,0) -> 0 | I6: =VLOOKUP($B:$B,FL!$B:$AV,Total!I$1,0) -> 0 | J6: =VLOOKUP($B:$B,FL!$B:$AV,Total!J$1,0) -> 0 | K6: =VLOOKUP($B:$B,FL!$B:$AV,Total!K$1,0) -> 0 | L6: =VLOOKUP($B:$B,FL!$B:$AV,Total!L$1,0) -> 0 | M6: =VLOOKUP($B:$B,FL!$B:$AV,Total!M$1,0) -> 0 | ... Q6: =VLOOKUP($B:$B,FL!$B:$AV,Total!Q$1,0) -> 0 | R6: =VLOOKUP(B:B,Conformance!$B$3:$AJ$37,Total!$R$1,0) -> 0 | S6: =IF((R6*24)>12,3,IF((R6*24)>6,2,IF((R6*24)>2,1,0))) -> 0
A7: =A6+1 -> 5 | B7: =IF(FL!B8="","",FL!B8) -> V22MAshrafy | C7: =IF(FL!C8="","",FL!C8) -> Merna Ashraf-Ashrafy | D7: =IF(FL!D8="","",FL!D8) -> Mohamed Ahmed-Nagy | E7: =IF(FL!E8="","",FL!E8) -> Mohamed Ahmed-Nagy | F7: =VLOOKUP($B:$B,FL!$B:$AV,Total!F$1,0) -> 23 | G7: =VLOOKUP($B:$B,FL!$B:$AV,Total!G$1,0) -> 0 | H7: =VLOOKUP($B:$B,FL!$B:$AV,Total!H$1,0) -> 0 | I7: =VLOOKUP($B:$B,FL!$B:$AV,Total!I$1,0) -> 0 | J7: =VLOOKUP($B:$B,FL!$B:$AV,Total!J$1,0) -> 0 | K7: =VLOOKUP($B:$B,FL!$B:$AV,Total!K$1,0) -> 0 | L7: =VLOOKUP($B:$B,FL!$B:$AV,Total!L$1,0) -> 0 | M7: =VLOOKUP($B:$B,FL!$B:$AV,Total!M$1,0) -> 0 | ... Q7: =VLOOKUP($B:$B,FL!$B:$AV,Total!Q$1,0) -> 0 | R7: =VLOOKUP(B:B,Conformance!$B$3:$AJ$37,Total!$R$1,0) -> 0 | S7: =IF((R7*24)>12,3,IF((R7*24)>6,2,IF((R7*24)>2,1,0))) -> 0
A8: =A7+1 -> 6 | B8: =IF(FL!B9="","",FL!B9) -> V24SAhmed28 | C8: =IF(FL!C9="","",FL!C9) -> Salma Taha-Ahmed | D8: =IF(FL!D9="","",FL!D9) -> Merna Ashraf-Ashrafy | E8: =IF(FL!E9="","",FL!E9) -> Mohamed Ahmed-Nagy | F8: =VLOOKUP($B:$B,FL!$B:$AV,Total!F$1,0) -> 9 | G8: =VLOOKUP($B:$B,FL!$B:$AV,Total!G$1,0) -> 7 | H8: =VLOOKUP($B:$B,FL!$B:$AV,Total!H$1,0) -> 0 | I8: =VLOOKUP($B:$B,FL!$B:$AV,Total!I$1,0) -> 0 | J8: =VLOOKUP($B:$B,FL!$B:$AV,Total!J$1,0) -> 0 | K8: =VLOOKUP($B:$B,FL!$B:$AV,Total!K$1,0) -> 0 | L8: =VLOOKUP($B:$B,FL!$B:$AV,Total!L$1,0) -> 0 | M8: =VLOOKUP($B:$B,FL!$B:$AV,Total!M$1,0) -> 0 | ... Q8: =VLOOKUP($B:$B,FL!$B:$AV,Total!Q$1,0) -> 0 | R8: =VLOOKUP(B:B,Conformance!$B$3:$AJ$37,Total!$R$1,0) -> 0.0083796296 | S8: =IF((R8*24)>12,3,IF((R8*24)>6,2,IF((R8*24)>2,1,0))) -> 0
A9: =A8+1 -> 7 | B9: =IF(FL!B10="","",FL!B10) -> V24AKelany | C9: =IF(FL!C10="","",FL!C10) -> AbdElRahman Adel-ElKelany | D9: =IF(FL!D10="","",FL!D10) -> Mohamed Ahmed-Nagy | E9: =IF(FL!E10="","",FL!E10) -> Mohamed Ahmed-Nagy | F9: =VLOOKUP($B:$B,FL!$B:$AV,Total!F$1,0) -> 21 | G9: =VLOOKUP($B:$B,FL!$B:$AV,Total!G$1,0) -> 0 | H9: =VLOOKUP($B:$B,FL!$B:$AV,Total!H$1,0) -> 0 | I9: =VLOOKUP($B:$B,FL!$B:$AV,Total!I$1,0) -> 0 | J9: =VLOOKUP($B:$B,FL!$B:$AV,Total!J$1,0) -> 0 | K9: =VLOOKUP($B:$B,FL!$B:$AV,Total!K$1,0) -> 0 | L9: =VLOOKUP($B:$B,FL!$B:$AV,Total!L$1,0) -> 0 | M9: =VLOOKUP($B:$B,FL!$B:$AV,Total!M$1,0) -> 0 | ... Q9: =VLOOKUP($B:$B,FL!$B:$AV,Total!Q$1,0) -> 0 | R9: =VLOOKUP(B:B,Conformance!$B$3:$AJ$37,Total!$R$1,0) -> 2.3148148e-05 | S9: =IF((R9*24)>12,3,IF((R9*24)>6,2,IF((R9*24)>2,1,0))) -> 0
A10: =A9+1 -> 8 | B10: =IF(FL!B11="","",FL!B11) -> V24OSamea | C10: =IF(FL!C11="","",FL!C11) -> Omnia Salah-AbdElSamea | D10: =IF(FL!D11="","",FL!D11) -> Merna Ashraf-Ashrafy | E10: =IF(FL!E11="","",FL!E11) -> Mohamed Ahmed-Nagy | F10: =VLOOKUP($B:$B,FL!$B:$AV,Total!F$1,0) -> 13 | G10: =VLOOKUP($B:$B,FL!$B:$AV,Total!G$1,0) -> 3 | H10: =VLOOKUP($B:$B,FL!$B:$AV,Total!H$1,0) -> 0 | I10: =VLOOKUP($B:$B,FL!$B:$AV,Total!I$1,0) -> 0 | J10: =VLOOKUP($B:$B,FL!$B:$AV,Total!J$1,0) -> 0 | K10: =VLOOKUP($B:$B,FL!$B:$AV,Total!K$1,0) -> 0 | L10: =VLOOKUP($B:$B,FL!$B:$AV,Total!L$1,0) -> 0 | M10: =VLOOKUP($B:$B,FL!$B:$AV,Total!M$1,0) -> 0 | ... Q10: =VLOOKUP($B:$B,FL!$B:$AV,Total!Q$1,0) -> 0 | R10: =VLOOKUP(B:B,Conformance!$B$3:$AJ$37,Total!$R$1,0) -> 0.045150463 | S10: =IF((R10*24)>12,3,IF((R10*24)>6,2,IF((R10*24)>2,1,0))) -> 0
A11: =A10+1 -> 9 | B11: =IF(FL!#REF!="","",FL!#REF!) -> #REF! | C11: =IF(FL!#REF!="","",FL!#REF!) -> #REF! | D11: =IF(FL!#REF!="","",FL!#REF!) -> #REF! | E11: =IF(FL!#REF!="","",FL!#REF!) -> #REF! | F11: =VLOOKUP($B:$B,FL!$B:$AV,Total!F$1,0) -> #REF! | G11: =VLOOKUP($B:$B,FL!$B:$AV,Total!G$1,0) -> #REF! | H11: =VLOOKUP($B:$B,FL!$B:$AV,Total!H$1,0) -> #REF! | I11: =VLOOKUP($B:$B,FL!$B:$AV,Total!I$1,0) -> #REF! | J11: =VLOOKUP($B:$B,FL!$B:$AV,Total!J$1,0) -> #REF! | K11: =VLOOKUP($B:$B,FL!$B:$AV,Total!K$1,0) -> #REF! | L11: =VLOOKUP($B:$B,FL!$B:$AV,Total!L$1,0) -> #REF! | M11: =VLOOKUP($B:$B,FL!$B:$AV,Total!M$1,0) -> #REF! | ... Q11: =VLOOKUP($B:$B,FL!$B:$AV,Total!Q$1,0) -> #REF! | R11: =VLOOKUP(B:B,Conformance!$B$3:$AJ$37,Total!$R$1,0) -> #REF! | S11: =IF((R11*24)>12,3,IF((R11*24)>6,2,IF((R11*24)>2,1,0))) -> #REF!
A12: =A11+1 -> 10 | B12: =IF(FL!B12="","",FL!B12) -> V24AMohamed142 | C12: =IF(FL!C12="","",FL!C12) -> Ahmed Hany-Mohamed | D12: =IF(FL!D12="","",FL!D12) -> Mohamed Ahmed-Nagy | E12: =IF(FL!E12="","",FL!E12) -> Mohamed Ahmed-Nagy | F12: =VLOOKUP($B:$B,FL!$B:$AV,Total!F$1,0) -> 0 | G12: =VLOOKUP($B:$B,FL!$B:$AV,Total!G$1,0) -> 0 | H12: =VLOOKUP($B:$B,FL!$B:$AV,Total!H$1,0) -> 0 | I12: =VLOOKUP($B:$B,FL!$B:$AV,Total!I$1,0) -> 0 | J12: =VLOOKUP($B:$B,FL!$B:$AV,Total!J$1,0) -> 0 | K12: =VLOOKUP($B:$B,FL!$B:$AV,Total!K$1,0) -> 0 | L12: =VLOOKUP($B:$B,FL!$B:$AV,Total!L$1,0) -> 0 | M12: =VLOOKUP($B:$B,FL!$B:$AV,Total!M$1,0) -> 0 | ... Q12: =VLOOKUP($B:$B,FL!$B:$AV,Total!Q$1,0) -> 0 | R12: =VLOOKUP(B:B,Conformance!$B$3:$AJ$37,Total!$R$1,0) -> 0 | S12: =IF((R12*24)>12,3,IF((R12*24)>6,2,IF((R12*24)>2,1,0))) -> 0
A13: =A12+1 -> 11 | B13: =IF(FL!B13="","",FL!B13) -> V24KKhalek1 | C13: =IF(FL!C13="","",FL!C13) -> Khaled Waleed-AbdElKhalek | D13: =IF(FL!D13="","",FL!D13) -> Omar Emad-Mahmoud | E13: =IF(FL!E13="","",FL!E13) -> Mohamed Ahmed-Nagy | F13: =VLOOKUP($B:$B,FL!$B:$AV,Total!F$1,0) -> 17 | G13: =VLOOKUP($B:$B,FL!$B:$AV,Total!G$1,0) -> 0 | H13: =VLOOKUP($B:$B,FL!$B:$AV,Total!H$1,0) -> 0 | I13: =VLOOKUP($B:$B,FL!$B:$AV,Total!I$1,0) -> 0 | J13: =VLOOKUP($B:$B,FL!$B:$AV,Total!J$1,0) -> 0 | K13: =VLOOKUP($B:$B,FL!$B:$AV,Total!K$1,0) -> 0 | L13: =VLOOKUP($B:$B,FL!$B:$AV,Total!L$1,0) -> 1 | M13: =VLOOKUP($B:$B,FL!$B:$AV,Total!M$1,0) -> 0 | ... Q13: =VLOOKUP($B:$B,FL!$B:$AV,Total!Q$1,0) -> 0 | R13: =VLOOKUP(B:B,Conformance!$B$3:$AJ$37,Total!$R$1,0) -> 0.0050925926 | S13: =IF((R13*24)>12,3,IF((R13*24)>6,2,IF((R13*24)>2,1,0))) -> 0
A14: =A13+1 -> 12 | B14: =IF(FL!B14="","",FL!B14) -> V25RFarag3 | C14: =IF(FL!C14="","",FL!C14) -> Rawan Ayman-Farag | D14: =IF(FL!D14="","",FL!D14) -> Merna Ashraf-Ashrafy | E14: =IF(FL!E14="","",FL!E14) -> Mohamed Ahmed-Nagy | F14: =VLOOKUP($B:$B,FL!$B:$AV,Total!F$1,0) -> 16 | G14: =VLOOKUP($B:$B,FL!$B:$AV,Total!G$1,0) -> 0 | H14: =VLOOKUP($B:$B,FL!$B:$AV,Total!H$1,0) -> 0 | I14: =VLOOKUP($B:$B,FL!$B:$AV,Total!I$1,0) -> 0 | J14: =VLOOKUP($B:$B,FL!$B:$AV,Total!J$1,0) -> 0 | K14: =VLOOKUP($B:$B,FL!$B:$AV,Total!K$1,0) -> 0 | L14: =VLOOKUP($B:$B,FL!$B:$AV,Total!L$1,0) -> 0 | M14: =VLOOKUP($B:$B,FL!$B:$AV,Total!M$1,0) -> 0 | ... Q14: =VLOOKUP($B:$B,FL!$B:$AV,Total!Q$1,0) -> 0 | R14: =VLOOKUP(B:B,Conformance!$B$3:$AJ$37,Total!$R$1,0) -> 0.0028703704 | S14: =IF((R14*24)>12,3,IF((R14*24)>6,2,IF((R14*24)>2,1,0))) -> 0
A15: =A14+1 -> 13 | B15: =IF(FL!B15="","",FL!B15) -> V25ASamir2 | C15: =IF(FL!C15="","",FL!C15) -> AbdElRahman Mohamed-Samir | D15: =IF(FL!D15="","",FL!D15) -> AbdElRahman Adel-ElKelany | E15: =IF(FL!E15="","",FL!E15) -> Mohamed Ahmed-Nagy | F15: =VLOOKUP($B:$B,FL!$B:$AV,Total!F$1,0) -> 15 | G15: =VLOOKUP($B:$B,FL!$B:$AV,Total!G$1,0) -> 2 | H15: =VLOOKUP($B:$B,FL!$B:$AV,Total!H$1,0) -> 0 | I15: =VLOOKUP($B:$B,FL!$B:$AV,Total!I$1,0) -> 0 | J15: =VLOOKUP($B:$B,FL!$B:$AV,Total!J$1,0) -> 0 | K15: =VLOOKUP($B:$B,FL!$B:$AV,Total!K$1,0) -> 0 | L15: =VLOOKUP($B:$B,FL!$B:$AV,Total!L$1,0) -> 0 | M15: =VLOOKUP($B:$B,FL!$B:$AV,Total!M$1,0) -> 0 | ... Q15: =VLOOKUP($B:$B,FL!$B:$AV,Total!Q$1,0) -> 0 | R15: =VLOOKUP(B:B,Conformance!$B$3:$AJ$37,Total!$R$1,0) -> 0.0035069444 | S15: =IF((R15*24)>12,3,IF((R15*24)>6,2,IF((R15*24)>2,1,0))) -> 0
A16: =A15+1 -> 14 | B16: =IF(FL!B16="","",FL!B16) -> V25SZekry | C16: =IF(FL!C16="","",FL!C16) -> Safaa Safwat-Zekry | D16: =IF(FL!D16="","",FL!D16) -> Merna Ashraf-Ashrafy | E16: =IF(FL!E16="","",FL!E16) -> Mohamed Ahmed-Nagy | F16: =VLOOKUP($B:$B,FL!$B:$AV,Total!F$1,0) -> 17 | G16: =VLOOKUP($B:$B,FL!$B:$AV,Total!G$1,0) -> 1 | H16: =VLOOKUP($B:$B,FL!$B:$AV,Total!H$1,0) -> 0 | I16: =VLOOKUP($B:$B,FL!$B:$AV,Total!I$1,0) -> 0 | J16: =VLOOKUP($B:$B,FL!$B:$AV,Total!J$1,0) -> 0 | K16: =VLOOKUP($B:$B,FL!$B:$AV,Total!K$1,0) -> 0 | L16: =VLOOKUP($B:$B,FL!$B:$AV,Total!L$1,0) -> 0 | M16: =VLOOKUP($B:$B,FL!$B:$AV,Total!M$1,0) -> 0 | ... Q16: =VLOOKUP($B:$B,FL!$B:$AV,Total!Q$1,0) -> 0 | R16: =VLOOKUP(B:B,Conformance!$B$3:$AJ$37,Total!$R$1,0) -> 0.011736111 | S16: =IF((R16*24)>12,3,IF((R16*24)>6,2,IF((R16*24)>2,1,0))) -> 0
A17: =A16+1 -> 15 | B17: =IF(FL!B17="","",FL!B17) -> V24OMohamed10 | C17: =IF(FL!C17="","",FL!C17) -> Osama Magdy-Mohamed | D17: =IF(FL!D17="","",FL!D17) -> AbdElRahman Adel-ElKelany | E17: =IF(FL!E17="","",FL!E17) -> Mohamed Ahmed-Nagy | F17: =VLOOKUP($B:$B,FL!$B:$AV,Total!F$1,0) -> 16 | G17: =VLOOKUP($B:$B,FL!$B:$AV,Total!G$1,0) -> 0 | H17: =VLOOKUP($B:$B,FL!$B:$AV,Total!H$1,0) -> 0 | I17: =VLOOKUP($B:$B,FL!$B:$AV,Total!I$1,0) -> 0 | J17: =VLOOKUP($B:$B,FL!$B:$AV,Total!J$1,0) -> 0 | K17: =VLOOKUP($B:$B,FL!$B:$AV,Total!K$1,0) -> 0 | L17: =VLOOKUP($B:$B,FL!$B:$AV,Total!L$1,0) -> 0 | M17: =VLOOKUP($B:$B,FL!$B:$AV,Total!M$1,0) -> 0 | ... Q17: =VLOOKUP($B:$B,FL!$B:$AV,Total!Q$1,0) -> 0 | R17: =VLOOKUP(B:B,Conformance!$B$3:$AJ$37,Total!$R$1,0) -> 0.12077546 | S17: =IF((R17*24)>12,3,IF((R17*24)>6,2,IF((R17*24)>2,1,0))) -> 1
A18: =A17+1 -> 16 | B18: =IF(FL!#REF!="","",FL!#REF!) -> #REF! | C18: =IF(FL!#REF!="","",FL!#REF!) -> #REF! | D18: =IF(FL!#REF!="","",FL!#REF!) -> #REF! | E18: =IF(FL!#REF!="","",FL!#REF!) -> #REF! | F18: =VLOOKUP($B:$B,FL!$B:$AV,Total!F$1,0) -> #REF! | G18: =VLOOKUP($B:$B,FL!$B:$AV,Total!G$1,0) -> #REF! | H18: =VLOOKUP($B:$B,FL!$B:$AV,Total!H$1,0) -> #REF! | I18: =VLOOKUP($B:$B,FL!$B:$AV,Total!I$1,0) -> #REF! | J18: =VLOOKUP($B:$B,FL!$B:$AV,Total!J$1,0) -> #REF! | K18: =VLOOKUP($B:$B,FL!$B:$AV,Total!K$1,0) -> #REF! | L18: =VLOOKUP($B:$B,FL!$B:$AV,Total!L$1,0) -> #REF! | M18: =VLOOKUP($B:$B,FL!$B:$AV,Total!M$1,0) -> #REF! | ... Q18: =VLOOKUP($B:$B,FL!$B:$AV,Total!Q$1,0) -> #REF! | R18: =VLOOKUP(B:B,Conformance!$B$3:$AJ$37,Total!$R$1,0) -> #REF! | S18: =IF((R18*24)>12,3,IF((R18*24)>6,2,IF((R18*24)>2,1,0))) -> #REF!
