Workbook

Sheet Sheet6
A1: Msisdn | B1: Question1 | C1: Question2 | D1: Question3 | E1: Agent Name | F1: Full Date | G1: Pos Queue | H1: Display Name | I1: Team Leader | J1: Score
A2: 1013043594 | B2: 10 | C2: 4 | D2: 5 | E2: V25AMAHMOUD45 | F2: 46159 | G2: VMT_VQ_VFE3 | H2: Aya Ezzat-Mahmoud | I2: Merna Ashraf-Ashrafy | J2: P
A3: 1097880988 | B3: 10 | C3: 1 | D3: 5 | E3: V25AMAHMOUD45 | F3: 46159 | G3: VMT_VQ_VFE3 | H3: Aya Ezzat-Mahmoud | I3: Merna Ashraf-Ashrafy | J3: P
A4: 1062027180 | B4: 10 | C4: 1 | D4: 5 | E4: V25AMAHMOUD45 | F4: 46158 | G4: VMT_Red_VQ_VFE1 | H4: Aya Ezzat-Mahmoud | I4: Merna Ashraf-Ashrafy | J4: P
A5: 1061574610 | B5: 10 | C5: 1 | D5: 5 | E5: V25AMAHMOUD45 | F5: 46158 | G5: VMT_VQ_VFE3 | H5: Aya Ezzat-Mahmoud | I5: Merna Ashraf-Ashrafy | J5: P
A6: 1040117543 | B6: 10 | C6: 4 | D6: 5 | E6: V25AMAHMOUD45 | F6: 46158 | G6: VMT_VQ_VFE3 | H6: Aya Ezzat-Mahmoud | I6: Merna Ashraf-Ashrafy | J6: P
A7: 1060734865 | B7: 10 | C7: 1 | D7: 5 | E7: V25AMAHMOUD45 | F7: 46155 | G7: VMT_Red_VQ_VFE1 | H7: Aya Ezzat-Mahmoud | I7: Merna Ashraf-Ashrafy | J7: P
A8: 1002077069 | B8: 10 | C8: 4 | D8: 5 | E8: V25AMAHMOUD45 | F8: 46155 | G8: VMT_Red_VQ_VFE1 | H8: Aya Ezzat-Mahmoud | I8: Merna Ashraf-Ashrafy | J8: P
A9: 1099157562 | B9: 10 | C9: 1 | D9: 5 | E9: V25AMAHMOUD45 | F9: 46154 | G9: VMT_Red_VQ_VFE1 | H9: Aya Ezzat-Mahmoud | I9: Merna Ashraf-Ashrafy | J9: P
A10: 1065277718 | B10: 10 | C10: 3 | D10: 5 | E10: V25AMAHMOUD45 | F10: 46154 | G10: VMT_Red_VQ_VFE1 | H10: Aya Ezzat-Mahmoud | I10: Merna Ashraf-Ashrafy | J10: P
A11: 1021751111 | B11: 9 | C11: 4 | D11: 5 | E11: V25AMAHMOUD45 | F11: 46154 | G11: VMT_Red_VQ_VFE1 | H11: Aya Ezzat-Mahmoud | I11: Merna Ashraf-Ashrafy | J11: P
A12: 1068370983 | B12: 10 | C12: 1 | D12: 5 | E12: V25AMAHMOUD45 | F12: 46153 | G12: VMT_Red_VQ_VFE1 | H12: Aya Ezzat-Mahmoud | I12: Merna Ashraf-Ashrafy | J12: P
A13: 1096712464 | B13: 10 | C13: 4 | D13: 5 | E13: V25AMAHMOUD45 | F13: 46152 | G13: VMT_Red_VQ_VFE1 | H13: Aya Ezzat-Mahmoud | I13: Merna Ashraf-Ashrafy | J13: P
A14: 1033205019 | B14: 10 | C14: 4 | D14: 5 | E14: V25AMAHMOUD45 | F14: 46151 | G14: VMT_Red_VQ_VFE1 | H14: Aya Ezzat-Mahmoud | I14: Merna Ashraf-Ashrafy | J14: P
A15: 1279090763 | B15: 10 | C15: 4 | D15: 5 | E15: V25AMAHMOUD45 | F15: 46148 | G15: VMT_Red_VQ_VFE1 | H15: Aya Ezzat-Mahmoud | I15: Merna Ashraf-Ashrafy | J15: P
... A19: 1008910270 | B19: 10 | C19: 1 | D19: 5 | E19: V25AMAHMOUD45 | F19: 46146 | G19: VMT_Red_VQ_VFE1 | H19: Aya Ezzat-Mahmoud | I19: Merna Ashraf-Ashrafy | J19: P

Sheet NPS
M1: Display Name | N1: D | O1: N | P1: P | Q1: Grand Total | R1: Score | S1: Needed Promoters | W1: Display Name | X1: D | Y1: N | Z1: P | AA1: Grand Total | AB1: Score | AC1: Needed Promoters
M2: Karim Medhat-Mahrous | P2: 2 | Q2: 2 | R2: =(P2-N2)/Q2 *100 -> 100 | S2: =(N2 *5) + (O2 *2) -P2 -> -2 | W2: Aya Ezzat-Mahmoud | Z2: 18 | AA2: 18 | AB2: =(Z2-X2)/AA2 *100 -> 100 | AC2: =(X2 *5) + (Y2 *2) -Z2 -> -18
A3: Count of Question1 | B3: Column Labels | M3: AbdElRhman Hesham-AbdElFadeel | N3: 1 | P3: 14 | Q3: 15 | R3: =(P3-N3)/Q3 *100 -> 86.666667 | S3: =(N3 *5) + (O3 *2) -P3 -> -9 | W3: Salma Taha-Ahmed | Z3: 12 | AA3: 12 | AB3: =(Z3-X3)/AA3 *100 -> 100 | AC3: =(X3 *5) + (Y3 *2) -Z3 -> -12
A4: Display Name | B4: D | C4: N | D4: P | E4: Grand Total | F4: Score | G4: Needed Promoters | M4: Seif Ahmed-AbdELMawgod | O4: 1 | P4: 1 | Q4: 2 | R4: =(P4-N4)/Q4 *100 -> 50 | S4: =(N4 *5) + (O4 *2) -P4 -> 1 | W4: AbdElRhman Hesham-AbdElFadeel | X4: 1 | Z4: 14 | AA4: 15 | AB4: =(Z4-X4)/AA4 *100 -> 86.666667 | AC4: =(X4 *5) + (Y4 *2) -Z4 -> -9
A5: AbdElRahman Adel-ElKelany | B5: 19 | C5: 3 | D5: 45 | E5: 67 | F5: =(D5-B5)/E5 *100 -> 38.80597 | G5: =(B5 *5) + (C5 *2) -D5 -> 56 | M5: Ibrahim Ahmed-Ghonimy | N5: 3 | P5: 7 | Q5: 10 | R5: =(P5-N5)/Q5 *100 -> 40 | S5: =(N5 *5) + (O5 *2) -P5 -> 8 | W5: Safaa Safwat-Zekry | X5: 1 | Y5: 1 | Z5: 13 | AA5: 15 | AB5: =(Z5-X5)/AA5 *100 -> 80 | AC5: =(X5 *5) + (Y5 *2) -Z5 -> -6
A6: AbdElRhman Hesham-AbdElFadeel | B6: 1 | D6: 14 | E6: 15 | F6: =(D6-B6)/E6 *100 -> 86.666667 | G6: =(B6 *5) + (C6 *2) -D6 -> -9 | M6: Ziad Hassan-Donkol | N6: 3 | P6: 5 | Q6: 8 | R6: =(P6-N6)/Q6 *100 -> 25 | S6: =(N6 *5) + (O6 *2) -P6 -> 10 | W6: Mohamed Khaled-Khattab | X6: 1 | Y6: 1 | Z6: 12 | AA6: 14 | AB6: =(Z6-X6)/AA6 *100 -> 78.571429 | AC6: =(X6 *5) + (Y6 *2) -Z6 -> -5
A7: Ibrahim Ahmed-Ghonimy | B7: 4 | D7: 8 | E7: 12 | F7: =(D7-B7)/E7 *100 -> 33.333333 | G7: =(B7 *5) + (C7 *2) -D7 -> 12 | M7: Tarek Ayman-Ahmed | N7: 2 | O7: 1 | P7: 3 | Q7: 6 | R7: =(P7-N7)/Q7 *100 -> 16.666667 | S7: =(N7 *5) + (O7 *2) -P7 -> 9 | W7: Mohada Mohamed-Hamdy | Y7: 3 | Z7: 11 | AA7: 14 | AB7: =(Z7-X7)/AA7 *100 -> 78.571429 | AC7: =(X7 *5) + (Y7 *2) -Z7 -> -5
A8: Mohamed AbdElMohsen-Mahdy | B8: 5 | C8: 1 | D8: 3 | E8: 9 | F8: =(D8-B8)/E8 *100 -> -22.222222 | G8: =(B8 *5) + (C8 *2) -D8 -> 24 | M8: Omar Ali-Gohar | N8: 1 | P8: 1 | Q8: 2 | R8: =(P8-N8)/Q8 *100 -> 0 | S8: =(N8 *5) + (O8 *2) -P8 -> 4 | W8: Hatem Ibrahim-Ahmed | X8: 1 | Z8: 9 | AA8: 10 | AB8: =(Z8-X8)/AA8 *100 -> 80 | AC8: =(X8 *5) + (Y8 *2) -Z8 -> -4
A9: Seif Ahmed-AbdELMawgod | C9: 1 | D9: 3 | E9: 4 | F9: =(D9-B9)/E9 *100 -> 75 | G9: =(B9 *5) + (C9 *2) -D9 -> -1 | M9: Mohamed AbdElMohsen-Mahdy | N9: 5 | O9: 1 | P9: 3 | Q9: 9 | R9: =(P9-N9)/Q9 *100 -> -22.222222 | S9: =(N9 *5) + (O9 *2) -P9 -> 24 | W9: Karim Medhat-Mahrous | Z9: 2 | AA9: 2 | AB9: =(Z9-X9)/AA9 *100 -> 100 | AC9: =(X9 *5) + (Y9 *2) -Z9 -> -2
A10: Tarek Ayman-Ahmed | B10: 2 | C10: 1 | D10: 5 | E10: 8 | F10: =(D10-B10)/E10 *100 -> 37.5 | G10: =(B10 *5) + (C10 *2) -D10 -> 7 | M10: Taher Ibrahim-Omar | N10: 2 | Q10: 2 | R10: =(P10-N10)/Q10 *100 -> -100 | S10: =(N10 *5) + (O10 *2) -P10 -> 10 | W10: Seif Ahmed-AbdELMawgod | Y10: 1 | Z10: 3 | AA10: 4 | AB10: =(Z10-X10)/AA10 *100 -> 75 | AC10: =(X10 *5) + (Y10 *2) -Z10 -> -1
A11: Ziad Hassan-Donkol | B11: 3 | D11: 5 | E11: 8 | F11: =(D11-B11)/E11 *100 -> 25 | G11: =(B11 *5) + (C11 *2) -D11 -> 10 | M11: AbdElRahman Adel-ElKelany | N11: 17 | O11: 3 | P11: 36 | Q11: 56 | R11: =(P11-N11)/Q11 *100 -> 33.928571 | S11: =(N11 *5) + (O11 *2) -P11 -> 55 | W11: Merna Ashraf-Ashrafy | Z11: 1 | AA11: 1 | AB11: =(Z11-X11)/AA11 *100 -> 100 | AC11: =(X11 *5) + (Y11 *2) -Z11 -> -1
A12: Taher Ibrahim-Omar | B12: 2 | D12: 1 | E12: 3 | F12: =(D12-B12)/E12 *100 -> -33.333333 | G12: =(B12 *5) + (C12 *2) -D12 -> 9 | W12: Ahmed Sameh-Rizk | Z12: 1 | AA12: 1 | AB12: =(Z12-X12)/AA12 *100 -> 100 | AC12: =(X12 *5) + (Y12 *2) -Z12 -> -1
A13: Karim Medhat-Mahrous | D13: 2 | E13: 2 | F13: =(D13-B13)/E13 *100 -> 100 | G13: =(B13 *5) + (C13 *2) -D13 -> -2 | M13: Display Name | N13: D | O13: N | P13: P | Q13: Grand Total | R13: Score | S13: Needed Promoters | W13: Peter Amgad-Shehata | X13: 1 | Y13: 1 | Z13: 7 | AA13: 9 | AB13: =(Z13-X13)/AA13 *100 -> 66.666667 | AC13: =(X13 *5) + (Y13 *2) -Z13 -> 0
A14: Omar Ali-Gohar | B14: 2 | D14: 4 | E14: 6 | F14: =(D14-B14)/E14 *100 -> 33.333333 | G14: =(B14 *5) + (C14 *2) -D14 -> 6 | M14: Merna Mohamed-AbdElHalim | P14: 1 | Q14: 1 | R14: =(P14-N14)/Q14 *100 -> 100 | S14: =(N14 *5) + (O14 *2) -P14 -> -1 | W14: Mohamed Ali-AbdElGelil | X14: 1 | Z14: 5 | AA14: 6 | AB14: =(Z14-X14)/AA14 *100 -> 66.666667 | AC14: =(X14 *5) + (Y14 *2) -Z14 -> 0
A15: Hend Yousry-AbdElRassoul | B15: 31 | C15: 9 | D15: 99 | E15: 139 | F15: =(D15-B15)/E15 *100 -> 48.920863 | G15: =(B15 *5) + (C15 *2) -D15 -> 74 | M15: Mohamed AbdElazim-Farag | N15: 2 | P15: 13 | Q15: 15 | R15: =(P15-N15)/Q15 *100 -> 73.333333 | S15: =(N15 *5) + (O15 *2) -P15 -> -3 | W15: Sherif Madbouly-Sayed | X15: 1 | Z15: 5 | AA15: 6 | AB15: =(Z15-X15)/AA15 *100 -> 66.666667 | AC15: =(X15 *5) + (Y15 *2) -Z15 -> 0
A16: Ahmed Maged-Wahib | B16: 2 | D16: 4 | E16: 6 | F16: =(D16-B16)/E16 *100 -> 33.333333 | G16: =(B16 *5) + (C16 *2) -D16 -> 6 | M16: Mohamed Khaled-Khattab | N16: 1 | O16: 1 | P16: 9 | Q16: 11 | R16: =(P16-N16)/Q16 *100 -> 72.727273 | S16: =(N16 *5) + (O16 *2) -P16 -> -2 | W16: Mohamed Gamil-Salah | X16: 1 | Z16: 4 | AA16: 5 | AB16: =(Z16-X16)/AA16 *100 -> 60 | AC16: =(X16 *5) + (Y16 *2) -Z16 -> 1
A17: Esraa Saad-Mahfod | B17: 3 | D17: 10 | E17: 13 | F17: =(D17-B17)/E17 *100 -> 53.846154 | G17: =(B17 *5) + (C17 *2) -D17 -> 5 | M17: Peter Amgad-Shehata | N17: 1 | O17: 1 | P17: 7 | Q17: 9 | R17: =(P17-N17)/Q17 *100 -> 66.666667 | S17: =(N17 *5) + (O17 *2) -P17 -> 0 | W17: Kawthar Nasreldin-Mohyeldin | X17: 1 | Y17: 2 | Z17: 7 | AA17: 10 | AB17: =(Z17-X17)/AA17 *100 -> 60 | AC17: =(X17 *5) + (Y17 *2) -Z17 -> 2
A18: Mohamed AbdElazim-Farag | B18: 4 | C18: 1 | D18: 13 | E18: 18 | F18: =(D18-B18)/E18 *100 -> 50 | G18: =(B18 *5) + (C18 *2) -D18 -> 9 | M18: Omar Mamdouh-AbdAllah | N18: 3 | O18: 2 | P18: 12 | Q18: 17 | R18: =(P18-N18)/Q18 *100 -> 52.941176 | S18: =(N18 *5) + (O18 *2) -P18 -> 7 | W18: Bassant Salah-Hassan | X18: 2 | Z18: 8 | AA18: 10 | AB18: =(Z18-X18)/AA18 *100 -> 60 | AC18: =(X18 *5) + (Y18 *2) -Z18 -> 2
A19: Mohamed Ahmed-Mansour | B19: 3 | D19: 11 | E19: 14 | F19: =(D19-B19)/E19 *100 -> 57.142857 | G19: =(B19 *5) + (C19 *2) -D19 -> 4 | M19: Esraa Saad-Mahfod | N19: 3 | P19: 9 | Q19: 12 | R19: =(P19-N19)/Q19 *100 -> 50 | S19: =(N19 *5) + (O19 *2) -P19 -> 6 | W19: AbdElRahman Mohamed-Moslhy | X19: 1 | Y19: 1 | Z19: 5 | AA19: 7 | AB19: =(Z19-X19)/AA19 *100 -> 57.142857 | AC19: =(X19 *5) + (Y19 *2) -Z19 -> 2
A20: Mohamed Khaled-Khattab | B20: 1 | C20: 1 | D20: 12 | E20: 14 | F20: =(D20-B20)/E20 *100 -> 78.571429 | G20: =(B20 *5) + (C20 *2) -D20 -> -5 | M20: Mohamed Ahmed-Mansour | N20: 3 | P20: 9 | Q20: 12 | R20: =(P20-N20)/Q20 *100 -> 50 | S20: =(N20 *5) + (O20 *2) -P20 -> 6 | W20: Ahmed Magdy-Ewis | X20: 2 | Y20: 1 | Z20: 10 | AA20: 13 | AB20: =(Z20-X20)/AA20 *100 -> 61.538462 | AC20: =(X20 *5) + (Y20 *2) -Z20 -> 2
A21: Omar Mamdouh-AbdAllah | B21: 4 | C21: 2 | D21: 16 | E21: 22 | F21: =(D21-B21)/E21 *100 -> 54.545455 | G21: =(B21 *5) + (C21 *2) -D21 -> 8 | M21: Yara Hussein-Mofleh | N21: 6 | P21: 13 | Q21: 19 | R21: =(P21-N21)/Q21 *100 -> 36.842105 | S21: =(N21 *5) + (O21 *2) -P21 -> 17 | W21: Merna Mohamed-AbdElHalim | X21: 1 | Z21: 2 | AA21: 3 | AB21: =(Z21-X21)/AA21 *100 -> 33.333333 | AC21: =(X21 *5) + (Y21 *2) -Z21 -> 3
A22: Peter Amgad-Shehata | B22: 1 | C22: 1 | D22: 7 | E22: 9 | F22: =(D22-B22)/E22 *100 -> 66.666667 | G22: =(B22 *5) + (C22 *2) -D22 -> 0 | M22: Ahmed Maged-Wahib | N22: 2 | P22: 4 | Q22: 6 | R22: =(P22-N22)/Q22 *100 -> 33.333333 | S22: =(N22 *5) + (O22 *2) -P22 -> 6 | W22: Farha Ashraf-AboElMagd | X22: 1 | Z22: 2 | AA22: 3 | AB22: =(Z22-X22)/AA22 *100 -> 33.333333 | AC22: =(X22 *5) + (Y22 *2) -Z22 -> 3
A23: Yara Hussein-Mofleh | B23: 7 | D23: 13 | E23: 20 | F23: =(D23-B23)/E23 *100 -> 30 | G23: =(B23 *5) + (C23 *2) -D23 -> 22 | M23: Mayar Ibrahim-Noah | N23: 4 | O23: 2 | P23: 4 | Q23: 10 | R23: =(P23-N23)/Q23 *100 -> 0 | S23: =(N23 *5) + (O23 *2) -P23 -> 20 | W23: Mohamed Ahmed-Mansour | X23: 3 | Z23: 11 | AA23: 14 | AB23: =(Z23-X23)/AA23 *100 -> 57.142857 | AC23: =(X23 *5) + (Y23 *2) -Z23 -> 4
A24: Mayar Ibrahim-Noah | B24: 4 | C24: 2 | D24: 4 | E24: 10 | F24: =(D24-B24)/E24 *100 -> 0 | G24: =(B24 *5) + (C24 *2) -D24 -> 20 | M24: Kawthar Nasreldin-Mohyeldin | N24: 1 | O24: 1 | P24: 1 | Q24: 3 | R24: =(P24-N24)/Q24 *100 -> 0 | S24: =(N24 *5) + (O24 *2) -P24 -> 6 | W24: Omnia Wageeh-ElAzab | X24: 2 | Y24: 3 | Z24: 12 | AA24: 17 | AB24: =(Z24-X24)/AA24 *100 -> 58.823529 | AC24: =(X24 *5) + (Y24 *2) -Z24 -> 4
A25: Kawthar Nasreldin-Mohyeldin | B25: 1 | C25: 2 | D25: 7 | E25: 10 | F25: =(D25-B25)/E25 *100 -> 60 | G25: =(B25 *5) + (C25 *2) -D25 -> 2 | M25: Hend Yousry-AbdElRassoul | N25: 26 | O25: 7 | P25: 82 | Q25: 115 | R25: =(P25-N25)/Q25 *100 -> 48.695652 | S25: =(N25 *5) + (O25 *2) -P25 -> 62 | W25: Mohab Mohamed-Reda | X25: 1 | Z25: 1 | AA25: 2 | AB25: =(Z25-X25)/AA25 *100 -> 0 | AC25: =(X25 *5) + (Y25 *2) -Z25 -> 4
A26: Merna Mohamed-AbdElHalim | B26: 1 | D26: 2 | E26: 3 | F26: =(D26-B26)/E26 *100 -> 33.333333 | G26: =(B26 *5) + (C26 *2) -D26 -> 3 | W26: Islam Gamal-Zakaria | Y26: 4 | Z26: 4 | AA26: 8 | AB26: =(Z26-X26)/AA26 *100 -> 50 | AC26: =(X26 *5) + (Y26 *2) -Z26 -> 4
A27: Merna Ashraf-Ashrafy | B27: 25 | C27: 10 | D27: 103 | E27: 138 | F27: =(D27-B27)/E27 *100 -> 56.521739 | G27: =(B27 *5) + (C27 *2) -D27 -> 42 | M27: Display Name | N27: D | O27: N | P27: P | Q27: Grand Total | R27: Score | S27: Needed Promoters | W27: Esraa Saad-Mahfod | X27: 3 | Z27: 10 | AA27: 13 | AB27: =(Z27-X27)/AA27 *100 -> 53.846154 | AC27: =(X27 *5) + (Y27 *2) -Z27 -> 5
A28: Aya Ezzat-Mahmoud | D28: 18 | E28: 18 | F28: =(D28-B28)/E28 *100 -> 100 | G28: =(B28 *5) + (C28 *2) -D28 -> -18 | M28: Aya Ezzat-Mahmoud | P28: 18 | Q28: 18 | R28: =(P28-N28)/Q28 *100 -> 100 | S28: =(N28 *5) + (O28 *2) -P28 -> -18 | W28: Mohamed AbdElaziz-AbdElRahman | Y28: 3 | Z28: 1 | AA28: 4 | AB28: =(Z28-X28)/AA28 *100 -> 25 | AC28: =(X28 *5) + (Y28 *2) -Z28 -> 5
A29: Aya Mohamed-Hassan | B29: 2 | E29: 2 | F29: =(D29-B29)/E29 *100 -> -100 | G29: =(B29 *5) + (C29 *2) -D29 -> 10 | M29: Salma Taha-Ahmed | P29: 12 | Q29: 12 | R29: =(P29-N29)/Q29 *100 -> 100 | S29: =(N29 *5) + (O29 *2) -P29 -> -12 | W29: Omar Ali-Gohar | X29: 2 | Z29: 4 | AA29: 6 | AB29: =(Z29-X29)/AA29 *100 -> 33.333333 | AC29: =(X29 *5) + (Y29 *2) -Z29 -> 6
A30: Bassant Salah-Hassan | B30: 2 | D30: 8 | E30: 10 | F30: =(D30-B30)/E30 *100 -> 60 | G30: =(B30 *5) + (C30 *2) -D30 -> 2 | M30: Safaa Safwat-Zekry | N30: 1 | O30: 1 | P30: 13 | Q30: 15 | R30: =(P30-N30)/Q30 *100 -> 80 | S30: =(N30 *5) + (O30 *2) -P30 -> -6 | W30: Ahmed Maged-Wahib | X30: 2 | Z30: 4 | AA30: 6 | AB30: =(Z30-X30)/AA30 *100 -> 33.333333 | AC30: =(X30 *5) + (Y30 *2) -Z30 -> 6
A31: Farha Ashraf-AboElMagd | B31: 1 | D31: 2 | E31: 3 | F31: =(D31-B31)/E31 *100 -> 33.333333 | G31: =(B31 *5) + (C31 *2) -D31 -> 3 | M31: Mohada Mohamed-Hamdy | O31: 3 | P31: 11 | Q31: 14 | R31: =(P31-N31)/Q31 *100 -> 78.571429 | S31: =(N31 *5) + (O31 *2) -P31 -> -5 | W31: Ahmed Fathy-Fathy | X31: 3 | Y31: 1 | Z31: 11 | AA31: 15 | AB31: =(Z31-X31)/AA31 *100 -> 53.333333 | AC31: =(X31 *5) + (Y31 *2) -Z31 -> 6
A32: Hassan Ramy-Hassan | B32: 4 | C32: 1 | D32: 9 | E32: 14 | F32: =(D32-B32)/E32 *100 -> 35.714286 | G32: =(B32 *5) + (C32 *2) -D32 -> 13 | M32: Bassant Salah-Hassan | N32: 2 | P32: 8 | Q32: 10 | R32: =(P32-N32)/Q32 *100 -> 60 | S32: =(N32 *5) + (O32 *2) -P32 -> 2 | W32: Tarek Ayman-Ahmed | X32: 2 | Y32: 1 | Z32: 5 | AA32: 8 | AB32: =(Z32-X32)/AA32 *100 -> 37.5 | AC32: =(X32 *5) + (Y32 *2) -Z32 -> 7
A33: Mohada Mohamed-Hamdy | C33: 3 | D33: 11 | E33: 14 | F33: =(D33-B33)/E33 *100 -> 78.571429 | G33: =(B33 *5) + (C33 *2) -D33 -> -5 | M33: Omnia Wageeh-ElAzab | N33: 2 | O33: 3 | P33: 12 | Q33: 17 | R33: =(P33-N33)/Q33 *100 -> 58.823529 | S33: =(N33 *5) + (O33 *2) -P33 -> 4 | W33: Nouran AbdAllah-Saeed | X33: 3 | Z33: 8 | AA33: 11 | AB33: =(Z33-X33)/AA33 *100 -> 45.454545 | AC33: =(X33 *5) + (Y33 *2) -Z33 -> 7
A34: Nouran AbdAllah-Saeed | B34: 3 | D34: 8 | E34: 11 | F34: =(D34-B34)/E34 *100 -> 45.454545 | G34: =(B34 *5) + (C34 *2) -D34 -> 7 | M34: Hassan Ramy-Hassan | N34: 4 | O34: 1 | P34: 9 | Q34: 14 | R34: =(P34-N34)/Q34 *100 -> 35.714286 | S34: =(N34 *5) + (O34 *2) -P34 -> 13 | W34: Omar Mamdouh-AbdAllah | X34: 4 | Y34: 2 | Z34: 16 | AA34: 22 | AB34: =(Z34-X34)/AA34 *100 -> 54.545455 | AC34: =(X34 *5) + (Y34 *2) -Z34 -> 8
A35: Omnia Wageeh-ElAzab | B35: 2 | C35: 3 | D35: 12 | E35: 17 | F35: =(D35-B35)/E35 *100 -> 58.823529 | G35: =(B35 *5) + (C35 *2) -D35 -> 4 | M35: Farha Ashraf-AboElMagd | N35: 1 | P35: 2 | Q35: 3 | R35: =(P35-N35)/Q35 *100 -> 33.333333 | S35: =(N35 *5) + (O35 *2) -P35 -> 3 | W35: Andrwa Wafeek-Zaki | X35: 3 | Z35: 7 | AA35: 10 | AB35: =(Z35-X35)/AA35 *100 -> 40 | AC35: =(X35 *5) + (Y35 *2) -Z35 -> 8
A36: Safaa Safwat-Zekry | B36: 1 | C36: 1 | D36: 13 | E36: 15 | F36: =(D36-B36)/E36 *100 -> 80 | G36: =(B36 *5) + (C36 *2) -D36 -> -6 | M36: Nouran AbdAllah-Saeed | N36: 2 | P36: 3 | Q36: 5 | R36: =(P36-N36)/Q36 *100 -> 20 | S36: =(N36 *5) + (O36 *2) -P36 -> 7 | W36: Taher Ibrahim-Omar | X36: 2 | Z36: 1 | AA36: 3 | AB36: =(Z36-X36)/AA36 *100 -> -33.333333 | AC36: =(X36 *5) + (Y36 *2) -Z36 -> 9
A37: Salma Taha-Ahmed | D37: 12 | E37: 12 | F37: =(D37-B37)/E37 *100 -> 100 | G37: =(B37 *5) + (C37 *2) -D37 -> -12 | M37: Mohab Mohamed-Reda | N37: 1 | P37: 1 | Q37: 2 | R37: =(P37-N37)/Q37 *100 -> 0 | S37: =(N37 *5) + (O37 *2) -P37 -> 4 | W37: Mohamed AbdElazim-Farag | X37: 4 | Y37: 1 | Z37: 13 | AA37: 18 | AB37: =(Z37-X37)/AA37 *100 -> 50 | AC37: =(X37 *5) + (Y37 *2) -Z37 -> 9
A38: Yasmine Waleed-Mohamed | B38: 9 | C38: 2 | D38: 8 | E38: 19 | F38: =(D38-B38)/E38 *100 -> -5.2631579 | G38: =(B38 *5) + (C38 *2) -D38 -> 41 | M38: Yasmine Waleed-Mohamed | N38: 8 | O38: 2 | P38: 7 | Q38: 17 | R38: =(P38-N38)/Q38 *100 -> -5.8823529 | S38: =(N38 *5) + (O38 *2) -P38 -> 37 | W38: Ziad Hassan-Donkol | X38: 3 | Z38: 5 | AA38: 8 | AB38: =(Z38-X38)/AA38 *100 -> 25 | AC38: =(X38 *5) + (Y38 *2) -Z38 -> 10
A39: Mohab Mohamed-Reda | B39: 1 | D39: 1 | E39: 2 | F39: =(D39-B39)/E39 *100 -> 0 | G39: =(B39 *5) + (C39 *2) -D39 -> 4 | M39: Aya Mohamed-Hassan | N39: 2 | Q39: 2 | R39: =(P39-N39)/Q39 *100 -> -100 | S39: =(N39 *5) + (O39 *2) -P39 -> 10 | W39: Aya Mohamed-Hassan | X39: 2 | AA39: 2 | AB39: =(Z39-X39)/AA39 *100 -> -100 | AC39: =(X39 *5) + (Y39 *2) -Z39 -> 10
A40: Merna Ashraf-Ashrafy | D40: 1 | E40: 1 | F40: =(D40-B40)/E40 *100 -> 100 | G40: =(B40 *5) + (C40 *2) -D40 -> -1 | M40: Merna Ashraf-Ashrafy | N40: 23 | O40: 10 | P40: 96 | Q40: 129 | R40: =(P40-N40)/Q40 *100 -> 56.589147 | S40: =(N40 *5) + (O40 *2) -P40 -> 39 | W40: Ibrahim Ahmed-Ghonimy | X40: 4 | Z40: 8 | AA40: 12 | AB40: =(Z40-X40)/AA40 *100 -> 33.333333 | AC40: =(X40 *5) + (Y40 *2) -Z40 -> 12
...

Sheet NPS row data (Rizk structure)
A1: Msisdn | B1: Question1 | C1: Question2 | D1: Question3 | E1: Agent Name | F1: Full Date | G1: Pos Queue | H1: Display Name | I1: Team Leader | J1: Score
A2: 1000061099 | B2: 10 | C2: 1 | D2: 5 | E2: V25PSHEHATA | F2: 46145 | G2: VMT_VQ_VFE3 | H2: =VLOOKUP(E2,'HC for display name '!$B:$D,2,0) -> Peter Amgad-Shehata | I2: =VLOOKUP(E2,'HC for display name '!$B:$D,3,0) -> Hend Yousry-AbdElRassoul | J2: =VLOOKUP(B2,$T$3:$U$13,2,0) -> P
A3: 1001305864 | B3: 10 | C3: 1 | D3: 5 | E3: V25AEWIS2 | F3: 46145 | G3: VMT_VQ_VFE3 | H3: =VLOOKUP(E3,'HC for display name '!$B:$D,2,0) -> Ahmed Magdy-Ewis | I3: =VLOOKUP(E3,'HC for display name '!$B:$D,3,0) -> Omar Emad-Mahmoud | J3: =VLOOKUP(B3,$T$3:$U$13,2,0) -> P | T3: 0 | U3: D
A4: 1001454085 | B4: 10 | C4: 1 | D4: 5 | E4: V25OAZAB | F4: 46145 | G4: VMT_Red_VQ_VFE1 | H4: =VLOOKUP(E4,'HC for display name '!$B:$D,2,0) -> Omnia Wageeh-ElAzab | I4: =VLOOKUP(E4,'HC for display name '!$B:$D,3,0) -> Merna Ashraf-Ashrafy | J4: =VLOOKUP(B4,$T$3:$U$13,2,0) -> P | T4: 1 | U4: D
A5: 1005842115 | B5: 5 | C5: 3 | D5: 5 | E5: V25OALLAH9 | F5: 46145 | G5: VMT_Red_VQ_VFE1 | H5: =VLOOKUP(E5,'HC for display name '!$B:$D,2,0) -> Omar Mamdouh-AbdAllah | I5: =VLOOKUP(E5,'HC for display name '!$B:$D,3,0) -> Hend Yousry-AbdElRassoul | J5: =VLOOKUP(B5,$T$3:$U$13,2,0) -> D | T5: 2 | U5: D
A6: 1009900071 | B6: 10 | C6: 1 | D6: 5 | E6: V25IGHONIMY | F6: 46145 | G6: VMT_Red_VQ_VFE1 | H6: =VLOOKUP(E6,'HC for display name '!$B:$D,2,0) -> Ibrahim Ahmed-Ghonimy | I6: =VLOOKUP(E6,'HC for display name '!$B:$D,3,0) -> AbdElRahman Adel-ElKelany | J6: =VLOOKUP(B6,$T$3:$U$13,2,0) -> P | T6: 3 | U6: D
A7: 1010858015 | B7: 0 | C7: 3 | D7: 1 | E7: V25AFADEEL2 | F7: 46145 | G7: VMT_VQ_VFE3 | H7: =VLOOKUP(E7,'HC for display name '!$B:$D,2,0) -> AbdElRhman Hesham-AbdElFadeel | I7: =VLOOKUP(E7,'HC for display name '!$B:$D,3,0) -> AbdElRahman Adel-ElKelany | J7: =VLOOKUP(B7,$T$3:$U$13,2,0) -> D | T7: 4 | U7: D
A8: 1011031229 | B8: 10 | C8: 4 | D8: 5 | E8: V25PSHEHATA | F8: 46145 | G8: VMT_Red_VQ_VFE1 | H8: =VLOOKUP(E8,'HC for display name '!$B:$D,2,0) -> Peter Amgad-Shehata | I8: =VLOOKUP(E8,'HC for display name '!$B:$D,3,0) -> Hend Yousry-AbdElRassoul | J8: =VLOOKUP(B8,$T$3:$U$13,2,0) -> P | T8: 5 | U8: D
A9: 1011299898 | B9: 9 | C9: 1 | D9: 5 | E9: V25AWAHIB | F9: 46145 | G9: VMT_Red_VQ_VFE1 | H9: =VLOOKUP(E9,'HC for display name '!$B:$D,2,0) -> Ahmed Maged-Wahib | I9: =VLOOKUP(E9,'HC for display name '!$B:$D,3,0) -> Hend Yousry-AbdElRassoul | J9: =VLOOKUP(B9,$T$3:$U$13,2,0) -> P | T9: 6 | U9: D
A10: 1014945118 | B10: 10 | C10: 1 | D10: 5 | E10: V25HAHMED43 | F10: 46145 | G10: VMT_VQ_VFE3 | H10: =VLOOKUP(E10,'HC for display name '!$B:$D,2,0) -> Hatem Ibrahim-Ahmed | I10: =VLOOKUP(E10,'HC for display name '!$B:$D,3,0) -> Omar Emad-Mahmoud | J10: =VLOOKUP(B10,$T$3:$U$13,2,0) -> P | T10: 7 | U10: N
A11: 1015779232 | B11: 9 | C11: 1 | D11: 5 | E11: V25AEWIS2 | F11: 46145 | G11: VMT_VQ_VFE3 | H11: =VLOOKUP(E11,'HC for display name '!$B:$D,2,0) -> Ahmed Magdy-Ewis | I11: =VLOOKUP(E11,'HC for display name '!$B:$D,3,0) -> Omar Emad-Mahmoud | J11: =VLOOKUP(B11,$T$3:$U$13,2,0) -> P | T11: 8 | U11: N
A12: 1017470008 | B12: 10 | C12: 1 | D12: 5 | E12: V25HHASSAN50 | F12: 46145 | G12: VMT_VQ_VFE3 | H12: =VLOOKUP(E12,'HC for display name '!$B:$D,2,0) -> Hassan Ramy-Hassan | I12: =VLOOKUP(E12,'HC for display name '!$B:$D,3,0) -> Merna Ashraf-Ashrafy | J12: =VLOOKUP(B12,$T$3:$U$13,2,0) -> P | T12: 9 | U12: P
A13: 1022848164 | B13: 10 | C13: 4 | D13: 5 | E13: V25OALLAH9 | F13: 46145 | G13: VMT_Red_VQ_VFE1 | H13: =VLOOKUP(E13,'HC for display name '!$B:$D,2,0) -> Omar Mamdouh-AbdAllah | I13: =VLOOKUP(E13,'HC for display name '!$B:$D,3,0) -> Hend Yousry-AbdElRassoul | J13: =VLOOKUP(B13,$T$3:$U$13,2,0) -> P | T13: 10 | U13: P
A14: 1027107865 | B14: 10 | C14: 1 | D14: 5 | E14: V25AWAHIB | F14: 46145 | G14: VMT_Red_VQ_VFE1 | H14: =VLOOKUP(E14,'HC for display name '!$B:$D,2,0) -> Ahmed Maged-Wahib | I14: =VLOOKUP(E14,'HC for display name '!$B:$D,3,0) -> Hend Yousry-AbdElRassoul | J14: =VLOOKUP(B14,$T$3:$U$13,2,0) -> P
A15: 1031529082 | B15: 0 | C15: 3 | D15: 1 | E15: V26MMAHDY | F15: 46145 | G15: VMT_VQ_VFE3 | H15: =VLOOKUP(E15,'HC for display name '!$B:$D,2,0) -> Mohamed AbdElMohsen-Mahdy | I15: =VLOOKUP(E15,'HC for display name '!$B:$D,3,0) -> AbdElRahman Adel-ElKelany | J15: =VLOOKUP(B15,$T$3:$U$13,2,0) -> D
A16: 1035021343 | B16: 5 | C16: 4 | D16: 4 | E16: V26MMAHDY | F16: 46145 | G16: VMT_VQ_VFE3 | H16: =VLOOKUP(E16,'HC for display name '!$B:$D,2,0) -> Mohamed AbdElMohsen-Mahdy | I16: =VLOOKUP(E16,'HC for display name '!$B:$D,3,0) -> AbdElRahman Adel-ElKelany | J16: =VLOOKUP(B16,$T$3:$U$13,2,0) -> D
A17: 1035548000 | B17: 10 | C17: 3 | D17: 5 | E17: V25NSAEED1 | F17: 46145 | G17: VMT_Red_VQ_VFE1 | H17: =VLOOKUP(E17,'HC for display name '!$B:$D,2,0) -> Nouran AbdAllah-Saeed | I17: =VLOOKUP(E17,'HC for display name '!$B:$D,3,0) -> Merna Ashraf-Ashrafy | J17: =VLOOKUP(B17,$T$3:$U$13,2,0) -> P
A18: 1037877269 | B18: 0 | C18: 3 | D18: 1 | E18: V25MMANSOUR10 | F18: 46145 | G18: VMT_VQ_VFE3 | H18: =VLOOKUP(E18,'HC for display name '!$B:$D,2,0) -> Mohamed Ahmed-Mansour | I18: =VLOOKUP(E18,'HC for display name '!$B:$D,3,0) -> Hend Yousry-AbdElRassoul | J18: =VLOOKUP(B18,$T$3:$U$13,2,0) -> D
A19: 1040398992 | B19: 10 | C19: 1 | D19: 5 | E19: V25BHASSAN3 | F19: 46145 | G19: VMT_Red_VQ_VFE1 | H19: =VLOOKUP(E19,'HC for display name '!$B:$D,2,0) -> Bassant Salah-Hassan | I19: =VLOOKUP(E19,'HC for display name '!$B:$D,3,0) -> Merna Ashraf-Ashrafy | J19: =VLOOKUP(B19,$T$3:$U$13,2,0) -> P
A20: 1063323820 | B20: 9 | C20: 1 | D20: N/A | E20: V25BHASSAN3 | F20: 46145 | G20: VMT_Red_VQ_VFE1 | H20: =VLOOKUP(E20,'HC for display name '!$B:$D,2,0) -> Bassant Salah-Hassan | I20: =VLOOKUP(E20,'HC for display name '!$B:$D,3,0) -> Merna Ashraf-Ashrafy | J20: =VLOOKUP(B20,$T$3:$U$13,2,0) -> P
A21: 1065332825 | B21: 10 | C21: 4 | D21: 5 | E21: V25YMOHAMED24 | F21: 46145 | G21: VMT_Red_VQ_VFE1 | H21: =VLOOKUP(E21,'HC for display name '!$B:$D,2,0) -> Yasmine Waleed-Mohamed | I21: =VLOOKUP(E21,'HC for display name '!$B:$D,3,0) -> Merna Ashraf-Ashrafy | J21: =VLOOKUP(B21,$T$3:$U$13,2,0) -> P
A22: 1066261519 | B22: 0 | C22: 3 | D22: 5 | E22: V25FMAGD | F22: 46145 | G22: VMT_Red_VQ_VFE1 | H22: =VLOOKUP(E22,'HC for display name '!$B:$D,2,0) -> Farha Ashraf-AboElMagd | I22: =VLOOKUP(E22,'HC for display name '!$B:$D,3,0) -> Merna Ashraf-Ashrafy | J22: =VLOOKUP(B22,$T$3:$U$13,2,0) -> D
A23: 1069214805 | B23: 0 | C23: 4 | D23: 5 | E23: V25EMAHFOD | F23: 46145 | G23: VMT_Red_VQ_VFE1 | H23: =VLOOKUP(E23,'HC for display name '!$B:$D,2,0) -> Esraa Saad-Mahfod | I23: =VLOOKUP(E23,'HC for display name '!$B:$D,3,0) -> Hend Yousry-AbdElRassoul | J23: =VLOOKUP(B23,$T$3:$U$13,2,0) -> D
A24: 1070050788 | B24: 10 | C24: 4 | D24: 5 | E24: V25EMAHFOD | F24: 46145 | G24: VMT_Red_VQ_VFE1 | H24: =VLOOKUP(E24,'HC for display name '!$B:$D,2,0) -> Esraa Saad-Mahfod | I24: =VLOOKUP(E24,'HC for display name '!$B:$D,3,0) -> Hend Yousry-AbdElRassoul | J24: =VLOOKUP(B24,$T$3:$U$13,2,0) -> P
A25: 1070381335 | B25: 10 | C25: 4 | D25: 5 | E25: V25AFADEEL2 | F25: 46145 | G25: VMT_Red_VQ_VFE1 | H25: =VLOOKUP(E25,'HC for display name '!$B:$D,2,0) -> AbdElRhman Hesham-AbdElFadeel | I25: =VLOOKUP(E25,'HC for display name '!$B:$D,3,0) -> AbdElRahman Adel-ElKelany | J25: =VLOOKUP(B25,$T$3:$U$13,2,0) -> P
... A362: 1224988751 | B362: 10 | C362: 1 | D362: 5 | E362: V25SZEKRY | F362: 46158 | G362: VMT_VQ_VFE3 | H362: =VLOOKUP(E362,'HC for display name '!$B:$D,2,0) -> Safaa Safwat-Zekry | I362: =VLOOKUP(E362,'HC for display name '!$B:$D,3,0) -> Merna Ashraf-Ashrafy | J362: =VLOOKUP(B362,$T$3:$U$13,2,0) -> P
A363: 1028763420 | B363: 10 | C363: 1 | D363: 5 | E363: =VLOOKUP(H363,'HC for user name'!$B:$C,2,0) -> V26OGohar | F363: 46159 | G363: VMT_VQ_VFE3 | H363: Omar Ali-Gohar | I363: =VLOOKUP(E363,'HC for display name '!$B:$D,3,0) -> AbdElRahman Adel-ElKelany | J363: =VLOOKUP(B363,$T$3:$U$13,2,0) -> P
A364: 1005113698 | B364: 8 | C364: 4 | D364: 5 | E364: =VLOOKUP(H364,'HC for user name'!$B:$C,2,0) -> V25AEWIS2 | F364: 46159 | G364: VMT_VQ_VFE3 | H364: Ahmed Magdy-Ewis | I364: =VLOOKUP(E364,'HC for display name '!$B:$D,3,0) -> Omar Emad-Mahmoud | J364: =VLOOKUP(B364,$T$3:$U$13,2,0) -> N
A365: 1066045999 | B365: 10 | C365: 1 | D365: 5 | E365: =VLOOKUP(H365,'HC for user name'!$B:$C,2,0) -> V25HHassan50 | F365: 46159 | G365: VMT_VQ_VFE3 | H365: Hassan Ramy-Hassan | I365: =VLOOKUP(E365,'HC for display name '!$B:$D,3,0) -> Merna Ashraf-Ashrafy | J365: =VLOOKUP(B365,$T$3:$U$13,2,0) -> P
A366: 1070266111 | B366: 10 | C366: 1 | D366: 5 | E366: =VLOOKUP(H366,'HC for user name'!$B:$C,2,0) -> V25MFarag10 | F366: 46159 | G366: VMT_VQ_VFE3 | H366: Mohamed AbdElazim-Farag | I366: =VLOOKUP(E366,'HC for display name '!$B:$D,3,0) -> Hend Yousry-AbdElRassoul | J366: =VLOOKUP(B366,$T$3:$U$13,2,0) -> P
A367: 1009070108 | B367: 10 | C367: 3 | D367: 5 | E367: =VLOOKUP(H367,'HC for user name'!$B:$C,2,0) -> V25AFADEEL2 | F367: 46159 | G367: VMT_VQ_VFE3 | H367: AbdElRhman Hesham-AbdElFadeel | I367: =VLOOKUP(E367,'HC for display name '!$B:$D,3,0) -> AbdElRahman Adel-ElKelany | J367: =VLOOKUP(B367,$T$3:$U$13,2,0) -> P
A368: 1067253570 | B368: 7 | C368: 1 | D368: 4 | E368: =VLOOKUP(H368,'HC for user name'!$B:$C,2,0) -> #N/A | F368: 46159 | G368: VMT_VQ_VFE3 | H368: Fares Waleed-Mohamed | I368: =VLOOKUP(E368,'HC for display name '!$B:$D,3,0) -> #N/A | J368: =VLOOKUP(B368,$T$3:$U$13,2,0) -> N
A369: 1068367519 | B369: 10 | C369: 1 | D369: 5 | E369: =VLOOKUP(H369,'HC for user name'!$B:$C,2,0) -> V25AEWIS2 | F369: 46159 | G369: VMT_VQ_VFE3 | H369: Ahmed Magdy-Ewis | I369: =VLOOKUP(E369,'HC for display name '!$B:$D,3,0) -> Omar Emad-Mahmoud | J369: =VLOOKUP(B369,$T$3:$U$13,2,0) -> P
A370: 1065851862 | B370: 10 | C370: 1 | D370: 5 | E370: =VLOOKUP(H370,'HC for user name'!$B:$C,2,0) -> V25MFarag10 | F370: 46159 | G370: VMT_VQ_VFE3 | H370: Mohamed AbdElazim-Farag | I370: =VLOOKUP(E370,'HC for display name '!$B:$D,3,0) -> Hend Yousry-AbdElRassoul | J370: =VLOOKUP(B370,$T$3:$U$13,2,0) -> P
A371: 1007288279 | B371: 10 | C371: 1 | D371: 5 | E371: =VLOOKUP(H371,'HC for user name'!$B:$C,2,0) -> V25AFADEEL2 | F371: 46159 | G371: VMT_VQ_VFE3 | H371: AbdElRhman Hesham-AbdElFadeel | I371: =VLOOKUP(E371,'HC for display name '!$B:$D,3,0) -> AbdElRahman Adel-ElKelany | J371: =VLOOKUP(B371,$T$3:$U$13,2,0) -> P
A372: 1116556007 | B372: 10 | C372: 1 | D372: 5 | E372: =VLOOKUP(H372,'HC for user name'!$B:$C,2,0) -> V25HHassan50 | F372: 46159 | G372: VMT_VQ_VFE3 | H372: Hassan Ramy-Hassan | I372: =VLOOKUP(E372,'HC for display name '!$B:$D,3,0) -> Merna Ashraf-Ashrafy | J372: =VLOOKUP(B372,$T$3:$U$13,2,0) -> P
A373: 1092279013 | B373: 10 | C373: 1 | D373: 5 | E373: =VLOOKUP(H373,'HC for user name'!$B:$C,2,0) -> V25HHassan50 | F373: 46159 | G373: VMT_VQ_VFE3 | H373: Hassan Ramy-Hassan | I373: =VLOOKUP(E373,'HC for display name '!$B:$D,3,0) -> Merna Ashraf-Ashrafy | J373: =VLOOKUP(B373,$T$3:$U$13,2,0) -> P
A374: 1036888809 | B374: 0 | C374: 4 | D374: 1 | E374: =VLOOKUP(H374,'HC for user name'!$B:$C,2,0) -> V26AZaki2 | F374: 46159 | G374: VMT_VQ_VFE3 | H374: Andrwa Wafeek-Zaki | I374: =VLOOKUP(E374,'HC for display name '!$B:$D,3,0) -> Omar Emad-Mahmoud | J374: =VLOOKUP(B374,$T$3:$U$13,2,0) -> D
... A437: 1015495603 | B437: 10 | C437: 1 | D437: 5 | E437: =VLOOKUP(H437,'HC for user name'!$B:$C,2,0) -> V25EMahfod | F437: 46160 | G437: VMT_VQ_VFE3 | H437: Esraa Saad-Mahfod | I437: =VLOOKUP(E437,'HC for display name '!$B:$D,3,0) -> Hend Yousry-AbdElRassoul | J437: =VLOOKUP(B437,$T$3:$U$13,2,0) -> P

Sheet HC for display name 
A1: Agent-Name | B1: UserName | C1: Display Name | D1: TL | E1: SPV | F1: Segment | G1: Site | H1: Full/Part | I1: Gender | J1: NUM | K1: Jop Title | L1: Mail | M1: UserName
A2: V23MGELIL - Mohamed.A | B2: V23MGELIL | C2: Mohamed Ali-AbdElGelil | D2: Omar Emad-Mahmoud | E2: Mohamed Ahmed-Nagy | F2: Old | G2: Red | H2: Full Time | I2: M | J2: 1028671298 | K2: Credit Control VF Cash Representative | L2: mohamed.aliabdelgelil1@vodafone.com.eg | M2: V23MGELIL
A3: V24ASAEED11 - Ali.B | B3: V24ASAEED11 | C3: Ali Bahat-Saeed | D3: Omar Emad-Mahmoud | E3: Mohamed Ahmed-Nagy | F3: New | G3: Red | H3: Full Time | I3: M | J3: 1024811820 | K3: Credit Control VF Cash Representative | L3: ali.bahatsaeed@vodafone.com.eg | M3: V24ASAEED11
A4: V24KKHALEK1 - Khaled.W | B4: V24KKHALEK1 | C4: Khaled Waleed-AbdElKhalek | D4: Omar Emad-Mahmoud | E4: Mohamed Ahmed-Nagy | F4: Old | G4: Red | H4: Full Time | I4: M | J4: 1068648163 | K4: Credit Control VF Cash Representative | L4: khaled.waleedabdelkhalek@vodafone.com.eg | M4: V24KKHALEK1
A5: V25ARIZK - Ahmed.S | B5: V25ARIZK | C5: Ahmed Sameh-Rizk | D5: Omar Emad-Mahmoud | E5: Mohamed Ahmed-Nagy | F5: New | G5: Red | H5: Full Time | I5: M | J5: 1090816081 | K5: Credit Control VF Cash Representative | L5: ahmed.samehrizk@vodafone.com | M5: V25ARIZK
A6: V25YMOHAMED7 - Youssef.H | B6: V25YMOHAMED7 | C6: Youssef Hamdy-Mohamed | D6: Omar Emad-Mahmoud | E6: Mohamed Ahmed-Nagy | F6: New | G6: Red | H6: Full Time | I6: M | J6: 1221559609 | K6: Credit Control VF Cash Representative | L6: youssef.hamdymohamed1@vodafone.com.eg | M6: V25YMOHAMED7
A7: V25AAZIZ28 - AbdAllah.S | B7: V25AAZIZ28 | C7: AbdAllah Shaker-AbdElAziz | D7: Omar Emad-Mahmoud | E7: Mohamed Ahmed-Nagy | F7: New | G7: Red | H7: Full Time | I7: M | J7: 1014370411 | K7: Credit Control VF Cash Representative | L7: abdallah.shakerabdelaziz@vodafone.com.eg | M7: V25AAZIZ28
A8: V25AEWIS2 - Ahmed.M | B8: V25AEWIS2 | C8: Ahmed Magdy-Ewis | D8: Omar Emad-Mahmoud | E8: Mohamed Ahmed-Nagy | F8: New | G8: Red | H8: Full Time | I8: M | J8: 1126752132 | K8: Credit Control VF Cash Representative | L8: ahmed.magdyewis@vodafone.com.eg | M8: V25AEWIS2
A9: V25HAHMED43 - Hatem.I | B9: V25HAHMED43 | C9: Hatem Ibrahim-Ahmed | D9: Omar Emad-Mahmoud | E9: Mohamed Ahmed-Nagy | F9: New | G9: Red | H9: Full Time | I9: M | J9: 1221731201 | K9: Credit Control VF Cash Representative | L9: hatem.ibrahimahmed@vodafone.com.eg | M9: V25HAHMED43
A10: V25IZAKARIA - Islam.G | B10: V25IZAKARIA | C10: Islam Gamal-Zakaria | D10: Omar Emad-Mahmoud | E10: Mohamed Ahmed-Nagy | F10: New | G10: Red | H10: Full Time | I10: M | J10: 1555187430 | K10: Credit Control VF Cash Representative | L10: islam.gamalzakaria@vodafone.com.eg | M10: V25IZAKARIA
A11: V24OSAMEA - Omnia.S | B11: V24OSAMEA | C11: Omnia Salah-AbdElSamea | D11: Merna Ashraf-Ashrafy | E11: Mohamed Ahmed-Nagy | F11: Old | G11: Red | H11: Full Time | I11: F | J11: 1065210836 | K11: Credit Control VF Cash Representative | L11: omnia.salahabdelsamea@vodafone.com.eg | M11: V24OSAMEA
A12: V24SAHMED28 - Salma.T | B12: V24SAHMED28 | C12: Salma Taha-Ahmed | D12: Merna Ashraf-Ashrafy | E12: Mohamed Ahmed-Nagy | F12: Old | G12: Red | H12: Full Time | I12: F | J12: 1080946604 | K12: Credit Control VF Cash Representative | L12: salma.tahaahmed1@vodafone.com.eg | M12: V24SAHMED28
A13: V25FMAGD - Farha.A | B13: V25FMAGD | C13: Farha Ashraf-AboElMagd | D13: Merna Ashraf-Ashrafy | E13: Mohamed Ahmed-Nagy | F13: New | G13: Red | H13: Full Time | I13: M | J13: 1119093689 | K13: Credit Control VF Cash Representative | L13: farha.ashrafaboelmagd@vodafone.com.eg | M13: V25FMAGD
... A33: V25SSAGHEER - Samir.H | B33: V25SSAGHEER | C33: Samir Hosny-Sagheer | D33: AbdElRahman Adel-ElKelany | E33: Mohamed Ahmed-Nagy | F33: New | G33: Red | H33: Full Time | I33: M | J33: 1050122437 | K33: Credit Control VF Cash Representative | L33: samir.hosnysagheer@vodafone.com.eg | M33: V25SSAGHEER
A34: V25AHASSAN63 - Alaa.M | B34: V25AHASSAN63 | C34: Alaa Mahmoud-Hassan | D34: Merna Ashraf-Ashrafy | E34: Mohamed Ahmed-Nagy | F34: New | G34: Red | H34: Full Time | I34: M | J34: 1011759074 | K34: Credit Control VF Cash Representative | L34: alaa.mahmoudhassan1@vodafone.com.eg
A35: V25SMOHAMED145 - Salma.W | B35: V25SMOHAMED145 | C35: Salma Wael-Mohamed | D35: Merna Ashraf-Ashrafy | E35: Mohamed Ahmed-Nagy | F35: New | G35: Red | H35: Full Time | I35: M | K35: Credit Control VF Cash Representative | L35: salma.waelmohamed@vodafone.com.eg
A36: V25MSALAH21 - Mohamed.G | B36: V25MSALAH21 | C36: Mohamed Gamil-Salah | D36: Omar Emad-Mahmoud | E36: Mohamed Ahmed-Nagy | F36: New | G36: Red | H36: Full Time | I36: M | J36: 1023410812 | K36: Credit Control VF Cash Representative | L36: mohamed.gamilsalah@vodafone.com.eg
A37: V25BSHENAWY - Badr.M | B37: V25BSHENAWY | C37: Badr Medhat-ElShenawy | D37: AbdElRahman Adel-ElKelany | E37: Mohamed Ahmed-Nagy | F37: New | G37: Red | H37: Full Time | I37: M | K37: Credit Control VF Cash Representative | L37: badr.medhatelshenawy@vodafone.com.eg
A38: V25IGHONIMY - Ibrahim.A | B38: V25IGHONIMY | C38: Ibrahim Ahmed-Ghonimy | D38: AbdElRahman Adel-ElKelany | E38: Mohamed Ahmed-Nagy | F38: New | G38: Red | H38: Full Time | I38: M | K38: Credit Control VF Cash Representative | L38: ibrahim.ahmedghonimy@vodafone.com.eg
A39: V25SSAYED67 - Sherif.M | B39: V25SSAYED67 | C39: Sherif Madbouly-Sayed | D39: Omar Emad-Mahmoud | E39: Mohamed Ahmed-Nagy | F39: New | G39: Red | H39: Full Time | I39: M | K39: Credit Control VF Cash Representative | L39: sherif.madboulysayed@vodafone.com.eg
A40: V25HGAMAL2 - Hany.I | B40: V25HGAMAL2 | C40: Hany Ibrahim-Gamal | D40: AbdElRahman Adel-ElKelany | E40: Mohamed Ahmed-Nagy | F40: New | G40: Red | H40: Full Time | I40: M | K40: Credit Control VF Cash Representative | L40: hany.ibrahimgamal@vodafone.com.eg
A41: V25YREHIM4 - Yasmine.S | B41: V25YREHIM4 | C41: Yasmine Samer AbdElRehim AbdElGelil | D41: Merna Ashraf-Ashrafy | E41: Mohamed Ahmed-Nagy
A42: V22HRASSOUL - Hend.Y | B42: V22HRASSOUL | C42: Hend Yousry-AbdElRassoul | D42: Hend Yousry-AbdElRassoul | E42: Mohamed Ahmed-Nagy
A43: V22MASHRAFY - Merna.A | B43: V22MASHRAFY | C43: Merna Ashraf-Ashrafy | D43: Merna Ashraf-Ashrafy | E43: Mohamed Ahmed-Nagy
A44: V24AHASSAN6 - Aya.M | B44: V24AHASSAN6 | C44: Aya Mohamed-Hassan | D44: Merna Ashraf-Ashrafy | E44: Mohamed Ahmed-Nagy
A45: V24AKELANY - AbdElRahman.A | B45: V24AKELANY | C45: AbdElRahman Adel-ElKelany | D45: AbdElRahman Adel-ElKelany | E45: Mohamed Ahmed-Nagy
B46: V25SSayed21 | C46: Sara Ahmed-ElSayed | D46: Hend Yousry-AbdElRassoul | E46: Mohamed Ahmed-Nagy
B47: V25SMagd | C47: Sara Hassan-AboElMagd | D47: Hend Yousry-AbdElRassoul | E47: Mohamed Ahmed-Nagy
B48: V25EMahfod | C48: Esraa Saad-Mahfod | D48: Hend Yousry-AbdElRassoul | E48: Mohamed Ahmed-Nagy
B49: V25MMansour10 | C49: Mohamed Ahmed-Mansour | D49: Hend Yousry-AbdElRassoul | E49: Mohamed Ahmed-Nagy
B50: V25MFarag10 | C50: Mohamed AbdElazim-Farag | D50: Hend Yousry-AbdElRassoul | E50: Mohamed Ahmed-Nagy
B51: V25MAli107 | C51: Mohamed Mohsen-Ali | D51: Hend Yousry-AbdElRassoul | E51: Mohamed Ahmed-Nagy
B52: V25ALmaaty | C52: AbdAllah Hassan-AboELmaaty | D52: Hend Yousry-AbdElRassoul | E52: Mohamed Ahmed-Nagy
B53: V25MKhattab1 | C53: Mohamed Khaled-Khattab | D53: Hend Yousry-AbdElRassoul | E53: Mohamed Ahmed-Nagy
B54: V25MMohamed354 | C54: Mayada Essam-Mohamed | D54: Hend Yousry-AbdElRassoul | E54: Mohamed Ahmed-Nagy
B55: V25OAllah9 | C55: Omar Mamdouh-AbdAllah | D55: Hend Yousry-AbdElRassoul | E55: Mohamed Ahmed-Nagy
B56: V25AWahib | C56: Ahmed Maged-Wahib | D56: Hend Yousry-AbdElRassoul | E56: Mohamed Ahmed-Nagy
B57: V25YAhmed29 | C57: Youssef Sharafeldin-Ahmed | D57: Hend Yousry-AbdElRassoul | E57: Mohamed Ahmed-Nagy
... B77: V24OMAHMOUD | C77: Omar Emad-Mahmoud | D77: Omar Emad-Mahmoud | E77: Mohamed Ahmed-Nagy

Sheet HC for user name
A1: Agent-Name | B1: Display Name | C1: UserName | D1: TL | E1: SPV | F1: Segment | G1: Site | H1: Full/Part | I1: Gender | J1: NUM | K1: Jop Title | L1: Mail | M1: UserName
A2: V23MGELIL - Mohamed.A | B2: Mohamed Ali-AbdElGelil | C2: V23MGELIL | D2: Omar Emad-Mahmoud | E2: Mohamed Ahmed-Nagy | F2: Old | G2: Red | H2: Full Time | I2: M | J2: 1028671298 | K2: Credit Control VF Cash Representative | L2: mohamed.aliabdelgelil1@vodafone.com.eg | M2: V23MGELIL
A3: V24ASAEED11 - Ali.B | B3: Ali Bahat-Saeed | C3: V24ASAEED11 | D3: Omar Emad-Mahmoud | E3: Mohamed Ahmed-Nagy | F3: New | G3: Red | H3: Full Time | I3: M | J3: 1024811820 | K3: Credit Control VF Cash Representative | L3: ali.bahatsaeed@vodafone.com.eg | M3: V24ASAEED11
A4: V24KKHALEK1 - Khaled.W | B4: Khaled Waleed-AbdElKhalek | C4: V24KKHALEK1 | D4: Omar Emad-Mahmoud | E4: Mohamed Ahmed-Nagy | F4: Old | G4: Red | H4: Full Time | I4: M | J4: 1068648163 | K4: Credit Control VF Cash Representative | L4: khaled.waleedabdelkhalek@vodafone.com.eg | M4: V24KKHALEK1
A5: V25ARIZK - Ahmed.S | B5: Ahmed Sameh-Rizk | C5: V25ARIZK | D5: Omar Emad-Mahmoud | E5: Mohamed Ahmed-Nagy | F5: New | G5: Red | H5: Full Time | I5: M | J5: 1090816081 | K5: Credit Control VF Cash Representative | L5: ahmed.samehrizk@vodafone.com | M5: V25ARIZK
A6: V25YMOHAMED7 - Youssef.H | B6: Youssef Hamdy-Mohamed | C6: V25YMOHAMED7 | D6: Omar Emad-Mahmoud | E6: Mohamed Ahmed-Nagy | F6: New | G6: Red | H6: Full Time | I6: M | J6: 1221559609 | K6: Credit Control VF Cash Representative | L6: youssef.hamdymohamed1@vodafone.com.eg | M6: V25YMOHAMED7
A7: V25AAZIZ28 - AbdAllah.S | B7: AbdAllah Shaker-AbdElAziz | C7: V25AAZIZ28 | D7: Omar Emad-Mahmoud | E7: Mohamed Ahmed-Nagy | F7: New | G7: Red | H7: Full Time | I7: M | J7: 1014370411 | K7: Credit Control VF Cash Representative | L7: abdallah.shakerabdelaziz@vodafone.com.eg | M7: V25AAZIZ28
A8: V25AEWIS2 - Ahmed.M | B8: Ahmed Magdy-Ewis | C8: V25AEWIS2 | D8: Omar Emad-Mahmoud | E8: Mohamed Ahmed-Nagy | F8: New | G8: Red | H8: Full Time | I8: M | J8: 1126752132 | K8: Credit Control VF Cash Representative | L8: ahmed.magdyewis@vodafone.com.eg | M8: V25AEWIS2
A9: V25HAHMED43 - Hatem.I | B9: Hatem Ibrahim-Ahmed | C9: V25HAHMED43 | D9: Omar Emad-Mahmoud | E9: Mohamed Ahmed-Nagy | F9: New | G9: Red | H9: Full Time | I9: M | J9: 1221731201 | K9: Credit Control VF Cash Representative | L9: hatem.ibrahimahmed@vodafone.com.eg | M9: V25HAHMED43
A10: V25IZAKARIA - Islam.G | B10: Islam Gamal-Zakaria | C10: V25IZAKARIA | D10: Omar Emad-Mahmoud | E10: Mohamed Ahmed-Nagy | F10: New | G10: Red | H10: Full Time | I10: M | J10: 1555187430 | K10: Credit Control VF Cash Representative | L10: islam.gamalzakaria@vodafone.com.eg | M10: V25IZAKARIA
A11: V24OSAMEA - Omnia.S | B11: Omnia Salah-AbdElSamea | C11: V24OSAMEA | D11: Merna Ashraf-Ashrafy | E11: Mohamed Ahmed-Nagy | F11: Old | G11: Red | H11: Full Time | I11: F | J11: 1065210836 | K11: Credit Control VF Cash Representative | L11: omnia.salahabdelsamea@vodafone.com.eg | M11: V24OSAMEA
A12: V24SAHMED28 - Salma.T | B12: Salma Taha-Ahmed | C12: V24SAHMED28 | D12: Merna Ashraf-Ashrafy | E12: Mohamed Ahmed-Nagy | F12: Old | G12: Red | H12: Full Time | I12: F | J12: 1080946604 | K12: Credit Control VF Cash Representative | L12: salma.tahaahmed1@vodafone.com.eg | M12: V24SAHMED28
A13: V25FMAGD - Farha.A | B13: Farha Ashraf-AboElMagd | C13: V25FMAGD | D13: Merna Ashraf-Ashrafy | E13: Mohamed Ahmed-Nagy | F13: New | G13: Red | H13: Full Time | I13: M | J13: 1119093689 | K13: Credit Control VF Cash Representative | L13: farha.ashrafaboelmagd@vodafone.com.eg | M13: V25FMAGD
... A33: V25SSAGHEER - Samir.H | B33: Samir Hosny-Sagheer | C33: V25SSAGHEER | D33: AbdElRahman Adel-ElKelany | E33: Mohamed Ahmed-Nagy | F33: New | G33: Red | H33: Full Time | I33: M | J33: 1050122437 | K33: Credit Control VF Cash Representative | L33: samir.hosnysagheer@vodafone.com.eg | M33: V25SSAGHEER
A34: V25AHASSAN63 - Alaa.M | B34: Alaa Mahmoud-Hassan | C34: V25AHASSAN63 | D34: Merna Ashraf-Ashrafy | E34: Mohamed Ahmed-Nagy | F34: New | G34: Red | H34: Full Time | I34: M | J34: 1011759074 | K34: Credit Control VF Cash Representative | L34: alaa.mahmoudhassan1@vodafone.com.eg
A35: V25SMOHAMED145 - Salma.W | B35: Salma Wael-Mohamed | C35: V25SMOHAMED145 | D35: Merna Ashraf-Ashrafy | E35: Mohamed Ahmed-Nagy | F35: New | G35: Red | H35: Full Time | I35: M | K35: Credit Control VF Cash Representative | L35: salma.waelmohamed@vodafone.com.eg
A36: V25MSALAH21 - Mohamed.G | B36: Mohamed Gamil-Salah | C36: V25MSALAH21 | D36: Omar Emad-Mahmoud | E36: Mohamed Ahmed-Nagy | F36: New | G36: Red | H36: Full Time | I36: M | J36: 1023410812 | K36: Credit Control VF Cash Representative | L36: mohamed.gamilsalah@vodafone.com.eg
A37: V25BSHENAWY - Badr.M | B37: Badr Medhat-ElShenawy | C37: V25BSHENAWY | D37: AbdElRahman Adel-ElKelany | E37: Mohamed Ahmed-Nagy | F37: New | G37: Red | H37: Full Time | I37: M | K37: Credit Control VF Cash Representative | L37: badr.medhatelshenawy@vodafone.com.eg
A38: V25IGHONIMY - Ibrahim.A | B38: Ibrahim Ahmed-Ghonimy | C38: V25IGHONIMY | D38: AbdElRahman Adel-ElKelany | E38: Mohamed Ahmed-Nagy | F38: New | G38: Red | H38: Full Time | I38: M | K38: Credit Control VF Cash Representative | L38: ibrahim.ahmedghonimy@vodafone.com.eg
A39: V25SSAYED67 - Sherif.M | B39: Sherif Madbouly-Sayed | C39: V25SSAYED67 | D39: Omar Emad-Mahmoud | E39: Mohamed Ahmed-Nagy | F39: New | G39: Red | H39: Full Time | I39: M | K39: Credit Control VF Cash Representative | L39: sherif.madboulysayed@vodafone.com.eg
A40: V25HGAMAL2 - Hany.I | B40: Hany Ibrahim-Gamal | C40: V25HGAMAL2 | D40: AbdElRahman Adel-ElKelany | E40: Mohamed Ahmed-Nagy | F40: New | G40: Red | H40: Full Time | I40: M | K40: Credit Control VF Cash Representative | L40: hany.ibrahimgamal@vodafone.com.eg
A41: V25YREHIM4 - Yasmine.S | B41: Yasmine Samer AbdElRehim AbdElGelil | C41: V25YREHIM4 | D41: Merna Ashraf-Ashrafy | E41: Mohamed Ahmed-Nagy
A42: V22HRASSOUL - Hend.Y | B42: Hend Yousry-AbdElRassoul | C42: V22HRASSOUL | D42: Hend Yousry-AbdElRassoul | E42: Mohamed Ahmed-Nagy
A43: V22MASHRAFY - Merna.A | B43: Merna Ashraf-Ashrafy | C43: V22MASHRAFY | D43: Merna Ashraf-Ashrafy | E43: Mohamed Ahmed-Nagy
A44: V24AHASSAN6 - Aya.M | B44: Aya Mohamed-Hassan | C44: V24AHASSAN6 | D44: Merna Ashraf-Ashrafy | E44: Mohamed Ahmed-Nagy
A45: V24AKELANY - AbdElRahman.A | B45: AbdElRahman Adel-ElKelany | C45: V24AKELANY | D45: AbdElRahman Adel-ElKelany | E45: Mohamed Ahmed-Nagy
B46: Sara Ahmed-ElSayed | C46: V25SSayed21 | D46: Hend Yousry-AbdElRassoul | E46: Mohamed Ahmed-Nagy
B47: Sara Hassan-AboElMagd | C47: V25SMagd | D47: Hend Yousry-AbdElRassoul | E47: Mohamed Ahmed-Nagy
B48: Esraa Saad-Mahfod | C48: V25EMahfod | D48: Hend Yousry-AbdElRassoul | E48: Mohamed Ahmed-Nagy
B49: Mohamed Ahmed-Mansour | C49: V25MMansour10 | D49: Hend Yousry-AbdElRassoul | E49: Mohamed Ahmed-Nagy
B50: Mohamed AbdElazim-Farag | C50: V25MFarag10 | D50: Hend Yousry-AbdElRassoul | E50: Mohamed Ahmed-Nagy
B51: Mohamed Mohsen-Ali | C51: V25MAli107 | D51: Hend Yousry-AbdElRassoul | E51: Mohamed Ahmed-Nagy
B52: AbdAllah Hassan-AboELmaaty | C52: V25ALmaaty | D52: Hend Yousry-AbdElRassoul | E52: Mohamed Ahmed-Nagy
B53: Mohamed Khaled-Khattab | C53: V25MKhattab1 | D53: Hend Yousry-AbdElRassoul | E53: Mohamed Ahmed-Nagy
B54: Mayada Essam-Mohamed | C54: V25MMohamed354 | D54: Hend Yousry-AbdElRassoul | E54: Mohamed Ahmed-Nagy
B55: Omar Mamdouh-AbdAllah | C55: V25OAllah9 | D55: Hend Yousry-AbdElRassoul | E55: Mohamed Ahmed-Nagy
B56: Ahmed Maged-Wahib | C56: V25AWahib | D56: Hend Yousry-AbdElRassoul | E56: Mohamed Ahmed-Nagy
B57: Youssef Sharafeldin-Ahmed | C57: V25YAhmed29 | D57: Hend Yousry-AbdElRassoul | E57: Mohamed Ahmed-Nagy
... B77: Omar Emad-Mahmoud | C77: V24OMAHMOUD | D77: Omar Emad-Mahmoud | E77: Mohamed Ahmed-Nagy
